Workbook

Sheet EERR RODEO
A2: ESTADO DE RESULTADOS
A3: PARTIDAS | B3: =IF(ISBLANK(A2),"",YEAR(TODAY())-1) -> 2025 | C3: % Vtas | D3: % Gastos | E3: ENE | F3: % Vtas | G3: % Gastos | H3: FEB | I3: % Vtas | J3: % Gastos | K3: Vari Rel. | L3: ACUM EJEC | M3: % Vtas | N3: % Gastos | O3: MAR | P3: % Vtas | Q3: % Gastos | R3: Vari Rel. | S3: ACUM EJEC | T3: % Vtas | U3: % Gastos | V3: ACUM PPTO | W3: % Vtas | X3: Var PPTO | Y3: ABR | Z3: % Vtas | AA3: % Gastos | AB3: Vari Rel. | AC3: ACUM EJEC | AD3: % Vtas | AE3: % Gastos | AF3: MAY | AG3: % Vtas | AH3: % Gastos | AI3: Vari Rel. | AJ3: ACUM EJEC | AK3: % Vtas | AL3: % Gastos | AM3: JUN | AN3: % Vtas | AO3: % Gastos | AP3: Vari Rel. | AQ3: ACUM EJEC | AR3: % Vtas | AS3: % Gastos | AT3: ACUM PPTO | AU3: % Vtas | AV3: Var PPTO | AW3: PROM 6 EJEC | AX3: % Vtas | AY3: % Gastos | AZ3: PROM 6 PPTO | BA3: % Vtas | BB3: Var PPTO | BC3: JUL | BD3: % Vtas | BE3: % Gastos | BF3: Vari Rel. | BG3: ACUM EJEC | BH3: % Vtas | BI3: % Gastos | BJ3: AGO | BK3: % Vtas | BL3: % Gastos | BM3: Vari Rel. | BN3: ACUM EJEC | BO3: % Vtas | BP3: % Gastos | BQ3: SEPT | BR3: % Vtas | BS3: % Gastos | BT3: Vari Rel. | BU3: ACUM EJEC | BV3: % Vtas | BW3: % Gastos | BX3: ACUM PPTO | BY3: % Vtas | BZ3: Var PPTO | CA3: OCT | CB3: % Vtas | CC3: % Gastos | CD3: Vari Rel. | CE3: ACUM EJEC | CF3: % Vtas | CG3: % Gastos | CH3: NOV | CI3: % Vtas | CJ3: % Gastos | CK3: Vari Rel. | CL3: ACUM EJEC | CM3: % Vtas | CN3: % Gastos | CO3: DIC | CP3: % Vtas | CQ3: % Gastos | CR3: Vari Rel. | CS3: 2025 | CT3: % Vtas | CU3: % Gastos | CV3: ACUM PPTO | CW3: % Vtas | CX3: Var PPTO
A4: Total Ingresos | B4: =+B5+B10+B15+B18 -> 0 | C4: =IF(AND(B4=0,B4>=0), "",B4/B4) | E4: =+E5+E10+E15+E18 -> 47933.03 | F4: =IF(AND(E4=0,E4>=0), "",E4/E4) -> 1 | H4: =+H5+H10+H15+H18 -> 51483.04 | I4: =IF(AND(H4=0,H4>=0), "",H4/H4) -> 1 | K4: =IF(AND(E4=0,H4>0),100%,IF(AND(E4<0,H4=0),(E4-H4)/E4,IF(AND(E4>0,H4>0),(H4-E4)/E4,IF(AND(E4=0,H4=0),"",(H4-E4)/E4)))) -> 0.074061873 | L4: =+L5+L10+L15+L18 -> 99416.07 | M4: =IF(AND(L4=0,L4>=0), "",L4/L4) -> 1 | O4: =+O5+O10+O15+O18 -> 64106.18 | P4: =IF(AND(O4=0,O4>=0), "",O4/O4) -> 1 | R4: =IF(AND(H4=0,O4>0),100%,IF(AND(H4<0,O4=0),(H4-O4)/H4,IF(AND(H4>0,O4>0),(O4-H4)/H4,IF(AND(H4=0,O4=0),"",(O4-H4)/H4)))) -> 0.24519026 | S4: =+S5+S10+S15+S18 -> 163522.25 | T4: =IF(AND(S4=0,S4>=0), "",S4/S4) -> 1 | V4: =+V5+V10+V15+V18 -> 0 | W4: =IF(AND(V4=0,V4>=0), "",V4/V4) | X4: =IF(AND(V4=0,S4>0),100%,IF(AND(V4<0,S4=0),(V4-S4)/V4,IF(AND(V4>0,S4>0),(S4-V4)/V4,IF(AND(V4=0,S4=0),"",(S4-V4)/V4)))) -> 1 | Y4: =+Y5+Y10+Y15+Y18 -> 0 | Z4: =IF(AND(Y4=0,Y4>=0), "",Y4/Y4) | AB4: =IF(AND(O4=0,Y4>0),100%,IF(AND(O4<0,Y4=0),(O4-Y4)/O4,IF(AND(O4>0,Y4>0),(Y4-O4)/O4,IF(AND(O4=0,Y4=0),"",(Y4-O4)/O4)))) -> -1 | AC4: =+AC5+AC10+AC15+AC18 -> 163522.25 | AD4: =IF(AND(AC4=0,AC4>=0), "",AC4/AC4) -> 1 | AF4: =+AF5+AF10+AF15+AF18 -> 0 | AG4: =IF(AND(AF4=0,AF4>=0), "",AF4/AF4) | AI4: =IF(AND(Y4=0,AF4>0),100%,IF(AND(Y4<0,AF4=0),(Y4-AF4)/Y4,IF(AND(Y4>0,AF4>0),(AF4-Y4)/Y4,IF(AND(Y4=0,AF4=0),"",(AF4-Y4)/Y4)))) | AJ4: =+AJ5+AJ10+AJ15+AJ18 -> 163522.25 | AK4: =IF(AND(AJ4=0,AJ4>=0), "",AJ4/AJ4) -> 1 | AM4: =+AM5+AM10+AM15+AM18 -> 0 | AN4: =IF(AND(AM4=0,AM4>=0), "",AM4/AM4) | AP4: =IF(AND(AF4=0,AM4>0),100%,IF(AND(AF4<0,AM4=0),(AF4-AM4)/AF4,IF(AND(AF4>0,AM4>0),(AM4-AF4)/AF4,IF(AND(AF4=0,AM4=0),"",(AM4-AF4)/AF4)))) | AQ4: =+AQ5+AQ10+AQ15+AQ18 -> 163522.25 | AR4: =IF(AND(AQ4=0,AQ4>=0), "",AQ4/AQ4) -> 1 | AT4: =+AT5+AT10+AT15+AT18 -> 0 | AU4: =IF(AND(AT4=0,AT4>=0), "",AT4/AT4) | AV4: =IF(AND(AT4=0,AQ4>0),100%,IF(AND(AT4<0,AQ4=0),(AT4-AQ4)/AT4,IF(AND(AT4>0,AQ4>0),(AQ4-AT4)/AT4,IF(AND(AT4=0,AQ4=0),"",(AQ4-AT4)/AT4)))) -> 1 | AW4: =+AW5+AW10+AW15+AW18 -> 27253.708 | AX4: =IF(AND(AW4=0,AW4>=0), "",AW4/AW4) -> 1 | AZ4: =+AZ5+AZ10+AZ15+AZ18 -> 0 | BA4: =IF(AND(AZ4=0,AZ4>=0), "",AZ4/AZ4) | BB4: =IF(AND(AZ4=0,AW4>0),100%,IF(AND(AZ4<0,AW4=0),(AZ4-AW4)/AZ4,IF(AND(AZ4>0,AW4>0),(AW4-AZ4)/AZ4,IF(AND(AZ4=0,AW4=0),"",(AW4-AZ4)/AZ4)))) -> 1 | BC4: =+BC5+BC10+BC15+BC18 -> 0 | BD4: =IF(AND(BC4=0,BC4>=0), "",BC4/BC4) | BF4: =IF(AND(AM4=0,BC4>0),100%,IF(AND(AM4<0,BC4=0),(AM4-BC4)/AM4,IF(AND(AM4>0,BC4>0),(BC4-AM4)/AM4,IF(AND(AM4=0,BC4=0),"",(BC4-AM4)/AM4)))) | BG4: =+BG5+BG10+BG15+BG18 -> 163522.25 | BH4: =IF(AND(BG4=0,BG4>=0), "",BG4/BG4) -> 1 | BJ4: =+BJ5+BJ10+BJ15+BJ18 -> 0 | BK4: =IF(AND(BJ4=0,BJ4>=0), "",BJ4/BJ4) | BM4: =IF(AND(BC4=0,BJ4>0),100%,IF(AND(BC4<0,BJ4=0),(BC4-BJ4)/BC4,IF(AND(BC4>0,BJ4>0),(BJ4-BC4)/BC4,IF(AND(BC4=0,BJ4=0),"",(BJ4-BC4)/BC4)))) | BN4: =+BN5+BN10+BN15+BN18 -> 163522.25 | BO4: =IF(AND(BN4=0,BN4>=0), "",BN4/BN4) -> 1 | BQ4: =+BQ5+BQ10+BQ15+BQ18 -> 0 | BR4: =IF(AND(BQ4=0,BQ4>=0), "",BQ4/BQ4) | BT4: =IF(AND(BJ4=0,BQ4>0),100%,IF(AND(BJ4<0,BQ4=0),(BJ4-BQ4)/BJ4,IF(AND(BJ4>0,BQ4>0),(BQ4-BJ4)/BJ4,IF(AND(BJ4=0,BQ4=0),"",(BQ4-BJ4)/BJ4)))) | BU4: =+BU5+BU10+BU15+BU18 -> 163522.25 | BV4: =IF(AND(BU4=0,BU4>=0), "",BU4/BU4) -> 1 | BX4: =+BX5+BX10+BX15+BX18 -> 0 | BY4: =IF(AND(BX4=0,BX4>=0), "",BX4/BX4) | BZ4: =IF(AND(BX4=0,BU4>0),100%,IF(AND(BX4<0,BU4=0),(BX4-BU4)/BX4,IF(AND(BX4>0,BU4>0),(BU4-BX4)/BX4,IF(AND(BX4=0,BU4=0),"",(BU4-BX4)/BX4)))) -> 1 | CA4: =+CA5+CA10+CA15+CA18 -> 0 | CB4: =IF(AND(CA4=0,CA4>=0), "",CA4/CA4) | CD4: =IF(AND(BQ4=0,CA4>0),100%,IF(AND(BQ4<0,CA4=0),(BQ4-CA4)/BQ4,IF(AND(BQ4>0,CA4>0),(CA4-BQ4)/BQ4,IF(AND(BQ4=0,CA4=0),"",(CA4-BQ4)/BQ4)))) | CE4: =+CE5+CE10+CE15+CE18 -> 163522.25 | CF4: =IF(AND(CE4=0,CE4>=0), "",CE4/CE4) -> 1 | CH4: =+CH5+CH10+CH15+CH18 -> 0 | CI4: =IF(AND(CH4=0,CH4>=0), "",CH4/CH4) | CK4: =IF(AND(CA4=0,CH4>0),100%,IF(AND(CA4<0,CH4=0),(CA4-CH4)/CA4,IF(AND(CA4>0,CH4>0),(CH4-CA4)/CA4,IF(AND(CA4=0,CH4=0),"",(CH4-CA4)/CA4)))) | CL4: =+CL5+CL10+CL15+CL18 -> 163522.25 | CM4: =IF(AND(CL4=0,CL4>=0), "",CL4/CL4) -> 1 | CO4: =+CO5+CO10+CO15+CO18 -> 0 | CP4: =IF(AND(CO4=0,CO4>=0), "",CO4/CO4) | CR4: =IF(AND(CH4=0,CO4>0),100%,IF(AND(CH4<0,CO4=0),(CH4-CO4)/CH4,IF(AND(CH4>0,CO4>0),(CO4-CH4)/CH4,IF(AND(CH4=0,CO4=0),"",(CO4-CH4)/CH4)))) | CS4: =+CS5+CS10+CS15+CS18 -> 163522.25 | CT4: =IF(AND(CS4=0,CS4>=0), "",CS4/CS4) -> 1 | CV4: =+CV5+CV10+CV15+CV18 -> 0 | CW4: =IF(AND(CV4=0,CV4>=0), "",CV4/CV4) | CX4: =IF(AND(CV4=0,CS4>0),100%,IF(AND(CV4<0,CS4=0),(CV4-CS4)/CV4,IF(AND(CV4>0,CS4>0),(CS4-CV4)/CV4,IF(AND(CV4=0,CS4=0),"",(CS4-CV4)/CV4)))) -> 1
A5: Subtotal Ingresos por Venta de Mercancia | B5: =+B6-B7-B8 -> 0 | C5: =IF(AND(B4=0,B5>=0), "",B5/B4) | E5: =+E6-E7-E8 -> 47933.03 | F5: =IF(AND(E4=0,E5>=0), "",E5/E4) -> 1 | H5: =+H6-H7-H8 -> 51483.04 | I5: =IF(AND(H4=0,H5>=0), "",H5/H4) -> 1 | K5: =IF(AND(E5=0,H5>0),100%,IF(AND(E5<0,H5=0),(E5-H5)/E5,IF(AND(E5>0,H5>0),(H5-E5)/E5,IF(AND(E5=0,H5=0),"",(H5-E5)/E5)))) -> 0.074061873 | L5: =+L6-L7-L8 -> 99416.07 | M5: =IF(AND(L4=0,L5>=0), "",L5/L4) -> 1 | O5: =+O6-O7-O8 -> 64106.18 | P5: =IF(AND(O4=0,O5>=0), "",O5/O4) -> 1 | R5: =IF(AND(H5=0,O5>0),100%,IF(AND(H5<0,O5=0),(H5-O5)/H5,IF(AND(H5>0,O5>0),(O5-H5)/H5,IF(AND(H5=0,O5=0),"",(O5-H5)/H5)))) -> 0.24519026 | S5: =+S6-S7-S8 -> 163522.25 | T5: =IF(AND(S4=0,S5>=0), "",S5/S4) -> 1 | V5: =+V6-V7-V8 -> 0 | W5: =IF(AND(V4=0,V5>=0), "",V5/V4) | X5: =IF(AND(V5=0,S5>0),100%,IF(AND(V5<0,S5=0),(V5-S5)/V5,IF(AND(V5>0,S5>0),(S5-V5)/V5,IF(AND(V5=0,S5=0),"",(S5-V5)/V5)))) -> 1 | Y5: =+Y6-Y7-Y8 -> 0 | Z5: =IF(AND(Y4=0,Y5>=0), "",Y5/Y4) | AB5: =IF(AND(O5=0,Y5>0),100%,IF(AND(O5<0,Y5=0),(O5-Y5)/O5,IF(AND(O5>0,Y5>0),(Y5-O5)/O5,IF(AND(O5=0,Y5=0),"",(Y5-O5)/O5)))) -> -1 | AC5: =+AC6-AC7-AC8 -> 163522.25 | AD5: =IF(AND(AC4=0,AC5>=0), "",AC5/AC4) -> 1 | AF5: =+AF6-AF7-AF8 -> 0 | AG5: =IF(AND(AF4=0,AF5>=0), "",AF5/AF4) | AI5: =IF(AND(Y5=0,AF5>0),100%,IF(AND(Y5<0,AF5=0),(Y5-AF5)/Y5,IF(AND(Y5>0,AF5>0),(AF5-Y5)/Y5,IF(AND(Y5=0,AF5=0),"",(AF5-Y5)/Y5)))) | AJ5: =+AJ6-AJ7-AJ8 -> 163522.25 | AK5: =IF(AND(AJ4=0,AJ5>=0), "",AJ5/AJ4) -> 1 | AM5: =+AM6-AM7-AM8 -> 0 | AN5: =IF(AND(AM4=0,AM5>=0), "",AM5/AM4) | AP5: =IF(AND(AF5=0,AM5>0),100%,IF(AND(AF5<0,AM5=0),(AF5-AM5)/AF5,IF(AND(AF5>0,AM5>0),(AM5-AF5)/AF5,IF(AND(AF5=0,AM5=0),"",(AM5-AF5)/AF5)))) | AQ5: =+AQ6-AQ7-AQ8 -> 163522.25 | AR5: =IF(AND(AQ4=0,AQ5>=0), "",AQ5/AQ4) -> 1 | AT5: =+AT6-AT7-AT8 -> 0 | AU5: =IF(AND(AT4=0,AT5>=0), "",AT5/AT4) | AV5: =IF(AND(AT5=0,AQ5>0),100%,IF(AND(AT5<0,AQ5=0),(AT5-AQ5)/AT5,IF(AND(AT5>0,AQ5>0),(AQ5-AT5)/AT5,IF(AND(AT5=0,AQ5=0),"",(AQ5-AT5)/AT5)))) -> 1 | AW5: =+AW6-AW7-AW8 -> 27253.708 | AX5: =IF(AND(AW4=0,AW5>=0), "",AW5/AW4) -> 1 | AZ5: =+AZ6-AZ7-AZ8 -> 0 | BA5: =IF(AND(AZ4=0,AZ5>=0), "",AZ5/AZ4) | BB5: =IF(AND(AZ5=0,AW5>0),100%,IF(AND(AZ5<0,AW5=0),(AZ5-AW5)/AZ5,IF(AND(AZ5>0,AW5>0),(AW5-AZ5)/AZ5,IF(AND(AZ5=0,AW5=0),"",(AW5-AZ5)/AZ5)))) -> 1 | BC5: =+BC6-BC7-BC8 -> 0 | BD5: =IF(AND(BC4=0,BC5>=0), "",BC5/BC4) | BF5: =IF(AND(AM5=0,BC5>0),100%,IF(AND(AM5<0,BC5=0),(AM5-BC5)/AM5,IF(AND(AM5>0,BC5>0),(BC5-AM5)/AM5,IF(AND(AM5=0,BC5=0),"",(BC5-AM5)/AM5)))) | BG5: =+BG6-BG7-BG8 -> 163522.25 | BH5: =IF(AND(BG4=0,BG5>=0), "",BG5/BG4) -> 1 | BJ5: =+BJ6-BJ7-BJ8 -> 0 | BK5: =IF(AND(BJ4=0,BJ5>=0), "",BJ5/BJ4) | BM5: =IF(AND(BC5=0,BJ5>0),100%,IF(AND(BC5<0,BJ5=0),(BC5-BJ5)/BC5,IF(AND(BC5>0,BJ5>0),(BJ5-BC5)/BC5,IF(AND(BC5=0,BJ5=0),"",(BJ5-BC5)/BC5)))) | BN5: =+BN6-BN7-BN8 -> 163522.25 | BO5: =IF(AND(BN4=0,BN5>=0), "",BN5/BN4) -> 1 | BQ5: =+BQ6-BQ7-BQ8 -> 0 | BR5: =IF(AND(BQ4=0,BQ5>=0), "",BQ5/BQ4) | BT5: =IF(AND(BJ5=0,BQ5>0),100%,IF(AND(BJ5<0,BQ5=0),(BJ5-BQ5)/BJ5,IF(AND(BJ5>0,BQ5>0),(BQ5-BJ5)/BJ5,IF(AND(BJ5=0,BQ5=0),"",(BQ5-BJ5)/BJ5)))) | BU5: =+BU6-BU7-BU8 -> 163522.25 | BV5: =IF(AND(BU4=0,BU5>=0), "",BU5/BU4) -> 1 | BX5: =+BX6-BX7-BX8 -> 0 | BY5: =IF(AND(BX4=0,BX5>=0), "",BX5/BX4) | BZ5: =IF(AND(BX5=0,BU5>0),100%,IF(AND(BX5<0,BU5=0),(BX5-BU5)/BX5,IF(AND(BX5>0,BU5>0),(BU5-BX5)/BX5,IF(AND(BX5=0,BU5=0),"",(BU5-BX5)/BX5)))) -> 1 | CA5: =+CA6-CA7-CA8 -> 0 | CB5: =IF(AND(CA4=0,CA5>=0), "",CA5/CA4) | CD5: =IF(AND(BQ5=0,CA5>0),100%,IF(AND(BQ5<0,CA5=0),(BQ5-CA5)/BQ5,IF(AND(BQ5>0,CA5>0),(CA5-BQ5)/BQ5,IF(AND(BQ5=0,CA5=0),"",(CA5-BQ5)/BQ5)))) | CE5: =+CE6-CE7-CE8 -> 163522.25 | CF5: =IF(AND(CE4=0,CE5>=0), "",CE5/CE4) -> 1 | CH5: =+CH6-CH7-CH8 -> 0 | CI5: =IF(AND(CH4=0,CH5>=0), "",CH5/CH4) | CK5: =IF(AND(CA5=0,CH5>0),100%,IF(AND(CA5<0,CH5=0),(CA5-CH5)/CA5,IF(AND(CA5>0,CH5>0),(CH5-CA5)/CA5,IF(AND(CA5=0,CH5=0),"",(CH5-CA5)/CA5)))) | CL5: =+CL6-CL7-CL8 -> 163522.25 | CM5: =IF(AND(CL4=0,CL5>=0), "",CL5/CL4) -> 1 | CO5: =+CO6-CO7-CO8 -> 0 | CP5: =IF(AND(CO4=0,CO5>=0), "",CO5/CO4) | CR5: =IF(AND(CH5=0,CO5>0),100%,IF(AND(CH5<0,CO5=0),(CH5-CO5)/CH5,IF(AND(CH5>0,CO5>0),(CO5-CH5)/CH5,IF(AND(CH5=0,CO5=0),"",(CO5-CH5)/CH5)))) | CS5: =+CS6-CS7-CS8 -> 163522.25 | CT5: =IF(AND(CS4=0,CS5>=0), "",CS5/CS4) -> 1 | CV5: =+CV6-CV7-CV8 -> 0 | CW5: =IF(AND(CV4=0,CV5>=0), "",CV5/CV4) | CX5: =IF(AND(CV5=0,CS5>0),100%,IF(AND(CV5<0,CS5=0),(CV5-CS5)/CV5,IF(AND(CV5>0,CS5>0),(CS5-CV5)/CV5,IF(AND(CV5=0,CS5=0),"",(CS5-CV5)/CV5)))) -> 1
A6: Ingresos por venta de mercancía | B6: =+'N EERR RODEO'!B6 -> 0 | C6: =IF(AND(B4=0,B6>=0), "",B6/B4) | E6: =+'N EERR RODEO'!C6 -> 47933.03 | F6: =IF(AND(E4=0,E6>=0), "",E6/E4) -> 1 | H6: =+'N EERR RODEO'!D6 -> 51483.04 | I6: =IF(AND(H4=0,H6>=0), "",H6/H4) -> 1 | K6: =IF(AND(E6=0,H6>0),100%,IF(AND(E6<0,H6=0),(E6-H6)/E6,IF(AND(E6>0,H6>0),(H6-E6)/E6,IF(AND(E6=0,H6=0),"",(H6-E6)/E6)))) -> 0.074061873 | L6: =+E6+H6 -> 99416.07 | M6: =IF(AND(L4=0,L6>=0), "",L6/L4) -> 1 | O6: =+'N EERR RODEO'!E6 -> 64106.18 | P6: =IF(AND(O4=0,O6>=0), "",O6/O4) -> 1 | R6: =IF(AND(H6=0,O6>0),100%,IF(AND(H6<0,O6=0),(H6-O6)/H6,IF(AND(H6>0,O6>0),(O6-H6)/H6,IF(AND(H6=0,O6=0),"",(O6-H6)/H6)))) -> 0.24519026 | S6: =+L6+O6 -> 163522.25 | T6: =IF(AND(S4=0,S6>=0), "",S6/S4) -> 1 | W6: =IF(AND(V4=0,V6>=0), "",V6/V4) | X6: =IF(AND(V6=0,S6>0),100%,IF(AND(V6<0,S6=0),(V6-S6)/V6,IF(AND(V6>0,S6>0),(S6-V6)/V6,IF(AND(V6=0,S6=0),"",(S6-V6)/V6)))) -> 1 | Y6: =+'N EERR RODEO'!F6 -> 0 | Z6: =IF(AND(Y4=0,Y6>=0), "",Y6/Y4) | AB6: =IF(AND(O6=0,Y6>0),100%,IF(AND(O6<0,Y6=0),(O6-Y6)/O6,IF(AND(O6>0,Y6>0),(Y6-O6)/O6,IF(AND(O6=0,Y6=0),"",(Y6-O6)/O6)))) -> -1 | AC6: =+S6+Y6 -> 163522.25 | AD6: =IF(AND(AC4=0,AC6>=0), "",AC6/AC4) -> 1 | AF6: =+'N EERR RODEO'!G6 -> 0 | AG6: =IF(AND(AF4=0,AF6>=0), "",AF6/AF4) | AI6: =IF(AND(Y6=0,AF6>0),100%,IF(AND(Y6<0,AF6=0),(Y6-AF6)/Y6,IF(AND(Y6>0,AF6>0),(AF6-Y6)/Y6,IF(AND(Y6=0,AF6=0),"",(AF6-Y6)/Y6)))) | AJ6: =+AC6+AF6 -> 163522.25 | AK6: =IF(AND(AJ4=0,AJ6>=0), "",AJ6/AJ4) -> 1 | AM6: =+'N EERR RODEO'!H6 -> 0 | AN6: =IF(AND(AM4=0,AM6>=0), "",AM6/AM4) | AP6: =IF(AND(AF6=0,AM6>0),100%,IF(AND(AF6<0,AM6=0),(AF6-AM6)/AF6,IF(AND(AF6>0,AM6>0),(AM6-AF6)/AF6,IF(AND(AF6=0,AM6=0),"",(AM6-AF6)/AF6)))) | AQ6: =+AJ6+AM6 -> 163522.25 | AR6: =IF(AND(AQ4=0,AQ6>=0), "",AQ6/AQ4) -> 1 | AT6: =+V6*2 -> 0 | AU6: =IF(AND(AT4=0,AT6>=0), "",AT6/AT4) | AV6: =IF(AND(AT6=0,AQ6>0),100%,IF(AND(AT6<0,AQ6=0),(AT6-AQ6)/AT6,IF(AND(AT6>0,AQ6>0),(AQ6-AT6)/AT6,IF(AND(AT6=0,AQ6=0),"",(AQ6-AT6)/AT6)))) -> 1 | AW6: =+AQ6/6 -> 27253.708 | AX6: =IF(AND(AW4=0,AW6>=0), "",AW6/AW4) -> 1 | AZ6: =+AT6/6 -> 0 | BA6: =IF(AND(AZ4=0,AZ6>=0), "",AZ6/AZ4) | BB6: =IF(AND(AZ6=0,AW6>0),100%,IF(AND(AZ6<0,AW6=0),(AZ6-AW6)/AZ6,IF(AND(AZ6>0,AW6>0),(AW6-AZ6)/AZ6,IF(AND(AZ6=0,AW6=0),"",(AW6-AZ6)/AZ6)))) -> 1 | BC6: =+'N EERR RODEO'!I6 -> 0 | BD6: =IF(AND(BC4=0,BC6>=0), "",BC6/BC4) | BF6: =IF(AND(AM6=0,BC6>0),100%,IF(AND(AM6<0,BC6=0),(AM6-BC6)/AM6,IF(AND(AM6>0,BC6>0),(BC6-AM6)/AM6,IF(AND(AM6=0,BC6=0),"",(BC6-AM6)/AM6)))) | BG6: =+AQ6+BC6 -> 163522.25 | BH6: =IF(AND(BG4=0,BG6>=0), "",BG6/BG4) -> 1 | BJ6: =+'N EERR RODEO'!J6 -> 0 | BK6: =IF(AND(BJ4=0,BJ6>=0), "",BJ6/BJ4) | BM6: =IF(AND(BC6=0,BJ6>0),100%,IF(AND(BC6<0,BJ6=0),(BC6-BJ6)/BC6,IF(AND(BC6>0,BJ6>0),(BJ6-BC6)/BC6,IF(AND(BC6=0,BJ6=0),"",(BJ6-BC6)/BC6)))) | BN6: =+BG6+BJ6 -> 163522.25 | BO6: =IF(AND(BN4=0,BN6>=0), "",BN6/BN4) -> 1 | BQ6: =+'N EERR RODEO'!K6 -> 0 | BR6: =IF(AND(BQ4=0,BQ6>=0), "",BQ6/BQ4) | BT6: =IF(AND(BJ6=0,BQ6>0),100%,IF(AND(BJ6<0,BQ6=0),(BJ6-BQ6)/BJ6,IF(AND(BJ6>0,BQ6>0),(BQ6-BJ6)/BJ6,IF(AND(BJ6=0,BQ6=0),"",(BQ6-BJ6)/BJ6)))) | BU6: =+BN6+BQ6 -> 163522.25 | BV6: =IF(AND(BU4=0,BU6>=0), "",BU6/BU4) -> 1 | BX6: =+AZ6*9 -> 0 | BY6: =IF(AND(BX4=0,BX6>=0), "",BX6/BX4) | BZ6: =IF(AND(BX6=0,BU6>0),100%,IF(AND(BX6<0,BU6=0),(BX6-BU6)/BX6,IF(AND(BX6>0,BU6>0),(BU6-BX6)/BX6,IF(AND(BX6=0,BU6=0),"",(BU6-BX6)/BX6)))) -> 1 | CA6: =+'N EERR RODEO'!L6 -> 0 | CB6: =IF(AND(CA4=0,CA6>=0), "",CA6/CA4) | CD6: =IF(AND(BQ6=0,CA6>0),100%,IF(AND(BQ6<0,CA6=0),(BQ6-CA6)/BQ6,IF(AND(BQ6>0,CA6>0),(CA6-BQ6)/BQ6,IF(AND(BQ6=0,CA6=0),"",(CA6-BQ6)/BQ6)))) | CE6: =+BU6+CA6 -> 163522.25 | CF6: =IF(AND(CE4=0,CE6>=0), "",CE6/CE4) -> 1 | CH6: =+'N EERR RODEO'!M6 -> 0 | CI6: =IF(AND(CH4=0,CH6>=0), "",CH6/CH4) | CK6: =IF(AND(CA6=0,CH6>0),100%,IF(AND(CA6<0,CH6=0),(CA6-CH6)/CA6,IF(AND(CA6>0,CH6>0),(CH6-CA6)/CA6,IF(AND(CA6=0,CH6=0),"",(CH6-CA6)/CA6)))) | CL6: =+CE6+CH6 -> 163522.25 | CM6: =IF(AND(CL4=0,CL6>=0), "",CL6/CL4) -> 1 | CO6: =+'N EERR RODEO'!N6 -> 0 | CP6: =IF(AND(CO4=0,CO6>=0), "",CO6/CO4) | CR6: =IF(AND(CH6=0,CO6>0),100%,IF(AND(CH6<0,CO6=0),(CH6-CO6)/CH6,IF(AND(CH6>0,CO6>0),(CO6-CH6)/CH6,IF(AND(CH6=0,CO6=0),"",(CO6-CH6)/CH6)))) | CS6: =+CL6+CO6 -> 163522.25 | CT6: =IF(AND(CS4=0,CS6>=0), "",CS6/CS4) -> 1 | CV6: =+AZ6*12 -> 0 | CW6: =IF(AND(CV4=0,CV6>=0), "",CV6/CV4) | CX6: =IF(AND(CV6=0,CS6>0),100%,IF(AND(CV6<0,CS6=0),(CV6-CS6)/CV6,IF(AND(CV6>0,CS6>0),(CS6-CV6)/CV6,IF(AND(CV6=0,CS6=0),"",(CS6-CV6)/CV6)))) -> 1
A7: Devoluciones sobre ventas | B7: =+'N EERR RODEO'!B7 -> 0 | C7: =IF(AND(B4=0,B7>=0), "",B7/B4) | E7: =+'N EERR RODEO'!C7 -> 0 | F7: =IF(AND(E4=0,E7>=0), "",E7/E4) -> 0 | H7: =+'N EERR RODEO'!D7 -> 0 | I7: =IF(AND(H4=0,H7>=0), "",H7/H4) -> 0 | K7: =IF(AND(E7=0,H7>0),100%,IF(AND(E7<0,H7=0),(E7-H7)/E7,IF(AND(E7>0,H7>0),(H7-E7)/E7,IF(AND(E7=0,H7=0),"",(H7-E7)/E7)))) | L7: =+E7+H7 -> 0 | M7: =IF(AND(L4=0,L7>=0), "",L7/L4) -> 0 | O7: =+'N EERR RODEO'!E7 -> 0 | P7: =IF(AND(O4=0,O7>=0), "",O7/O4) -> 0 | R7: =IF(AND(H7=0,O7>0),100%,IF(AND(H7<0,O7=0),(H7-O7)/H7,IF(AND(H7>0,O7>0),(O7-H7)/H7,IF(AND(H7=0,O7=0),"",(O7-H7)/H7)))) | S7: =+L7+O7 -> 0 | T7: =IF(AND(S4=0,S7>=0), "",S7/S4) -> 0 | W7: =IF(AND(V4=0,V7>=0), "",V7/V4) | X7: =IF(AND(V7=0,S7>0),100%,IF(AND(V7<0,S7=0),(V7-S7)/V7,IF(AND(V7>0,S7>0),(S7-V7)/V7,IF(AND(V7=0,S7=0),"",(S7-V7)/V7)))) | Y7: =+'N EERR RODEO'!F7 -> 0 | Z7: =IF(AND(Y4=0,Y7>=0), "",Y7/Y4) | AB7: =IF(AND(O7=0,Y7>0),100%,IF(AND(O7<0,Y7=0),(O7-Y7)/O7,IF(AND(O7>0,Y7>0),(Y7-O7)/O7,IF(AND(O7=0,Y7=0),"",(Y7-O7)/O7)))) | AC7: =+S7+Y7 -> 0 | AD7: =IF(AND(AC4=0,AC7>=0), "",AC7/AC4) -> 0 | AF7: =+'N EERR RODEO'!G7 -> 0 | AG7: =IF(AND(AF4=0,AF7>=0), "",AF7/AF4) | AI7: =IF(AND(Y7=0,AF7>0),100%,IF(AND(Y7<0,AF7=0),(Y7-AF7)/Y7,IF(AND(Y7>0,AF7>0),(AF7-Y7)/Y7,IF(AND(Y7=0,AF7=0),"",(AF7-Y7)/Y7)))) | AJ7: =+AC7+AF7 -> 0 | AK7: =IF(AND(AJ4=0,AJ7>=0), "",AJ7/AJ4) -> 0 | AM7: =+'N EERR RODEO'!H7 -> 0 | AN7: =IF(AND(AM4=0,AM7>=0), "",AM7/AM4) | AP7: =IF(AND(AF7=0,AM7>0),100%,IF(AND(AF7<0,AM7=0),(AF7-AM7)/AF7,IF(AND(AF7>0,AM7>0),(AM7-AF7)/AF7,IF(AND(AF7=0,AM7=0),"",(AM7-AF7)/AF7)))) | AQ7: =+AJ7+AM7 -> 0 | AR7: =IF(AND(AQ4=0,AQ7>=0), "",AQ7/AQ4) -> 0 | AT7: =+V7*2 -> 0 | AU7: =IF(AND(AT4=0,AT7>=0), "",AT7/AT4) | AV7: =IF(AND(AT7=0,AQ7>0),100%,IF(AND(AT7<0,AQ7=0),(AT7-AQ7)/AT7,IF(AND(AT7>0,AQ7>0),(AQ7-AT7)/AT7,IF(AND(AT7=0,AQ7=0),"",(AQ7-AT7)/AT7)))) | AW7: =+AQ7/6 -> 0 | AX7: =IF(AND(AW4=0,AW7>=0), "",AW7/AW4) -> 0 | AZ7: =+AT7/6 -> 0 | BA7: =IF(AND(AZ4=0,AZ7>=0), "",AZ7/AZ4) | BB7: =IF(AND(AZ7=0,AW7>0),100%,IF(AND(AZ7<0,AW7=0),(AZ7-AW7)/AZ7,IF(AND(AZ7>0,AW7>0),(AW7-AZ7)/AZ7,IF(AND(AZ7=0,AW7=0),"",(AW7-AZ7)/AZ7)))) | BC7: =+'N EERR RODEO'!I7 -> 0 | BD7: =IF(AND(BC4=0,BC7>=0), "",BC7/BC4) | BF7: =IF(AND(AM7=0,BC7>0),100%,IF(AND(AM7<0,BC7=0),(AM7-BC7)/AM7,IF(AND(AM7>0,BC7>0),(BC7-AM7)/AM7,IF(AND(AM7=0,BC7=0),"",(BC7-AM7)/AM7)))) | BG7: =+AQ7+BC7 -> 0 | BH7: =IF(AND(BG4=0,BG7>=0), "",BG7/BG4) -> 0 | BJ7: =+'N EERR RODEO'!J7 -> 0 | BK7: =IF(AND(BJ4=0,BJ7>=0), "",BJ7/BJ4) | BM7: =IF(AND(BC7=0,BJ7>0),100%,IF(AND(BC7<0,BJ7=0),(BC7-BJ7)/BC7,IF(AND(BC7>0,BJ7>0),(BJ7-BC7)/BC7,IF(AND(BC7=0,BJ7=0),"",(BJ7-BC7)/BC7)))) | BN7: =+BG7+BJ7 -> 0 | BO7: =IF(AND(BN4=0,BN7>=0), "",BN7/BN4) -> 0 | BQ7: =+'N EERR RODEO'!K7 -> 0 | BR7: =IF(AND(BQ4=0,BQ7>=0), "",BQ7/BQ4) | BT7: =IF(AND(BJ7=0,BQ7>0),100%,IF(AND(BJ7<0,BQ7=0),(BJ7-BQ7)/BJ7,IF(AND(BJ7>0,BQ7>0),(BQ7-BJ7)/BJ7,IF(AND(BJ7=0,BQ7=0),"",(BQ7-BJ7)/BJ7)))) | BU7: =+BN7+BQ7 -> 0 | BV7: =IF(AND(BU4=0,BU7>=0), "",BU7/BU4) -> 0 | BX7: =+AZ7*9 -> 0 | BY7: =IF(AND(BX4=0,BX7>=0), "",BX7/BX4) | BZ7: =IF(AND(BX7=0,BU7>0),100%,IF(AND(BX7<0,BU7=0),(BX7-BU7)/BX7,IF(AND(BX7>0,BU7>0),(BU7-BX7)/BX7,IF(AND(BX7=0,BU7=0),"",(BU7-BX7)/BX7)))) | CA7: =+'N EERR RODEO'!L7 -> 0 | CB7: =IF(AND(CA4=0,CA7>=0), "",CA7/CA4) | CD7: =IF(AND(BQ7=0,CA7>0),100%,IF(AND(BQ7<0,CA7=0),(BQ7-CA7)/BQ7,IF(AND(BQ7>0,CA7>0),(CA7-BQ7)/BQ7,IF(AND(BQ7=0,CA7=0),"",(CA7-BQ7)/BQ7)))) | CE7: =+BU7+CA7 -> 0 | CF7: =IF(AND(CE4=0,CE7>=0), "",CE7/CE4) -> 0 | CH7: =+'N EERR RODEO'!M7 -> 0 | CI7: =IF(AND(CH4=0,CH7>=0), "",CH7/CH4) | CK7: =IF(AND(CA7=0,CH7>0),100%,IF(AND(CA7<0,CH7=0),(CA7-CH7)/CA7,IF(AND(CA7>0,CH7>0),(CH7-CA7)/CA7,IF(AND(CA7=0,CH7=0),"",(CH7-CA7)/CA7)))) | CL7: =+CE7+CH7 -> 0 | CM7: =IF(AND(CL4=0,CL7>=0), "",CL7/CL4) -> 0 | CO7: =+'N EERR RODEO'!N7 -> 0 | CP7: =IF(AND(CO4=0,CO7>=0), "",CO7/CO4) | CR7: =IF(AND(CH7=0,CO7>0),100%,IF(AND(CH7<0,CO7=0),(CH7-CO7)/CH7,IF(AND(CH7>0,CO7>0),(CO7-CH7)/CH7,IF(AND(CH7=0,CO7=0),"",(CO7-CH7)/CH7)))) | CS7: =+CL7+CO7 -> 0 | CT7: =IF(AND(CS4=0,CS7>=0), "",CS7/CS4) -> 0 | CV7: =+AZ7*12 -> 0 | CW7: =IF(AND(CV4=0,CV7>=0), "",CV7/CV4) | CX7: =IF(AND(CV7=0,CS7>0),100%,IF(AND(CV7<0,CS7=0),(CV7-CS7)/CV7,IF(AND(CV7>0,CS7>0),(CS7-CV7)/CV7,IF(AND(CV7=0,CS7=0),"",(CS7-CV7)/CV7))))
A8: Descuentos sobre ventas | B8: =+'N EERR RODEO'!B8+'N EERR RODEO'!B9 -> 0 | C8: =IF(AND(B5=0,B8>=0), "",B8/B5) | E8: =+'N EERR RODEO'!C8+'N EERR RODEO'!C9 -> 0 | F8: =IF(AND(E5=0,E8>=0), "",E8/E5) -> 0 | H8: =+'N EERR RODEO'!D8+'N EERR RODEO'!D9 -> 0 | I8: =IF(AND(H5=0,H8>=0), "",H8/H5) -> 0 | K8: =IF(AND(E8=0,H8>0),100%,IF(AND(E8<0,H8=0),(E8-H8)/E8,IF(AND(E8>0,H8>0),(H8-E8)/E8,IF(AND(E8=0,H8=0),"",(H8-E8)/E8)))) | L8: =+E8+H8 -> 0 | M8: =IF(AND(L5=0,L8>=0), "",L8/L5) -> 0 | O8: =+'N EERR RODEO'!E8+'N EERR RODEO'!E9 -> 0 | P8: =IF(AND(O5=0,O8>=0), "",O8/O5) -> 0 | R8: =IF(AND(H8=0,O8>0),100%,IF(AND(H8<0,O8=0),(H8-O8)/H8,IF(AND(H8>0,O8>0),(O8-H8)/H8,IF(AND(H8=0,O8=0),"",(O8-H8)/H8)))) | S8: =+L8+O8 -> 0 | T8: =IF(AND(S5=0,S8>=0), "",S8/S5) -> 0 | W8: =IF(AND(V5=0,V8>=0), "",V8/V5) | X8: =IF(AND(V8=0,S8>0),100%,IF(AND(V8<0,S8=0),(V8-S8)/V8,IF(AND(V8>0,S8>0),(S8-V8)/V8,IF(AND(V8=0,S8=0),"",(S8-V8)/V8)))) | Y8: =+'N EERR RODEO'!F8+'N EERR RODEO'!F9 -> 0 | Z8: =IF(AND(Y5=0,Y8>=0), "",Y8/Y5) | AB8: =IF(AND(O8=0,Y8>0),100%,IF(AND(O8<0,Y8=0),(O8-Y8)/O8,IF(AND(O8>0,Y8>0),(Y8-O8)/O8,IF(AND(O8=0,Y8=0),"",(Y8-O8)/O8)))) | AC8: =+S8+Y8 -> 0 | AD8: =IF(AND(AC5=0,AC8>=0), "",AC8/AC5) -> 0 | AF8: =+'N EERR RODEO'!G8+'N EERR RODEO'!G9 -> 0 | AG8: =IF(AND(AF5=0,AF8>=0), "",AF8/AF5) | AI8: =IF(AND(Y8=0,AF8>0),100%,IF(AND(Y8<0,AF8=0),(Y8-AF8)/Y8,IF(AND(Y8>0,AF8>0),(AF8-Y8)/Y8,IF(AND(Y8=0,AF8=0),"",(AF8-Y8)/Y8)))) | AJ8: =+AC8+AF8 -> 0 | AK8: =IF(AND(AJ5=0,AJ8>=0), "",AJ8/AJ5) -> 0 | AM8: =+'N EERR RODEO'!H8+'N EERR RODEO'!H9 -> 0 | AN8: =IF(AND(AM5=0,AM8>=0), "",AM8/AM5) | AP8: =IF(AND(AF8=0,AM8>0),100%,IF(AND(AF8<0,AM8=0),(AF8-AM8)/AF8,IF(AND(AF8>0,AM8>0),(AM8-AF8)/AF8,IF(AND(AF8=0,AM8=0),"",(AM8-AF8)/AF8)))) | AQ8: =+AJ8+AM8 -> 0 | AR8: =IF(AND(AQ5=0,AQ8>=0), "",AQ8/AQ5) -> 0 | AT8: =+V8*2 -> 0 | AU8: =IF(AND(AT5=0,AT8>=0), "",AT8/AT5) | AV8: =IF(AND(AT8=0,AQ8>0),100%,IF(AND(AT8<0,AQ8=0),(AT8-AQ8)/AT8,IF(AND(AT8>0,AQ8>0),(AQ8-AT8)/AT8,IF(AND(AT8=0,AQ8=0),"",(AQ8-AT8)/AT8)))) | AW8: =+AQ8/6 -> 0 | AX8: =IF(AND(AW5=0,AW8>=0), "",AW8/AW5) -> 0 | AZ8: =+AT8/6 -> 0 | BA8: =IF(AND(AZ5=0,AZ8>=0), "",AZ8/AZ5) | BB8: =IF(AND(AZ8=0,AW8>0),100%,IF(AND(AZ8<0,AW8=0),(AZ8-AW8)/AZ8,IF(AND(AZ8>0,AW8>0),(AW8-AZ8)/AZ8,IF(AND(AZ8=0,AW8=0),"",(AW8-AZ8)/AZ8)))) | BC8: =+'N EERR RODEO'!I8+'N EERR RODEO'!I9 -> 0 | BD8: =IF(AND(BC5=0,BC8>=0), "",BC8/BC5) | BF8: =IF(AND(AM8=0,BC8>0),100%,IF(AND(AM8<0,BC8=0),(AM8-BC8)/AM8,IF(AND(AM8>0,BC8>0),(BC8-AM8)/AM8,IF(AND(AM8=0,BC8=0),"",(BC8-AM8)/AM8)))) | BG8: =+AQ8+BC8 -> 0 | BH8: =IF(AND(BG5=0,BG8>=0), "",BG8/BG5) -> 0 | BJ8: =+'N EERR RODEO'!J8+'N EERR RODEO'!J9 -> 0 | BK8: =IF(AND(BJ5=0,BJ8>=0), "",BJ8/BJ5) | BM8: =IF(AND(BC8=0,BJ8>0),100%,IF(AND(BC8<0,BJ8=0),(BC8-BJ8)/BC8,IF(AND(BC8>0,BJ8>0),(BJ8-BC8)/BC8,IF(AND(BC8=0,BJ8=0),"",(BJ8-BC8)/BC8)))) | BN8: =+BG8+BJ8 -> 0 | BO8: =IF(AND(BN5=0,BN8>=0), "",BN8/BN5) -> 0 | BQ8: =+'N EERR RODEO'!K8+'N EERR RODEO'!K9 -> 0 | BR8: =IF(AND(BQ5=0,BQ8>=0), "",BQ8/BQ5) | BT8: =IF(AND(BJ8=0,BQ8>0),100%,IF(AND(BJ8<0,BQ8=0),(BJ8-BQ8)/BJ8,IF(AND(BJ8>0,BQ8>0),(BQ8-BJ8)/BJ8,IF(AND(BJ8=0,BQ8=0),"",(BQ8-BJ8)/BJ8)))) | BU8: =+BN8+BQ8 -> 0 | BV8: =IF(AND(BU5=0,BU8>=0), "",BU8/BU5) -> 0 | BX8: =+AZ8*9 -> 0 | BY8: =IF(AND(BX5=0,BX8>=0), "",BX8/BX5) | BZ8: =IF(AND(BX8=0,BU8>0),100%,IF(AND(BX8<0,BU8=0),(BX8-BU8)/BX8,IF(AND(BX8>0,BU8>0),(BU8-BX8)/BX8,IF(AND(BX8=0,BU8=0),"",(BU8-BX8)/BX8)))) | CA8: =+'N EERR RODEO'!L8+'N EERR RODEO'!L9 -> 0 | CB8: =IF(AND(CA5=0,CA8>=0), "",CA8/CA5) | CD8: =IF(AND(BQ8=0,CA8>0),100%,IF(AND(BQ8<0,CA8=0),(BQ8-CA8)/BQ8,IF(AND(BQ8>0,CA8>0),(CA8-BQ8)/BQ8,IF(AND(BQ8=0,CA8=0),"",(CA8-BQ8)/BQ8)))) | CE8: =+BU8+CA8 -> 0 | CF8: =IF(AND(CE5=0,CE8>=0), "",CE8/CE5) -> 0 | CH8: =+'N EERR RODEO'!M8+'N EERR RODEO'!M9 -> 0 | CI8: =IF(AND(CH5=0,CH8>=0), "",CH8/CH5) | CK8: =IF(AND(CA8=0,CH8>0),100%,IF(AND(CA8<0,CH8=0),(CA8-CH8)/CA8,IF(AND(CA8>0,CH8>0),(CH8-CA8)/CA8,IF(AND(CA8=0,CH8=0),"",(CH8-CA8)/CA8)))) | CL8: =+CE8+CH8 -> 0 | CM8: =IF(AND(CL5=0,CL8>=0), "",CL8/CL5) -> 0 | CO8: =+'N EERR RODEO'!N8+'N EERR RODEO'!N9 -> 0 | CP8: =IF(AND(CO5=0,CO8>=0), "",CO8/CO5) | CR8: =IF(AND(CH8=0,CO8>0),100%,IF(AND(CH8<0,CO8=0),(CH8-CO8)/CH8,IF(AND(CH8>0,CO8>0),(CO8-CH8)/CH8,IF(AND(CH8=0,CO8=0),"",(CO8-CH8)/CH8)))) | CS8: =+CL8+CO8 -> 0 | CT8: =IF(AND(CS5=0,CS8>=0), "",CS8/CS5) -> 0 | CV8: =+AZ8*12 -> 0 | CW8: =IF(AND(CV5=0,CV8>=0), "",CV8/CV5) | CX8: =IF(AND(CV8=0,CS8>0),100%,IF(AND(CV8<0,CS8=0),(CV8-CS8)/CV8,IF(AND(CV8>0,CS8>0),(CS8-CV8)/CV8,IF(AND(CV8=0,CS8=0),"",(CS8-CV8)/CV8))))
K9: =IF(AND(E9=0,H9>0),100%,IF(AND(E9<0,H9=0),(E9-H9)/E9,IF(AND(E9>0,H9>0),(H9-E9)/E9,IF(AND(E9=0,H9=0),"",(H9-E9)/E9)))) | R9: =IF(AND(H9=0,O9>0),100%,IF(AND(H9<0,O9=0),(H9-O9)/H9,IF(AND(H9>0,O9>0),(O9-H9)/H9,IF(AND(H9=0,O9=0),"",(O9-H9)/H9)))) | X9: =IF(AND(V9=0,S9>0),100%,IF(AND(V9<0,S9=0),(V9-S9)/V9,IF(AND(V9>0,S9>0),(S9-V9)/V9,IF(AND(V9=0,S9=0),"",(S9-V9)/V9)))) | AB9: =IF(AND(O9=0,Y9>0),100%,IF(AND(O9<0,Y9=0),(O9-Y9)/O9,IF(AND(O9>0,Y9>0),(Y9-O9)/O9,IF(AND(O9=0,Y9=0),"",(Y9-O9)/O9)))) | AI9: =IF(AND(Y9=0,AF9>0),100%,IF(AND(Y9<0,AF9=0),(Y9-AF9)/Y9,IF(AND(Y9>0,AF9>0),(AF9-Y9)/Y9,IF(AND(Y9=0,AF9=0),"",(AF9-Y9)/Y9)))) | AJ9: =+AC9+AF9 -> 0 | AP9: =IF(AND(AF9=0,AM9>0),100%,IF(AND(AF9<0,AM9=0),(AF9-AM9)/AF9,IF(AND(AF9>0,AM9>0),(AM9-AF9)/AF9,IF(AND(AF9=0,AM9=0),"",(AM9-AF9)/AF9)))) | AQ9: =+AJ9+AM9 -> 0 | AT9: =+V9*2 -> 0 | AV9: =IF(AND(AT9=0,AQ9>0),100%,IF(AND(AT9<0,AQ9=0),(AT9-AQ9)/AT9,IF(AND(AT9>0,AQ9>0),(AQ9-AT9)/AT9,IF(AND(AT9=0,AQ9=0),"",(AQ9-AT9)/AT9)))) | AZ9: =+AT9/6 -> 0 | BB9: =IF(AND(AZ9=0,AW9>0),100%,IF(AND(AZ9<0,AW9=0),(AZ9-AW9)/AZ9,IF(AND(AZ9>0,AW9>0),(AW9-AZ9)/AZ9,IF(AND(AZ9=0,AW9=0),"",(AW9-AZ9)/AZ9)))) | BF9: =IF(AND(AM9=0,BC9>0),100%,IF(AND(AM9<0,BC9=0),(AM9-BC9)/AM9,IF(AND(AM9>0,BC9>0),(BC9-AM9)/AM9,IF(AND(AM9=0,BC9=0),"",(BC9-AM9)/AM9)))) | BG9: =+AQ9+BC9 -> 0 | BM9: =IF(AND(BC9=0,BJ9>0),100%,IF(AND(BC9<0,BJ9=0),(BC9-BJ9)/BC9,IF(AND(BC9>0,BJ9>0),(BJ9-BC9)/BC9,IF(AND(BC9=0,BJ9=0),"",(BJ9-BC9)/BC9)))) | BN9: =+BG9+BJ9 -> 0 | BT9: =IF(AND(BJ9=0,BQ9>0),100%,IF(AND(BJ9<0,BQ9=0),(BJ9-BQ9)/BJ9,IF(AND(BJ9>0,BQ9>0),(BQ9-BJ9)/BJ9,IF(AND(BJ9=0,BQ9=0),"",(BQ9-BJ9)/BJ9)))) | BU9: =+BN9+BQ9 -> 0 | BX9: =+AZ9*9 -> 0 | BZ9: =IF(AND(BX9=0,BU9>0),100%,IF(AND(BX9<0,BU9=0),(BX9-BU9)/BX9,IF(AND(BX9>0,BU9>0),(BU9-BX9)/BX9,IF(AND(BX9=0,BU9=0),"",(BU9-BX9)/BX9)))) | CD9: =IF(AND(BQ9=0,CA9>0),100%,IF(AND(BQ9<0,CA9=0),(BQ9-CA9)/BQ9,IF(AND(BQ9>0,CA9>0),(CA9-BQ9)/BQ9,IF(AND(BQ9=0,CA9=0),"",(CA9-BQ9)/BQ9)))) | CK9: =IF(AND(CA9=0,CH9>0),100%,IF(AND(CA9<0,CH9=0),(CA9-CH9)/CA9,IF(AND(CA9>0,CH9>0),(CH9-CA9)/CA9,IF(AND(CA9=0,CH9=0),"",(CH9-CA9)/CA9)))) | CL9: =+CE9+CH9 -> 0 | CR9: =IF(AND(CH9=0,CO9>0),100%,IF(AND(CH9<0,CO9=0),(CH9-CO9)/CH9,IF(AND(CH9>0,CO9>0),(CO9-CH9)/CH9,IF(AND(CH9=0,CO9=0),"",(CO9-CH9)/CH9)))) | CS9: =+CL9+CO9 -> 0 | CV9: =+AZ9*12 -> 0 | CX9: =IF(AND(CV9=0,CS9>0),100%,IF(AND(CV9<0,CS9=0),(CV9-CS9)/CV9,IF(AND(CV9>0,CS9>0),(CS9-CV9)/CV9,IF(AND(CV9=0,CS9=0),"",(CS9-CV9)/CV9))))
A10: Subtotal Ingresos por Servicios | B10: =SUM(B11:B14) -> 0 | C10: =IF(AND(B4=0,B10>=0), "",B10/B4) | E10: =SUM(E11:E14) -> 0 | F10: =IF(AND(E4=0,E10>=0), "",E10/E4) -> 0 | H10: =SUM(H11:H14) -> 0 | I10: =IF(AND(H4=0,H10>=0), "",H10/H4) -> 0 | K10: =IF(AND(E10=0,H10>0),100%,IF(AND(E10<0,H10=0),(E10-H10)/E10,IF(AND(E10>0,H10>0),(H10-E10)/E10,IF(AND(E10=0,H10=0),"",(H10-E10)/E10)))) | L10: =SUM(L11:L14) -> 0 | M10: =IF(AND(L4=0,L10>=0), "",L10/L4) -> 0 | O10: =SUM(O11:O14) -> 0 | P10: =IF(AND(O4=0,O10>=0), "",O10/O4) -> 0 | R10: =IF(AND(H10=0,O10>0),100%,IF(AND(H10<0,O10=0),(H10-O10)/H10,IF(AND(H10>0,O10>0),(O10-H10)/H10,IF(AND(H10=0,O10=0),"",(O10-H10)/H10)))) | S10: =SUM(S11:S14) -> 0 | T10: =IF(AND(S4=0,S10>=0), "",S10/S4) -> 0 | V10: =SUM(V11:V14) -> 0 | W10: =IF(AND(V4=0,V10>=0), "",V10/V4) | X10: =IF(AND(V10=0,S10>0),100%,IF(AND(V10<0,S10=0),(V10-S10)/V10,IF(AND(V10>0,S10>0),(S10-V10)/V10,IF(AND(V10=0,S10=0),"",(S10-V10)/V10)))) | Y10: =SUM(Y11:Y14) -> 0 | Z10: =IF(AND(Y4=0,Y10>=0), "",Y10/Y4) | AB10: =IF(AND(O10=0,Y10>0),100%,IF(AND(O10<0,Y10=0),(O10-Y10)/O10,IF(AND(O10>0,Y10>0),(Y10-O10)/O10,IF(AND(O10=0,Y10=0),"",(Y10-O10)/O10)))) | AC10: =SUM(AC11:AC14) -> 0 | AD10: =IF(AND(AC4=0,AC10>=0), "",AC10/AC4) -> 0 | AF10: =SUM(AF11:AF14) -> 0 | AG10: =IF(AND(AF4=0,AF10>=0), "",AF10/AF4) | AI10: =IF(AND(Y10=0,AF10>0),100%,IF(AND(Y10<0,AF10=0),(Y10-AF10)/Y10,IF(AND(Y10>0,AF10>0),(AF10-Y10)/Y10,IF(AND(Y10=0,AF10=0),"",(AF10-Y10)/Y10)))) | AJ10: =SUM(AJ11:AJ14) -> 0 | AK10: =IF(AND(AJ4=0,AJ10>=0), "",AJ10/AJ4) -> 0 | AM10: =SUM(AM11:AM14) -> 0 | AN10: =IF(AND(AM4=0,AM10>=0), "",AM10/AM4) | AP10: =IF(AND(AF10=0,AM10>0),100%,IF(AND(AF10<0,AM10=0),(AF10-AM10)/AF10,IF(AND(AF10>0,AM10>0),(AM10-AF10)/AF10,IF(AND(AF10=0,AM10=0),"",(AM10-AF10)/AF10)))) | AQ10: =SUM(AQ11:AQ14) -> 0 | AR10: =IF(AND(AQ4=0,AQ10>=0), "",AQ10/AQ4) -> 0 | AT10: =SUM(AT11:AT14) -> 0 | AU10: =IF(AND(AT4=0,AT10>=0), "",AT10/AT4) | AV10: =IF(AND(AT10=0,AQ10>0),100%,IF(AND(AT10<0,AQ10=0),(AT10-AQ10)/AT10,IF(AND(AT10>0,AQ10>0),(AQ10-AT10)/AT10,IF(AND(AT10=0,AQ10=0),"",(AQ10-AT10)/AT10)))) | AW10: =SUM(AW11:AW14) -> 0 | AX10: =IF(AND(AW4=0,AW10>=0), "",AW10/AW4) -> 0 | AZ10: =SUM(AZ11:AZ14) -> 0 | BA10: =IF(AND(AZ4=0,AZ10>=0), "",AZ10/AZ4) | BB10: =IF(AND(AZ10=0,AW10>0),100%,IF(AND(AZ10<0,AW10=0),(AZ10-AW10)/AZ10,IF(AND(AZ10>0,AW10>0),(AW10-AZ10)/AZ10,IF(AND(AZ10=0,AW10=0),"",(AW10-AZ10)/AZ10)))) | BC10: =SUM(BC11:BC14) -> 0 | BD10: =IF(AND(BC4=0,BC10>=0), "",BC10/BC4) | BF10: =IF(AND(AM10=0,BC10>0),100%,IF(AND(AM10<0,BC10=0),(AM10-BC10)/AM10,IF(AND(AM10>0,BC10>0),(BC10-AM10)/AM10,IF(AND(AM10=0,BC10=0),"",(BC10-AM10)/AM10)))) | BG10: =SUM(BG11:BG14) -> 0 | BH10: =IF(AND(BG4=0,BG10>=0), "",BG10/BG4) -> 0 | BJ10: =SUM(BJ11:BJ14) -> 0 | BK10: =IF(AND(BJ4=0,BJ10>=0), "",BJ10/BJ4) | BM10: =IF(AND(BC10=0,BJ10>0),100%,IF(AND(BC10<0,BJ10=0),(BC10-BJ10)/BC10,IF(AND(BC10>0,BJ10>0),(BJ10-BC10)/BC10,IF(AND(BC10=0,BJ10=0),"",(BJ10-BC10)/BC10)))) | BN10: =SUM(BN11:BN14) -> 0 | BO10: =IF(AND(BN4=0,BN10>=0), "",BN10/BN4) -> 0 | BQ10: =SUM(BQ11:BQ14) -> 0 | BR10: =IF(AND(BQ4=0,BQ10>=0), "",BQ10/BQ4) | BT10: =IF(AND(BJ10=0,BQ10>0),100%,IF(AND(BJ10<0,BQ10=0),(BJ10-BQ10)/BJ10,IF(AND(BJ10>0,BQ10>0),(BQ10-BJ10)/BJ10,IF(AND(BJ10=0,BQ10=0),"",(BQ10-BJ10)/BJ10)))) | BU10: =SUM(BU11:BU14) -> 0 | BV10: =IF(AND(BU4=0,BU10>=0), "",BU10/BU4) -> 0 | BX10: =SUM(BX11:BX14) -> 0 | BY10: =IF(AND(BX4=0,BX10>=0), "",BX10/BX4) | BZ10: =IF(AND(BX10=0,BU10>0),100%,IF(AND(BX10<0,BU10=0),(BX10-BU10)/BX10,IF(AND(BX10>0,BU10>0),(BU10-BX10)/BX10,IF(AND(BX10=0,BU10=0),"",(BU10-BX10)/BX10)))) | CA10: =SUM(CA11:CA14) -> 0 | CB10: =IF(AND(CA4=0,CA10>=0), "",CA10/CA4) | CD10: =IF(AND(BQ10=0,CA10>0),100%,IF(AND(BQ10<0,CA10=0),(BQ10-CA10)/BQ10,IF(AND(BQ10>0,CA10>0),(CA10-BQ10)/BQ10,IF(AND(BQ10=0,CA10=0),"",(CA10-BQ10)/BQ10)))) | CE10: =SUM(CE11:CE14) -> 0 | CF10: =IF(AND(CE4=0,CE10>=0), "",CE10/CE4) -> 0 | CH10: =SUM(CH11:CH14) -> 0 | CI10: =IF(AND(CH4=0,CH10>=0), "",CH10/CH4) | CK10: =IF(AND(CA10=0,CH10>0),100%,IF(AND(CA10<0,CH10=0),(CA10-CH10)/CA10,IF(AND(CA10>0,CH10>0),(CH10-CA10)/CA10,IF(AND(CA10=0,CH10=0),"",(CH10-CA10)/CA10)))) | CL10: =SUM(CL11:CL14) -> 0 | CM10: =IF(AND(CL4=0,CL10>=0), "",CL10/CL4) -> 0 | CO10: =SUM(CO11:CO14) -> 0 | CP10: =IF(AND(CO4=0,CO10>=0), "",CO10/CO4) | CR10: =IF(AND(CH10=0,CO10>0),100%,IF(AND(CH10<0,CO10=0),(CH10-CO10)/CH10,IF(AND(CH10>0,CO10>0),(CO10-CH10)/CH10,IF(AND(CH10=0,CO10=0),"",(CO10-CH10)/CH10)))) | CS10: =SUM(CS11:CS14) -> 0 | CT10: =IF(AND(CS4=0,CS10>=0), "",CS10/CS4) -> 0 | CV10: =SUM(CV11:CV14) -> 0 | CW10: =IF(AND(CV4=0,CV10>=0), "",CV10/CV4) | CX10: =IF(AND(CV10=0,CS10>0),100%,IF(AND(CV10<0,CS10=0),(CV10-CS10)/CV10,IF(AND(CV10>0,CS10>0),(CS10-CV10)/CV10,IF(AND(CV10=0,CS10=0),"",(CS10-CV10)/CV10))))
A11: Ingresos por servicios del café | B11: =+'N EERR RODEO'!B10 -> 0 | C11: =IF(AND(B4=0,B11>=0), "",B11/B4) | E11: =+'N EERR RODEO'!C10 -> 0 | F11: =IF(AND(E4=0,E11>=0), "",E11/E4) -> 0 | H11: =+'N EERR RODEO'!D10 -> 0 | I11: =IF(AND(H4=0,H11>=0), "",H11/H4) -> 0 | K11: =IF(AND(E11=0,H11>0),100%,IF(AND(E11<0,H11=0),(E11-H11)/E11,IF(AND(E11>0,H11>0),(H11-E11)/E11,IF(AND(E11=0,H11=0),"",(H11-E11)/E11)))) | L11: =+E11+H11 -> 0 | M11: =IF(AND(L4=0,L11>=0), "",L11/L4) -> 0 | O11: =+'N EERR RODEO'!E10 -> 0 | P11: =IF(AND(O4=0,O11>=0), "",O11/O4) -> 0 | R11: =IF(AND(H11=0,O11>0),100%,IF(AND(H11<0,O11=0),(H11-O11)/H11,IF(AND(H11>0,O11>0),(O11-H11)/H11,IF(AND(H11=0,O11=0),"",(O11-H11)/H11)))) | S11: =+L11+O11 -> 0 | T11: =IF(AND(S4=0,S11>=0), "",S11/S4) -> 0 | W11: =IF(AND(V4=0,V11>=0), "",V11/V4) | X11: =IF(AND(V11=0,S11>0),100%,IF(AND(V11<0,S11=0),(V11-S11)/V11,IF(AND(V11>0,S11>0),(S11-V11)/V11,IF(AND(V11=0,S11=0),"",(S11-V11)/V11)))) | Y11: =+'N EERR RODEO'!F10 -> 0 | Z11: =IF(AND(Y4=0,Y11>=0), "",Y11/Y4) | AB11: =IF(AND(O11=0,Y11>0),100%,IF(AND(O11<0,Y11=0),(O11-Y11)/O11,IF(AND(O11>0,Y11>0),(Y11-O11)/O11,IF(AND(O11=0,Y11=0),"",(Y11-O11)/O11)))) | AC11: =+S11+Y11 -> 0 | AD11: =IF(AND(AC4=0,AC11>=0), "",AC11/AC4) -> 0 | AF11: =+'N EERR RODEO'!G10 -> 0 | AG11: =IF(AND(AF4=0,AF11>=0), "",AF11/AF4) | AI11: =IF(AND(Y11=0,AF11>0),100%,IF(AND(Y11<0,AF11=0),(Y11-AF11)/Y11,IF(AND(Y11>0,AF11>0),(AF11-Y11)/Y11,IF(AND(Y11=0,AF11=0),"",(AF11-Y11)/Y11)))) | AJ11: =+AC11+AF11 -> 0 | AK11: =IF(AND(AJ4=0,AJ11>=0), "",AJ11/AJ4) -> 0 | AM11: =+'N EERR RODEO'!H10 -> 0 | AN11: =IF(AND(AM4=0,AM11>=0), "",AM11/AM4) | AP11: =IF(AND(AF11=0,AM11>0),100%,IF(AND(AF11<0,AM11=0),(AF11-AM11)/AF11,IF(AND(AF11>0,AM11>0),(AM11-AF11)/AF11,IF(AND(AF11=0,AM11=0),"",(AM11-AF11)/AF11)))) | AQ11: =+AJ11+AM11 -> 0 | AR11: =IF(AND(AQ4=0,AQ11>=0), "",AQ11/AQ4) -> 0 | AT11: =+V11*2 -> 0 | AU11: =IF(AND(AT4=0,AT11>=0), "",AT11/AT4) | AV11: =IF(AND(AT11=0,AQ11>0),100%,IF(AND(AT11<0,AQ11=0),(AT11-AQ11)/AT11,IF(AND(AT11>0,AQ11>0),(AQ11-AT11)/AT11,IF(AND(AT11=0,AQ11=0),"",(AQ11-AT11)/AT11)))) | AW11: =+AQ11/6 -> 0 | AX11: =IF(AND(AW4=0,AW11>=0), "",AW11/AW4) -> 0 | AZ11: =+AT11/6 -> 0 | BA11: =IF(AND(AZ4=0,AZ11>=0), "",AZ11/AZ4) | BB11: =IF(AND(AZ11=0,AW11>0),100%,IF(AND(AZ11<0,AW11=0),(AZ11-AW11)/AZ11,IF(AND(AZ11>0,AW11>0),(AW11-AZ11)/AZ11,IF(AND(AZ11=0,AW11=0),"",(AW11-AZ11)/AZ11)))) | BC11: =+'N EERR RODEO'!I10 -> 0 | BD11: =IF(AND(BC4=0,BC11>=0), "",BC11/BC4) | BF11: =IF(AND(AM11=0,BC11>0),100%,IF(AND(AM11<0,BC11=0),(AM11-BC11)/AM11,IF(AND(AM11>0,BC11>0),(BC11-AM11)/AM11,IF(AND(AM11=0,BC11=0),"",(BC11-AM11)/AM11)))) | BG11: =+AQ11+BC11 -> 0 | BH11: =IF(AND(BG4=0,BG11>=0), "",BG11/BG4) -> 0 | BJ11: =+'N EERR RODEO'!J10 -> 0 | BK11: =IF(AND(BJ4=0,BJ11>=0), "",BJ11/BJ4) | BM11: =IF(AND(BC11=0,BJ11>0),100%,IF(AND(BC11<0,BJ11=0),(BC11-BJ11)/BC11,IF(AND(BC11>0,BJ11>0),(BJ11-BC11)/BC11,IF(AND(BC11=0,BJ11=0),"",(BJ11-BC11)/BC11)))) | BN11: =+BG11+BJ11 -> 0 | BO11: =IF(AND(BN4=0,BN11>=0), "",BN11/BN4) -> 0 | BQ11: =+'N EERR RODEO'!K10 -> 0 | BR11: =IF(AND(BQ4=0,BQ11>=0), "",BQ11/BQ4) | BT11: =IF(AND(BJ11=0,BQ11>0),100%,IF(AND(BJ11<0,BQ11=0),(BJ11-BQ11)/BJ11,IF(AND(BJ11>0,BQ11>0),(BQ11-BJ11)/BJ11,IF(AND(BJ11=0,BQ11=0),"",(BQ11-BJ11)/BJ11)))) | BU11: =+BN11+BQ11 -> 0 | BV11: =IF(AND(BU4=0,BU11>=0), "",BU11/BU4) -> 0 | BX11: =+AZ11*9 -> 0 | BY11: =IF(AND(BX4=0,BX11>=0), "",BX11/BX4) | BZ11: =IF(AND(BX11=0,BU11>0),100%,IF(AND(BX11<0,BU11=0),(BX11-BU11)/BX11,IF(AND(BX11>0,BU11>0),(BU11-BX11)/BX11,IF(AND(BX11=0,BU11=0),"",(BU11-BX11)/BX11)))) | CA11: =+'N EERR RODEO'!L10 -> 0 | CB11: =IF(AND(CA4=0,CA11>=0), "",CA11/CA4) | CD11: =IF(AND(BQ11=0,CA11>0),100%,IF(AND(BQ11<0,CA11=0),(BQ11-CA11)/BQ11,IF(AND(BQ11>0,CA11>0),(CA11-BQ11)/BQ11,IF(AND(BQ11=0,CA11=0),"",(CA11-BQ11)/BQ11)))) | CE11: =+BU11+CA11 -> 0 | CF11: =IF(AND(CE4=0,CE11>=0), "",CE11/CE4) -> 0 | CH11: =+'N EERR RODEO'!M10 -> 0 | CI11: =IF(AND(CH4=0,CH11>=0), "",CH11/CH4) | CK11: =IF(AND(CA11=0,CH11>0),100%,IF(AND(CA11<0,CH11=0),(CA11-CH11)/CA11,IF(AND(CA11>0,CH11>0),(CH11-CA11)/CA11,IF(AND(CA11=0,CH11=0),"",(CH11-CA11)/CA11)))) | CL11: =+CE11+CH11 -> 0 | CM11: =IF(AND(CL4=0,CL11>=0), "",CL11/CL4) -> 0 | CO11: =+'N EERR RODEO'!N10 -> 0 | CP11: =IF(AND(CO4=0,CO11>=0), "",CO11/CO4) | CR11: =IF(AND(CH11=0,CO11>0),100%,IF(AND(CH11<0,CO11=0),(CH11-CO11)/CH11,IF(AND(CH11>0,CO11>0),(CO11-CH11)/CH11,IF(AND(CH11=0,CO11=0),"",(CO11-CH11)/CH11)))) | CS11: =+CL11+CO11 -> 0 | CT11: =IF(AND(CS4=0,CS11>=0), "",CS11/CS4) -> 0 | CV11: =+AZ11*12 -> 0 | CW11: =IF(AND(CV4=0,CV11>=0), "",CV11/CV4) | CX11: =IF(AND(CV11=0,CS11>0),100%,IF(AND(CV11<0,CS11=0),(CV11-CS11)/CV11,IF(AND(CV11>0,CS11>0),(CS11-CV11)/CV11,IF(AND(CV11=0,CS11=0),"",(CS11-CV11)/CV11))))
A12: Ingresos por zona FIT | B12: =+'N EERR RODEO'!B11 -> 0 | C12: =IF(AND(B4=0,B12>=0), "",B12/B4) | E12: =+'N EERR RODEO'!C11 -> 0 | F12: =IF(AND(E4=0,E12>=0), "",E12/E4) -> 0 | H12: =+'N EERR RODEO'!D11 -> 0 | I12: =IF(AND(H4=0,H12>=0), "",H12/H4) -> 0 | K12: =IF(AND(E12=0,H12>0),100%,IF(AND(E12<0,H12=0),(E12-H12)/E12,IF(AND(E12>0,H12>0),(H12-E12)/E12,IF(AND(E12=0,H12=0),"",(H12-E12)/E12)))) | L12: =+E12+H12 -> 0 | M12: =IF(AND(L4=0,L12>=0), "",L12/L4) -> 0 | O12: =+'N EERR RODEO'!E11 -> 0 | P12: =IF(AND(O4=0,O12>=0), "",O12/O4) -> 0 | R12: =IF(AND(H12=0,O12>0),100%,IF(AND(H12<0,O12=0),(H12-O12)/H12,IF(AND(H12>0,O12>0),(O12-H12)/H12,IF(AND(H12=0,O12=0),"",(O12-H12)/H12)))) | S12: =+L12+O12 -> 0 | T12: =IF(AND(S4=0,S12>=0), "",S12/S4) -> 0 | W12: =IF(AND(V4=0,V12>=0), "",V12/V4) | X12: =IF(AND(V12=0,S12>0),100%,IF(AND(V12<0,S12=0),(V12-S12)/V12,IF(AND(V12>0,S12>0),(S12-V12)/V12,IF(AND(V12=0,S12=0),"",(S12-V12)/V12)))) | Y12: =+'N EERR RODEO'!F11 -> 0 | Z12: =IF(AND(Y4=0,Y12>=0), "",Y12/Y4) | AB12: =IF(AND(O12=0,Y12>0),100%,IF(AND(O12<0,Y12=0),(O12-Y12)/O12,IF(AND(O12>0,Y12>0),(Y12-O12)/O12,IF(AND(O12=0,Y12=0),"",(Y12-O12)/O12)))) | AC12: =+S12+Y12 -> 0 | AD12: =IF(AND(AC4=0,AC12>=0), "",AC12/AC4) -> 0 | AF12: =+'N EERR RODEO'!G11 -> 0 | AG12: =IF(AND(AF4=0,AF12>=0), "",AF12/AF4) | AI12: =IF(AND(Y12=0,AF12>0),100%,IF(AND(Y12<0,AF12=0),(Y12-AF12)/Y12,IF(AND(Y12>0,AF12>0),(AF12-Y12)/Y12,IF(AND(Y12=0,AF12=0),"",(AF12-Y12)/Y12)))) | AJ12: =+AC12+AF12 -> 0 | AK12: =IF(AND(AJ4=0,AJ12>=0), "",AJ12/AJ4) -> 0 | AM12: =+'N EERR RODEO'!H11 -> 0 | AN12: =IF(AND(AM4=0,AM12>=0), "",AM12/AM4) | AP12: =IF(AND(AF12=0,AM12>0),100%,IF(AND(AF12<0,AM12=0),(AF12-AM12)/AF12,IF(AND(AF12>0,AM12>0),(AM12-AF12)/AF12,IF(AND(AF12=0,AM12=0),"",(AM12-AF12)/AF12)))) | AQ12: =+AJ12+AM12 -> 0 | AR12: =IF(AND(AQ4=0,AQ12>=0), "",AQ12/AQ4) -> 0 | AT12: =+V12*2 -> 0 | AU12: =IF(AND(AT4=0,AT12>=0), "",AT12/AT4) | AV12: =IF(AND(AT12=0,AQ12>0),100%,IF(AND(AT12<0,AQ12=0),(AT12-AQ12)/AT12,IF(AND(AT12>0,AQ12>0),(AQ12-AT12)/AT12,IF(AND(AT12=0,AQ12=0),"",(AQ12-AT12)/AT12)))) | AW12: =+AQ12/6 -> 0 | AX12: =IF(AND(AW4=0,AW12>=0), "",AW12/AW4) -> 0 | AZ12: =+AT12/6 -> 0 | BA12: =IF(AND(AZ4=0,AZ12>=0), "",AZ12/AZ4) | BB12: =IF(AND(AZ12=0,AW12>0),100%,IF(AND(AZ12<0,AW12=0),(AZ12-AW12)/AZ12,IF(AND(AZ12>0,AW12>0),(AW12-AZ12)/AZ12,IF(AND(AZ12=0,AW12=0),"",(AW12-AZ12)/AZ12)))) | BC12: =+'N EERR RODEO'!I11 -> 0 | BD12: =IF(AND(BC4=0,BC12>=0), "",BC12/BC4) | BF12: =IF(AND(AM12=0,BC12>0),100%,IF(AND(AM12<0,BC12=0),(AM12-BC12)/AM12,IF(AND(AM12>0,BC12>0),(BC12-AM12)/AM12,IF(AND(AM12=0,BC12=0),"",(BC12-AM12)/AM12)))) | BG12: =+AQ12+BC12 -> 0 | BH12: =IF(AND(BG4=0,BG12>=0), "",BG12/BG4) -> 0 | BJ12: =+'N EERR RODEO'!J11 -> 0 | BK12: =IF(AND(BJ4=0,BJ12>=0), "",BJ12/BJ4) | BM12: =IF(AND(BC12=0,BJ12>0),100%,IF(AND(BC12<0,BJ12=0),(BC12-BJ12)/BC12,IF(AND(BC12>0,BJ12>0),(BJ12-BC12)/BC12,IF(AND(BC12=0,BJ12=0),"",(BJ12-BC12)/BC12)))) | BN12: =+BG12+BJ12 -> 0 | BO12: =IF(AND(BN4=0,BN12>=0), "",BN12/BN4) -> 0 | BQ12: =+'N EERR RODEO'!K11 -> 0 | BR12: =IF(AND(BQ4=0,BQ12>=0), "",BQ12/BQ4) | BT12: =IF(AND(BJ12=0,BQ12>0),100%,IF(AND(BJ12<0,BQ12=0),(BJ12-BQ12)/BJ12,IF(AND(BJ12>0,BQ12>0),(BQ12-BJ12)/BJ12,IF(AND(BJ12=0,BQ12=0),"",(BQ12-BJ12)/BJ12)))) | BU12: =+BN12+BQ12 -> 0 | BV12: =IF(AND(BU4=0,BU12>=0), "",BU12/BU4) -> 0 | BX12: =+AZ12*9 -> 0 | BY12: =IF(AND(BX4=0,BX12>=0), "",BX12/BX4) | BZ12: =IF(AND(BX12=0,BU12>0),100%,IF(AND(BX12<0,BU12=0),(BX12-BU12)/BX12,IF(AND(BX12>0,BU12>0),(BU12-BX12)/BX12,IF(AND(BX12=0,BU12=0),"",(BU12-BX12)/BX12)))) | CA12: =+'N EERR RODEO'!L11 -> 0 | CB12: =IF(AND(CA4=0,CA12>=0), "",CA12/CA4) | CD12: =IF(AND(BQ12=0,CA12>0),100%,IF(AND(BQ12<0,CA12=0),(BQ12-CA12)/BQ12,IF(AND(BQ12>0,CA12>0),(CA12-BQ12)/BQ12,IF(AND(BQ12=0,CA12=0),"",(CA12-BQ12)/BQ12)))) | CE12: =+BU12+CA12 -> 0 | CF12: =IF(AND(CE4=0,CE12>=0), "",CE12/CE4) -> 0 | CH12: =+'N EERR RODEO'!M11 -> 0 | CI12: =IF(AND(CH4=0,CH12>=0), "",CH12/CH4) | CK12: =IF(AND(CA12=0,CH12>0),100%,IF(AND(CA12<0,CH12=0),(CA12-CH12)/CA12,IF(AND(CA12>0,CH12>0),(CH12-CA12)/CA12,IF(AND(CA12=0,CH12=0),"",(CH12-CA12)/CA12)))) | CL12: =+CE12+CH12 -> 0 | CM12: =IF(AND(CL4=0,CL12>=0), "",CL12/CL4) -> 0 | CO12: =+'N EERR RODEO'!N11 -> 0 | CP12: =IF(AND(CO4=0,CO12>=0), "",CO12/CO4) | CR12: =IF(AND(CH12=0,CO12>0),100%,IF(AND(CH12<0,CO12=0),(CH12-CO12)/CH12,IF(AND(CH12>0,CO12>0),(CO12-CH12)/CH12,IF(AND(CH12=0,CO12=0),"",(CO12-CH12)/CH12)))) | CS12: =+CL12+CO12 -> 0 | CT12: =IF(AND(CS4=0,CS12>=0), "",CS12/CS4) -> 0 | CV12: =+AZ12*12 -> 0 | CW12: =IF(AND(CV4=0,CV12>=0), "",CV12/CV4) | CX12: =IF(AND(CV12=0,CS12>0),100%,IF(AND(CV12<0,CS12=0),(CV12-CS12)/CV12,IF(AND(CV12>0,CS12>0),(CS12-CV12)/CV12,IF(AND(CV12=0,CS12=0),"",(CS12-CV12)/CV12))))
A13: Ingresos por fletes | B13: =+'N EERR RODEO'!B12 -> 0 | C13: =IF(AND(B4=0,B13>=0), "",B13/B4) | E13: =+'N EERR RODEO'!C12 -> 0 | F13: =IF(AND(E4=0,E13>=0), "",E13/E4) -> 0 | H13: =+'N EERR RODEO'!D12 -> 0 | I13: =IF(AND(H4=0,H13>=0), "",H13/H4) -> 0 | K13: =IF(AND(E13=0,H13>0),100%,IF(AND(E13<0,H13=0),(E13-H13)/E13,IF(AND(E13>0,H13>0),(H13-E13)/E13,IF(AND(E13=0,H13=0),"",(H13-E13)/E13)))) | L13: =+E13+H13 -> 0 | M13: =IF(AND(L4=0,L13>=0), "",L13/L4) -> 0 | O13: =+'N EERR RODEO'!E12 -> 0 | P13: =IF(AND(O4=0,O13>=0), "",O13/O4) -> 0 | R13: =IF(AND(H13=0,O13>0),100%,IF(AND(H13<0,O13=0),(H13-O13)/H13,IF(AND(H13>0,O13>0),(O13-H13)/H13,IF(AND(H13=0,O13=0),"",(O13-H13)/H13)))) | S13: =+L13+O13 -> 0 | T13: =IF(AND(S4=0,S13>=0), "",S13/S4) -> 0 | W13: =IF(AND(V4=0,V13>=0), "",V13/V4) | X13: =IF(AND(V13=0,S13>0),100%,IF(AND(V13<0,S13=0),(V13-S13)/V13,IF(AND(V13>0,S13>0),(S13-V13)/V13,IF(AND(V13=0,S13=0),"",(S13-V13)/V13)))) | Y13: =+'N EERR RODEO'!F12 -> 0 | Z13: =IF(AND(Y4=0,Y13>=0), "",Y13/Y4) | AB13: =IF(AND(O13=0,Y13>0),100%,IF(AND(O13<0,Y13=0),(O13-Y13)/O13,IF(AND(O13>0,Y13>0),(Y13-O13)/O13,IF(AND(O13=0,Y13=0),"",(Y13-O13)/O13)))) | AC13: =+S13+Y13 -> 0 | AD13: =IF(AND(AC4=0,AC13>=0), "",AC13/AC4) -> 0 | AF13: =+'N EERR RODEO'!G12 -> 0 | AG13: =IF(AND(AF4=0,AF13>=0), "",AF13/AF4) | AI13: =IF(AND(Y13=0,AF13>0),100%,IF(AND(Y13<0,AF13=0),(Y13-AF13)/Y13,IF(AND(Y13>0,AF13>0),(AF13-Y13)/Y13,IF(AND(Y13=0,AF13=0),"",(AF13-Y13)/Y13)))) | AJ13: =+AC13+AF13 -> 0 | AK13: =IF(AND(AJ4=0,AJ13>=0), "",AJ13/AJ4) -> 0 | AM13: =+'N EERR RODEO'!H12 -> 0 | AN13: =IF(AND(AM4=0,AM13>=0), "",AM13/AM4) | AP13: =IF(AND(AF13=0,AM13>0),100%,IF(AND(AF13<0,AM13=0),(AF13-AM13)/AF13,IF(AND(AF13>0,AM13>0),(AM13-AF13)/AF13,IF(AND(AF13=0,AM13=0),"",(AM13-AF13)/AF13)))) | AQ13: =+AJ13+AM13 -> 0 | AR13: =IF(AND(AQ4=0,AQ13>=0), "",AQ13/AQ4) -> 0 | AT13: =+V13*2 -> 0 | AU13: =IF(AND(AT4=0,AT13>=0), "",AT13/AT4) | AV13: =IF(AND(AT13=0,AQ13>0),100%,IF(AND(AT13<0,AQ13=0),(AT13-AQ13)/AT13,IF(AND(AT13>0,AQ13>0),(AQ13-AT13)/AT13,IF(AND(AT13=0,AQ13=0),"",(AQ13-AT13)/AT13)))) | AW13: =+AQ13/6 -> 0 | AX13: =IF(AND(AW4=0,AW13>=0), "",AW13/AW4) -> 0 | AZ13: =+AT13/6 -> 0 | BA13: =IF(AND(AZ4=0,AZ13>=0), "",AZ13/AZ4) | BB13: =IF(AND(AZ13=0,AW13>0),100%,IF(AND(AZ13<0,AW13=0),(AZ13-AW13)/AZ13,IF(AND(AZ13>0,AW13>0),(AW13-AZ13)/AZ13,IF(AND(AZ13=0,AW13=0),"",(AW13-AZ13)/AZ13)))) | BC13: =+'N EERR RODEO'!I12 -> 0 | BD13: =IF(AND(BC4=0,BC13>=0), "",BC13/BC4) | BF13: =IF(AND(AM13=0,BC13>0),100%,IF(AND(AM13<0,BC13=0),(AM13-BC13)/AM13,IF(AND(AM13>0,BC13>0),(BC13-AM13)/AM13,IF(AND(AM13=0,BC13=0),"",(BC13-AM13)/AM13)))) | BG13: =+AQ13+BC13 -> 0 | BH13: =IF(AND(BG4=0,BG13>=0), "",BG13/BG4) -> 0 | BJ13: =+'N EERR RODEO'!J12 -> 0 | BK13: =IF(AND(BJ4=0,BJ13>=0), "",BJ13/BJ4) | BM13: =IF(AND(BC13=0,BJ13>0),100%,IF(AND(BC13<0,BJ13=0),(BC13-BJ13)/BC13,IF(AND(BC13>0,BJ13>0),(BJ13-BC13)/BC13,IF(AND(BC13=0,BJ13=0),"",(BJ13-BC13)/BC13)))) | BN13: =+BG13+BJ13 -> 0 | BO13: =IF(AND(BN4=0,BN13>=0), "",BN13/BN4) -> 0 | BQ13: =+'N EERR RODEO'!K12 -> 0 | BR13: =IF(AND(BQ4=0,BQ13>=0), "",BQ13/BQ4) | BT13: =IF(AND(BJ13=0,BQ13>0),100%,IF(AND(BJ13<0,BQ13=0),(BJ13-BQ13)/BJ13,IF(AND(BJ13>0,BQ13>0),(BQ13-BJ13)/BJ13,IF(AND(BJ13=0,BQ13=0),"",(BQ13-BJ13)/BJ13)))) | BU13: =+BN13+BQ13 -> 0 | BV13: =IF(AND(BU4=0,BU13>=0), "",BU13/BU4) -> 0 | BX13: =+AZ13*9 -> 0 | BY13: =IF(AND(BX4=0,BX13>=0), "",BX13/BX4) | BZ13: =IF(AND(BX13=0,BU13>0),100%,IF(AND(BX13<0,BU13=0),(BX13-BU13)/BX13,IF(AND(BX13>0,BU13>0),(BU13-BX13)/BX13,IF(AND(BX13=0,BU13=0),"",(BU13-BX13)/BX13)))) | CA13: =+'N EERR RODEO'!L12 -> 0 | CB13: =IF(AND(CA4=0,CA13>=0), "",CA13/CA4) | CD13: =IF(AND(BQ13=0,CA13>0),100%,IF(AND(BQ13<0,CA13=0),(BQ13-CA13)/BQ13,IF(AND(BQ13>0,CA13>0),(CA13-BQ13)/BQ13,IF(AND(BQ13=0,CA13=0),"",(CA13-BQ13)/BQ13)))) | CE13: =+BU13+CA13 -> 0 | CF13: =IF(AND(CE4=0,CE13>=0), "",CE13/CE4) -> 0 | CH13: =+'N EERR RODEO'!M12 -> 0 | CI13: =IF(AND(CH4=0,CH13>=0), "",CH13/CH4) | CK13: =IF(AND(CA13=0,CH13>0),100%,IF(AND(CA13<0,CH13=0),(CA13-CH13)/CA13,IF(AND(CA13>0,CH13>0),(CH13-CA13)/CA13,IF(AND(CA13=0,CH13=0),"",(CH13-CA13)/CA13)))) | CL13: =+CE13+CH13 -> 0 | CM13: =IF(AND(CL4=0,CL13>=0), "",CL13/CL4) -> 0 | CO13: =+'N EERR RODEO'!N12 -> 0 | CP13: =IF(AND(CO4=0,CO13>=0), "",CO13/CO4) | CR13: =IF(AND(CH13=0,CO13>0),100%,IF(AND(CH13<0,CO13=0),(CH13-CO13)/CH13,IF(AND(CH13>0,CO13>0),(CO13-CH13)/CH13,IF(AND(CH13=0,CO13=0),"",(CO13-CH13)/CH13)))) | CS13: =+CL13+CO13 -> 0 | CT13: =IF(AND(CS4=0,CS13>=0), "",CS13/CS4) -> 0 | CV13: =+AZ13*12 -> 0 | CW13: =IF(AND(CV4=0,CV13>=0), "",CV13/CV4) | CX13: =IF(AND(CV13=0,CS13>0),100%,IF(AND(CV13<0,CS13=0),(CV13-CS13)/CV13,IF(AND(CV13>0,CS13>0),(CS13-CV13)/CV13,IF(AND(CV13=0,CS13=0),"",(CS13-CV13)/CV13))))
K14: =IF(AND(E14=0,H14>0),100%,IF(AND(E14<0,H14=0),(E14-H14)/E14,IF(AND(E14>0,H14>0),(H14-E14)/E14,IF(AND(E14=0,H14=0),"",(H14-E14)/E14)))) | R14: =IF(AND(H14=0,O14>0),100%,IF(AND(H14<0,O14=0),(H14-O14)/H14,IF(AND(H14>0,O14>0),(O14-H14)/H14,IF(AND(H14=0,O14=0),"",(O14-H14)/H14)))) | X14: =IF(AND(V14=0,S14>0),100%,IF(AND(V14<0,S14=0),(V14-S14)/V14,IF(AND(V14>0,S14>0),(S14-V14)/V14,IF(AND(V14=0,S14=0),"",(S14-V14)/V14)))) | AB14: =IF(AND(O14=0,Y14>0),100%,IF(AND(O14<0,Y14=0),(O14-Y14)/O14,IF(AND(O14>0,Y14>0),(Y14-O14)/O14,IF(AND(O14=0,Y14=0),"",(Y14-O14)/O14)))) | AI14: =IF(AND(Y14=0,AF14>0),100%,IF(AND(Y14<0,AF14=0),(Y14-AF14)/Y14,IF(AND(Y14>0,AF14>0),(AF14-Y14)/Y14,IF(AND(Y14=0,AF14=0),"",(AF14-Y14)/Y14)))) | AJ14: =+AC14+AF14 -> 0 | AP14: =IF(AND(AF14=0,AM14>0),100%,IF(AND(AF14<0,AM14=0),(AF14-AM14)/AF14,IF(AND(AF14>0,AM14>0),(AM14-AF14)/AF14,IF(AND(AF14=0,AM14=0),"",(AM14-AF14)/AF14)))) | AQ14: =+AJ14+AM14 -> 0 | AT14: =+V14*2 -> 0 | AV14: =IF(AND(AT14=0,AQ14>0),100%,IF(AND(AT14<0,AQ14=0),(AT14-AQ14)/AT14,IF(AND(AT14>0,AQ14>0),(AQ14-AT14)/AT14,IF(AND(AT14=0,AQ14=0),"",(AQ14-AT14)/AT14)))) | AW14: =+AQ14/6 -> 0 | AZ14: =+AT14/6 -> 0 | BB14: =IF(AND(AZ14=0,AW14>0),100%,IF(AND(AZ14<0,AW14=0),(AZ14-AW14)/AZ14,IF(AND(AZ14>0,AW14>0),(AW14-AZ14)/AZ14,IF(AND(AZ14=0,AW14=0),"",(AW14-AZ14)/AZ14)))) | BF14: =IF(AND(AM14=0,BC14>0),100%,IF(AND(AM14<0,BC14=0),(AM14-BC14)/AM14,IF(AND(AM14>0,BC14>0),(BC14-AM14)/AM14,IF(AND(AM14=0,BC14=0),"",(BC14-AM14)/AM14)))) | BG14: =+AQ14+BC14 -> 0 | BM14: =IF(AND(BC14=0,BJ14>0),100%,IF(AND(BC14<0,BJ14=0),(BC14-BJ14)/BC14,IF(AND(BC14>0,BJ14>0),(BJ14-BC14)/BC14,IF(AND(BC14=0,BJ14=0),"",(BJ14-BC14)/BC14)))) | BN14: =+BG14+BJ14 -> 0 | BT14: =IF(AND(BJ14=0,BQ14>0),100%,IF(AND(BJ14<0,BQ14=0),(BJ14-BQ14)/BJ14,IF(AND(BJ14>0,BQ14>0),(BQ14-BJ14)/BJ14,IF(AND(BJ14=0,BQ14=0),"",(BQ14-BJ14)/BJ14)))) | BU14: =+BN14+BQ14 -> 0 | BX14: =+AZ14*9 -> 0 | BZ14: =IF(AND(BX14=0,BU14>0),100%,IF(AND(BX14<0,BU14=0),(BX14-BU14)/BX14,IF(AND(BX14>0,BU14>0),(BU14-BX14)/BX14,IF(AND(BX14=0,BU14=0),"",(BU14-BX14)/BX14)))) | CD14: =IF(AND(BQ14=0,CA14>0),100%,IF(AND(BQ14<0,CA14=0),(BQ14-CA14)/BQ14,IF(AND(BQ14>0,CA14>0),(CA14-BQ14)/BQ14,IF(AND(BQ14=0,CA14=0),"",(CA14-BQ14)/BQ14)))) | CK14: =IF(AND(CA14=0,CH14>0),100%,IF(AND(CA14<0,CH14=0),(CA14-CH14)/CA14,IF(AND(CA14>0,CH14>0),(CH14-CA14)/CA14,IF(AND(CA14=0,CH14=0),"",(CH14-CA14)/CA14)))) | CL14: =+CE14+CH14 -> 0 | CR14: =IF(AND(CH14=0,CO14>0),100%,IF(AND(CH14<0,CO14=0),(CH14-CO14)/CH14,IF(AND(CH14>0,CO14>0),(CO14-CH14)/CH14,IF(AND(CH14=0,CO14=0),"",(CO14-CH14)/CH14)))) | CS14: =+CL14+CO14 -> 0 | CV14: =+AZ14*12 -> 0 | CX14: =IF(AND(CV14=0,CS14>0),100%,IF(AND(CV14<0,CS14=0),(CV14-CS14)/CV14,IF(AND(CV14>0,CS14>0),(CS14-CV14)/CV14,IF(AND(CV14=0,CS14=0),"",(CS14-CV14)/CV14))))
A15: Subtotal Ingresos por Eventos | B15: =SUM(B16:B17) -> 0 | C15: =IF(AND(B4=0,B15>=0), "",B15/B4) | E15: =SUM(E16:E17) -> 0 | F15: =IF(AND(E4=0,E15>=0), "",E15/E4) -> 0 | H15: =SUM(H16:H17) -> 0 | I15: =IF(AND(H4=0,H15>=0), "",H15/H4) -> 0 | K15: =IF(AND(E15=0,H15>0),100%,IF(AND(E15<0,H15=0),(E15-H15)/E15,IF(AND(E15>0,H15>0),(H15-E15)/E15,IF(AND(E15=0,H15=0),"",(H15-E15)/E15)))) | L15: =SUM(L16:L17) -> 0 | M15: =IF(AND(L4=0,L15>=0), "",L15/L4) -> 0 | O15: =SUM(O16:O17) -> 0 | P15: =IF(AND(O4=0,O15>=0), "",O15/O4) -> 0 | R15: =IF(AND(H15=0,O15>0),100%,IF(AND(H15<0,O15=0),(H15-O15)/H15,IF(AND(H15>0,O15>0),(O15-H15)/H15,IF(AND(H15=0,O15=0),"",(O15-H15)/H15)))) | S15: =SUM(S16:S17) -> 0 | T15: =IF(AND(S4=0,S15>=0), "",S15/S4) -> 0 | V15: =SUM(V16:V17) -> 0 | W15: =IF(AND(V4=0,V15>=0), "",V15/V4) | X15: =IF(AND(V15=0,S15>0),100%,IF(AND(V15<0,S15=0),(V15-S15)/V15,IF(AND(V15>0,S15>0),(S15-V15)/V15,IF(AND(V15=0,S15=0),"",(S15-V15)/V15)))) | Y15: =SUM(Y16:Y17) -> 0 | Z15: =IF(AND(Y4=0,Y15>=0), "",Y15/Y4) | AB15: =IF(AND(O15=0,Y15>0),100%,IF(AND(O15<0,Y15=0),(O15-Y15)/O15,IF(AND(O15>0,Y15>0),(Y15-O15)/O15,IF(AND(O15=0,Y15=0),"",(Y15-O15)/O15)))) | AC15: =SUM(AC16:AC17) -> 0 | AD15: =IF(AND(AC4=0,AC15>=0), "",AC15/AC4) -> 0 | AF15: =SUM(AF16:AF17) -> 0 | AG15: =IF(AND(AF4=0,AF15>=0), "",AF15/AF4) | AI15: =IF(AND(Y15=0,AF15>0),100%,IF(AND(Y15<0,AF15=0),(Y15-AF15)/Y15,IF(AND(Y15>0,AF15>0),(AF15-Y15)/Y15,IF(AND(Y15=0,AF15=0),"",(AF15-Y15)/Y15)))) | AJ15: =SUM(AJ16:AJ17) -> 0 | AK15: =IF(AND(AJ4=0,AJ15>=0), "",AJ15/AJ4) -> 0 | AM15: =SUM(AM16:AM17) -> 0 | AN15: =IF(AND(AM4=0,AM15>=0), "",AM15/AM4) | AP15: =IF(AND(AF15=0,AM15>0),100%,IF(AND(AF15<0,AM15=0),(AF15-AM15)/AF15,IF(AND(AF15>0,AM15>0),(AM15-AF15)/AF15,IF(AND(AF15=0,AM15=0),"",(AM15-AF15)/AF15)))) | AQ15: =SUM(AQ16:AQ17) -> 0 | AR15: =IF(AND(AQ4=0,AQ15>=0), "",AQ15/AQ4) -> 0 | AT15: =SUM(AT16:AT17) -> 0 | AU15: =IF(AND(AT4=0,AT15>=0), "",AT15/AT4) | AV15: =IF(AND(AT15=0,AQ15>0),100%,IF(AND(AT15<0,AQ15=0),(AT15-AQ15)/AT15,IF(AND(AT15>0,AQ15>0),(AQ15-AT15)/AT15,IF(AND(AT15=0,AQ15=0),"",(AQ15-AT15)/AT15)))) | AW15: =SUM(AW16:AW17) -> 0 | AX15: =IF(AND(AW4=0,AW15>=0), "",AW15/AW4) -> 0 | AZ15: =SUM(AZ16:AZ17) -> 0 | BA15: =IF(AND(AZ4=0,AZ15>=0), "",AZ15/AZ4) | BB15: =IF(AND(AZ15=0,AW15>0),100%,IF(AND(AZ15<0,AW15=0),(AZ15-AW15)/AZ15,IF(AND(AZ15>0,AW15>0),(AW15-AZ15)/AZ15,IF(AND(AZ15=0,AW15=0),"",(AW15-AZ15)/AZ15)))) | BC15: =SUM(BC16:BC17) -> 0 | BD15: =IF(AND(BC4=0,BC15>=0), "",BC15/BC4) | BF15: =IF(AND(AM15=0,BC15>0),100%,IF(AND(AM15<0,BC15=0),(AM15-BC15)/AM15,IF(AND(AM15>0,BC15>0),(BC15-AM15)/AM15,IF(AND(AM15=0,BC15=0),"",(BC15-AM15)/AM15)))) | BG15: =SUM(BG16:BG17) -> 0 | BH15: =IF(AND(BG4=0,BG15>=0), "",BG15/BG4) -> 0 | BJ15: =SUM(BJ16:BJ17) -> 0 | BK15: =IF(AND(BJ4=0,BJ15>=0), "",BJ15/BJ4) | BM15: =IF(AND(BC15=0,BJ15>0),100%,IF(AND(BC15<0,BJ15=0),(BC15-BJ15)/BC15,IF(AND(BC15>0,BJ15>0),(BJ15-BC15)/BC15,IF(AND(BC15=0,BJ15=0),"",(BJ15-BC15)/BC15)))) | BN15: =SUM(BN16:BN17) -> 0 | BO15: =IF(AND(BN4=0,BN15>=0), "",BN15/BN4) -> 0 | BQ15: =SUM(BQ16:BQ17) -> 0 | BR15: =IF(AND(BQ4=0,BQ15>=0), "",BQ15/BQ4) | BT15: =IF(AND(BJ15=0,BQ15>0),100%,IF(AND(BJ15<0,BQ15=0),(BJ15-BQ15)/BJ15,IF(AND(BJ15>0,BQ15>0),(BQ15-BJ15)/BJ15,IF(AND(BJ15=0,BQ15=0),"",(BQ15-BJ15)/BJ15)))) | BU15: =SUM(BU16:BU17) -> 0 | BV15: =IF(AND(BU4=0,BU15>=0), "",BU15/BU4) -> 0 | BX15: =SUM(BX16:BX17) -> 0 | BY15: =IF(AND(BX4=0,BX15>=0), "",BX15/BX4) | BZ15: =IF(AND(BX15=0,BU15>0),100%,IF(AND(BX15<0,BU15=0),(BX15-BU15)/BX15,IF(AND(BX15>0,BU15>0),(BU15-BX15)/BX15,IF(AND(BX15=0,BU15=0),"",(BU15-BX15)/BX15)))) | CA15: =SUM(CA16:CA17) -> 0 | CB15: =IF(AND(CA4=0,CA15>=0), "",CA15/CA4) | CD15: =IF(AND(BQ15=0,CA15>0),100%,IF(AND(BQ15<0,CA15=0),(BQ15-CA15)/BQ15,IF(AND(BQ15>0,CA15>0),(CA15-BQ15)/BQ15,IF(AND(BQ15=0,CA15=0),"",(CA15-BQ15)/BQ15)))) | CE15: =SUM(CE16:CE17) -> 0 | CF15: =IF(AND(CE4=0,CE15>=0), "",CE15/CE4) -> 0 | CH15: =SUM(CH16:CH17) -> 0 | CI15: =IF(AND(CH4=0,CH15>=0), "",CH15/CH4) | CK15: =IF(AND(CA15=0,CH15>0),100%,IF(AND(CA15<0,CH15=0),(CA15-CH15)/CA15,IF(AND(CA15>0,CH15>0),(CH15-CA15)/CA15,IF(AND(CA15=0,CH15=0),"",(CH15-CA15)/CA15)))) | CL15: =SUM(CL16:CL17) -> 0 | CM15: =IF(AND(CL4=0,CL15>=0), "",CL15/CL4) -> 0 | CO15: =SUM(CO16:CO17) -> 0 | CP15: =IF(AND(CO4=0,CO15>=0), "",CO15/CO4) | CR15: =IF(AND(CH15=0,CO15>0),100%,IF(AND(CH15<0,CO15=0),(CH15-CO15)/CH15,IF(AND(CH15>0,CO15>0),(CO15-CH15)/CH15,IF(AND(CH15=0,CO15=0),"",(CO15-CH15)/CH15)))) | CS15: =SUM(CS16:CS17) -> 0 | CT15: =IF(AND(CS4=0,CS15>=0), "",CS15/CS4) -> 0 | CV15: =SUM(CV16:CV17) -> 0 | CW15: =IF(AND(CV4=0,CV15>=0), "",CV15/CV4) | CX15: =IF(AND(CV15=0,CS15>0),100%,IF(AND(CV15<0,CS15=0),(CV15-CS15)/CV15,IF(AND(CV15>0,CS15>0),(CS15-CV15)/CV15,IF(AND(CV15=0,CS15=0),"",(CS15-CV15)/CV15))))
A16: Ingresos por eventos | B16: =+'N EERR RODEO'!B14 -> 0 | C16: =IF(AND(B4=0,B16>=0), "",B16/B4) | E16: =+'N EERR RODEO'!C14 -> 0 | F16: =IF(AND(E4=0,E16>=0), "",E16/E4) -> 0 | H16: =+'N EERR RODEO'!D14 -> 0 | I16: =IF(AND(H4=0,H16>=0), "",H16/H4) -> 0 | K16: =IF(AND(E16=0,H16>0),100%,IF(AND(E16<0,H16=0),(E16-H16)/E16,IF(AND(E16>0,H16>0),(H16-E16)/E16,IF(AND(E16=0,H16=0),"",(H16-E16)/E16)))) | L16: =+E16+H16 -> 0 | M16: =IF(AND(L4=0,L16>=0), "",L16/L4) -> 0 | O16: =+'N EERR RODEO'!E14 -> 0 | P16: =IF(AND(O4=0,O16>=0), "",O16/O4) -> 0 | R16: =IF(AND(H16=0,O16>0),100%,IF(AND(H16<0,O16=0),(H16-O16)/H16,IF(AND(H16>0,O16>0),(O16-H16)/H16,IF(AND(H16=0,O16=0),"",(O16-H16)/H16)))) | S16: =+L16+O16 -> 0 | T16: =IF(AND(S4=0,S16>=0), "",S16/S4) -> 0 | W16: =IF(AND(V4=0,V16>=0), "",V16/V4) | X16: =IF(AND(V16=0,S16>0),100%,IF(AND(V16<0,S16=0),(V16-S16)/V16,IF(AND(V16>0,S16>0),(S16-V16)/V16,IF(AND(V16=0,S16=0),"",(S16-V16)/V16)))) | Y16: =+'N EERR RODEO'!F14 -> 0 | Z16: =IF(AND(Y4=0,Y16>=0), "",Y16/Y4) | AB16: =IF(AND(O16=0,Y16>0),100%,IF(AND(O16<0,Y16=0),(O16-Y16)/O16,IF(AND(O16>0,Y16>0),(Y16-O16)/O16,IF(AND(O16=0,Y16=0),"",(Y16-O16)/O16)))) | AC16: =+S16+Y16 -> 0 | AD16: =IF(AND(AC4=0,AC16>=0), "",AC16/AC4) -> 0 | AF16: =+'N EERR RODEO'!G14 -> 0 | AG16: =IF(AND(AF4=0,AF16>=0), "",AF16/AF4) | AI16: =IF(AND(Y16=0,AF16>0),100%,IF(AND(Y16<0,AF16=0),(Y16-AF16)/Y16,IF(AND(Y16>0,AF16>0),(AF16-Y16)/Y16,IF(AND(Y16=0,AF16=0),"",(AF16-Y16)/Y16)))) | AJ16: =+AC16+AF16 -> 0 | AK16: =IF(AND(AJ4=0,AJ16>=0), "",AJ16/AJ4) -> 0 | AM16: =+'N EERR RODEO'!H14 -> 0 | AN16: =IF(AND(AM4=0,AM16>=0), "",AM16/AM4) | AP16: =IF(AND(AF16=0,AM16>0),100%,IF(AND(AF16<0,AM16=0),(AF16-AM16)/AF16,IF(AND(AF16>0,AM16>0),(AM16-AF16)/AF16,IF(AND(AF16=0,AM16=0),"",(AM16-AF16)/AF16)))) | AQ16: =+AJ16+AM16 -> 0 | AR16: =IF(AND(AQ4=0,AQ16>=0), "",AQ16/AQ4) -> 0 | AT16: =+V16*2 -> 0 | AU16: =IF(AND(AT4=0,AT16>=0), "",AT16/AT4) | AV16: =IF(AND(AT16=0,AQ16>0),100%,IF(AND(AT16<0,AQ16=0),(AT16-AQ16)/AT16,IF(AND(AT16>0,AQ16>0),(AQ16-AT16)/AT16,IF(AND(AT16=0,AQ16=0),"",(AQ16-AT16)/AT16)))) | AW16: =+AQ16/6 -> 0 | AX16: =IF(AND(AW4=0,AW16>=0), "",AW16/AW4) -> 0 | AZ16: =+AT16/6 -> 0 | BA16: =IF(AND(AZ4=0,AZ16>=0), "",AZ16/AZ4) | BB16: =IF(AND(AZ16=0,AW16>0),100%,IF(AND(AZ16<0,AW16=0),(AZ16-AW16)/AZ16,IF(AND(AZ16>0,AW16>0),(AW16-AZ16)/AZ16,IF(AND(AZ16=0,AW16=0),"",(AW16-AZ16)/AZ16)))) | BC16: =+'N EERR RODEO'!I14 -> 0 | BD16: =IF(AND(BC4=0,BC16>=0), "",BC16/BC4) | BF16: =IF(AND(AM16=0,BC16>0),100%,IF(AND(AM16<0,BC16=0),(AM16-BC16)/AM16,IF(AND(AM16>0,BC16>0),(BC16-AM16)/AM16,IF(AND(AM16=0,BC16=0),"",(BC16-AM16)/AM16)))) | BG16: =+AQ16+BC16 -> 0 | BH16: =IF(AND(BG4=0,BG16>=0), "",BG16/BG4) -> 0 | BJ16: =+'N EERR RODEO'!J14 -> 0 | BK16: =IF(AND(BJ4=0,BJ16>=0), "",BJ16/BJ4) | BM16: =IF(AND(BC16=0,BJ16>0),100%,IF(AND(BC16<0,BJ16=0),(BC16-BJ16)/BC16,IF(AND(BC16>0,BJ16>0),(BJ16-BC16)/BC16,IF(AND(BC16=0,BJ16=0),"",(BJ16-BC16)/BC16)))) | BN16: =+BG16+BJ16 -> 0 | BO16: =IF(AND(BN4=0,BN16>=0), "",BN16/BN4) -> 0 | BQ16: =+'N EERR RODEO'!K14 -> 0 | BR16: =IF(AND(BQ4=0,BQ16>=0), "",BQ16/BQ4) | BT16: =IF(AND(BJ16=0,BQ16>0),100%,IF(AND(BJ16<0,BQ16=0),(BJ16-BQ16)/BJ16,IF(AND(BJ16>0,BQ16>0),(BQ16-BJ16)/BJ16,IF(AND(BJ16=0,BQ16=0),"",(BQ16-BJ16)/BJ16)))) | BU16: =+BN16+BQ16 -> 0 | BV16: =IF(AND(BU4=0,BU16>=0), "",BU16/BU4) -> 0 | BX16: =+AZ16*9 -> 0 | BY16: =IF(AND(BX4=0,BX16>=0), "",BX16/BX4) | BZ16: =IF(AND(BX16=0,BU16>0),100%,IF(AND(BX16<0,BU16=0),(BX16-BU16)/BX16,IF(AND(BX16>0,BU16>0),(BU16-BX16)/BX16,IF(AND(BX16=0,BU16=0),"",(BU16-BX16)/BX16)))) | CA16: =+'N EERR RODEO'!L14 -> 0 | CB16: =IF(AND(CA4=0,CA16>=0), "",CA16/CA4) | CD16: =IF(AND(BQ16=0,CA16>0),100%,IF(AND(BQ16<0,CA16=0),(BQ16-CA16)/BQ16,IF(AND(BQ16>0,CA16>0),(CA16-BQ16)/BQ16,IF(AND(BQ16=0,CA16=0),"",(CA16-BQ16)/BQ16)))) | CE16: =+BU16+CA16 -> 0 | CF16: =IF(AND(CE4=0,CE16>=0), "",CE16/CE4) -> 0 | CH16: =+'N EERR RODEO'!M14 -> 0 | CI16: =IF(AND(CH4=0,CH16>=0), "",CH16/CH4) | CK16: =IF(AND(CA16=0,CH16>0),100%,IF(AND(CA16<0,CH16=0),(CA16-CH16)/CA16,IF(AND(CA16>0,CH16>0),(CH16-CA16)/CA16,IF(AND(CA16=0,CH16=0),"",(CH16-CA16)/CA16)))) | CL16: =+CE16+CH16 -> 0 | CM16: =IF(AND(CL4=0,CL16>=0), "",CL16/CL4) -> 0 | CO16: =+'N EERR RODEO'!N14 -> 0 | CP16: =IF(AND(CO4=0,CO16>=0), "",CO16/CO4) | CR16: =IF(AND(CH16=0,CO16>0),100%,IF(AND(CH16<0,CO16=0),(CH16-CO16)/CH16,IF(AND(CH16>0,CO16>0),(CO16-CH16)/CH16,IF(AND(CH16=0,CO16=0),"",(CO16-CH16)/CH16)))) | CS16: =+CL16+CO16 -> 0 | CT16: =IF(AND(CS4=0,CS16>=0), "",CS16/CS4) -> 0 | CV16: =+AZ16*12 -> 0 | CW16: =IF(AND(CV4=0,CV16>=0), "",CV16/CV4) | CX16: =IF(AND(CV16=0,CS16>0),100%,IF(AND(CV16<0,CS16=0),(CV16-CS16)/CV16,IF(AND(CV16>0,CS16>0),(CS16-CV16)/CV16,IF(AND(CV16=0,CS16=0),"",(CS16-CV16)/CV16))))
