Workbook

Sheet ESF ULTRAX
A2: ESTADO DE SITUACIÓN FINANCIERA ULTRAX C.A.
A3: PARTIDAS | B3: =IF(ISBLANK(A2),"",YEAR(TODAY())-1) -> 2025 | C3: Q1 | D3: Vari Rel. | E3: Q2 | F3: Vari Rel. | G3: Q3 | H3: Vari Rel. | I3: Q4 | J3: Vari Rel. | K3: Vari Rel. actual vs anterior
A4: ACTIVOS CORRIENTES | B4: =+B5+B14+B20+B23+B29+B33+B38 -> 0 | C4: =+C5+C14+C20+C23+C29+C33+C38 -> 1002075.8 | D4: =IF(AND(B4=0,C4>0),100%,IF(AND(B4<0,C4>=0),(B4-C4)/B4,IF(AND(B4>0,C4>0),(C4-B4)/B4,IF(AND(B4=0,C4<=0),"",(C4-B4)/B4)))) -> 1 | E4: =+E5+E14+E20+E23+E29+E33+E38 -> 1165507.6 | F4: =IF(AND(C4=0,E4>0),100%,IF(AND(C4<0,E4>=0),(C4-E4)/C4,IF(AND(C4>0,E4>0),(E4-C4)/C4,IF(AND(C4=0,E4<=0),"",(E4-C4)/C4)))) -> 0.16309325 | G4: =+G5+G14+G20+G23+G29+G33+G38 -> 0 | H4: =IF(AND(E4=0,G4>0),100%,IF(AND(E4<0,G4>=0),(E4-G4)/E4,IF(AND(E4>0,G4>0),(G4-E4)/E4,IF(AND(E4=0,G4<=0),"",(G4-E4)/E4)))) -> -1 | I4: =+I5+I14+I20+I23+I29+I33+I38 -> 0 | J4: =IF(AND(G4=0,I4>0),100%,IF(AND(G4<0,I4>=0),(G4-I4)/G4,IF(AND(G4>0,I4>0),(I4-G4)/G4,IF(AND(G4=0,I4<=0),"",(I4-G4)/G4)))) | K4: =IF(AND(B4=0,I4>0),100%,IF(AND(B4<0,I4>=0),(B4-I4)/B4,IF(AND(B4>0,I4>0),(I4-B4)/B4,IF(AND(B4=0,I4<=0),"",(I4-B4)/B4))))
A5: Efectivo y Equivalentes | B5: =+SUM(B6:B13) -> 0 | C5: =+SUM(C6:C13) -> -9247.1755 | D5: =IF(AND(B5=0,C5>0),100%,IF(AND(B5<0,C5>=0),(B5-C5)/B5,IF(AND(B5>0,C5>0),(C5-B5)/B5,IF(AND(B5=0,C5<=0),"",(C5-B5)/B5)))) | E5: =+SUM(E6:E13) -> 5358.9955 | F5: =IF(AND(C5=0,E5>0),100%,IF(AND(C5<0,E5>=0),(C5-E5)/C5,IF(AND(C5>0,E5>0),(E5-C5)/C5,IF(AND(C5=0,E5<=0),"",(E5-C5)/C5)))) -> 1.5795278 | G5: =+SUM(G6:G13) -> 0 | H5: =IF(AND(E5=0,G5>0),100%,IF(AND(E5<0,G5>=0),(E5-G5)/E5,IF(AND(E5>0,G5>0),(G5-E5)/E5,IF(AND(E5=0,G5<=0),"",(G5-E5)/E5)))) -> -1 | I5: =+SUM(I6:I13) -> 0 | J5: =IF(AND(G5=0,I5>0),100%,IF(AND(G5<0,I5>=0),(G5-I5)/G5,IF(AND(G5>0,I5>0),(I5-G5)/G5,IF(AND(G5=0,I5<=0),"",(I5-G5)/G5)))) | K5: =IF(AND(B5=0,I5>0),100%,IF(AND(B5<0,I5>=0),(B5-I5)/B5,IF(AND(B5>0,I5>0),(I5-B5)/B5,IF(AND(B5=0,I5<=0),"",(I5-B5)/B5))))
A6: Cajas en Bs | B6: =+'N ESF ULTRAX'!B5 -> 0 | C6: =+'N ESF ULTRAX'!E5 -> 0.90022265 | D6: =IF(AND(B6=0,C6>0),100%,IF(AND(B6<0,C6>=0),(B6-C6)/B6,IF(AND(B6>0,C6>0),(C6-B6)/B6,IF(AND(B6=0,C6<=0),"",(C6-B6)/B6)))) -> 1 | E6: =+'N ESF ULTRAX'!H5 -> 0.64365888 | F6: =IF(AND(C6=0,E6>0),100%,IF(AND(C6<0,E6>=0),(C6-E6)/C6,IF(AND(C6>0,E6>0),(E6-C6)/C6,IF(AND(C6=0,E6<=0),"",(E6-C6)/C6)))) -> -0.28500035 | G6: =+'N ESF ULTRAX'!K5 -> 0 | H6: =IF(AND(E6=0,G6>0),100%,IF(AND(E6<0,G6>=0),(E6-G6)/E6,IF(AND(E6>0,G6>0),(G6-E6)/E6,IF(AND(E6=0,G6<=0),"",(G6-E6)/E6)))) -> -1 | I6: =+'N ESF ULTRAX'!N5 -> 0 | J6: =IF(AND(G6=0,I6>0),100%,IF(AND(G6<0,I6>=0),(G6-I6)/G6,IF(AND(G6>0,I6>0),(I6-G6)/G6,IF(AND(G6=0,I6<=0),"",(I6-G6)/G6)))) | K6: =IF(AND(B6=0,I6>0),100%,IF(AND(B6<0,I6>=0),(B6-I6)/B6,IF(AND(B6>0,I6>0),(I6-B6)/B6,IF(AND(B6=0,I6<=0),"",(I6-B6)/B6))))
A7: Cajas en $ | B7: =+'N ESF ULTRAX'!B7 -> 0 | C7: =+'N ESF ULTRAX'!E7 -> -3447.85 | D7: =IF(AND(B7=0,C7>0),100%,IF(AND(B7<0,C7>=0),(B7-C7)/B7,IF(AND(B7>0,C7>0),(C7-B7)/B7,IF(AND(B7=0,C7<=0),"",(C7-B7)/B7)))) | E7: =+'N ESF ULTRAX'!H7 -> 4086.15 | F7: =IF(AND(C7=0,E7>0),100%,IF(AND(C7<0,E7>=0),(C7-E7)/C7,IF(AND(C7>0,E7>0),(E7-C7)/C7,IF(AND(C7=0,E7<=0),"",(E7-C7)/C7)))) -> 2.1851299 | G7: =+'N ESF ULTRAX'!K7 -> 0 | H7: =IF(AND(E7=0,G7>0),100%,IF(AND(E7<0,G7>=0),(E7-G7)/E7,IF(AND(E7>0,G7>0),(G7-E7)/E7,IF(AND(E7=0,G7<=0),"",(G7-E7)/E7)))) -> -1 | I7: =+'N ESF ULTRAX'!N7 -> 0 | J7: =IF(AND(G7=0,I7>0),100%,IF(AND(G7<0,I7>=0),(G7-I7)/G7,IF(AND(G7>0,I7>0),(I7-G7)/G7,IF(AND(G7=0,I7<=0),"",(I7-G7)/G7)))) | K7: =IF(AND(B7=0,I7>0),100%,IF(AND(B7<0,I7>=0),(B7-I7)/B7,IF(AND(B7>0,I7>0),(I7-B7)/B7,IF(AND(B7=0,I7<=0),"",(I7-B7)/B7))))
A8: Fondos en Bs | B8: =+'N ESF ULTRAX'!B11 -> 0 | C8: =+'N ESF ULTRAX'!E11 -> 17.997251 | D8: =IF(AND(B8=0,C8>0),100%,IF(AND(B8<0,C8>=0),(B8-C8)/B8,IF(AND(B8>0,C8>0),(C8-B8)/B8,IF(AND(B8=0,C8<=0),"",(C8-B8)/B8)))) -> 1 | E8: =+'N ESF ULTRAX'!H11 -> 28.237399 | F8: =IF(AND(C8=0,E8>0),100%,IF(AND(C8<0,E8>=0),(C8-E8)/C8,IF(AND(C8>0,E8>0),(E8-C8)/C8,IF(AND(C8=0,E8<=0),"",(E8-C8)/C8)))) -> 0.56898397 | G8: =+'N ESF ULTRAX'!K11 -> 0 | H8: =IF(AND(E8=0,G8>0),100%,IF(AND(E8<0,G8>=0),(E8-G8)/E8,IF(AND(E8>0,G8>0),(G8-E8)/E8,IF(AND(E8=0,G8<=0),"",(G8-E8)/E8)))) -> -1 | I8: =+'N ESF ULTRAX'!N11 -> 0 | J8: =IF(AND(G8=0,I8>0),100%,IF(AND(G8<0,I8>=0),(G8-I8)/G8,IF(AND(G8>0,I8>0),(I8-G8)/G8,IF(AND(G8=0,I8<=0),"",(I8-G8)/G8)))) | K8: =IF(AND(B8=0,I8>0),100%,IF(AND(B8<0,I8>=0),(B8-I8)/B8,IF(AND(B8>0,I8>0),(I8-B8)/B8,IF(AND(B8=0,I8<=0),"",(I8-B8)/B8))))
A9: Fondos en $ | B9: =+'N ESF ULTRAX'!B17 -> 0 | C9: =+'N ESF ULTRAX'!E17 -> 9640 | D9: =IF(AND(B9=0,C9>0),100%,IF(AND(B9<0,C9>=0),(B9-C9)/B9,IF(AND(B9>0,C9>0),(C9-B9)/B9,IF(AND(B9=0,C9<=0),"",(C9-B9)/B9)))) -> 1 | E9: =+'N ESF ULTRAX'!H17 -> 1910 | F9: =IF(AND(C9=0,E9>0),100%,IF(AND(C9<0,E9>=0),(C9-E9)/C9,IF(AND(C9>0,E9>0),(E9-C9)/C9,IF(AND(C9=0,E9<=0),"",(E9-C9)/C9)))) -> -0.80186722 | G9: =+'N ESF ULTRAX'!K17 -> 0 | H9: =IF(AND(E9=0,G9>0),100%,IF(AND(E9<0,G9>=0),(E9-G9)/E9,IF(AND(E9>0,G9>0),(G9-E9)/E9,IF(AND(E9=0,G9<=0),"",(G9-E9)/E9)))) -> -1 | I9: =+'N ESF ULTRAX'!N17 -> 0 | J9: =IF(AND(G9=0,I9>0),100%,IF(AND(G9<0,I9>=0),(G9-I9)/G9,IF(AND(G9>0,I9>0),(I9-G9)/G9,IF(AND(G9=0,I9<=0),"",(I9-G9)/G9)))) | K9: =IF(AND(B9=0,I9>0),100%,IF(AND(B9<0,I9>=0),(B9-I9)/B9,IF(AND(B9>0,I9>0),(I9-B9)/B9,IF(AND(B9=0,I9<=0),"",(I9-B9)/B9))))
A10: Bancos en Bs | B10: =+'N ESF ULTRAX'!B35 -> 0 | C10: =+'N ESF ULTRAX'!E35 -> 9702.3044 | D10: =IF(AND(B10=0,C10>0),100%,IF(AND(B10<0,C10>=0),(B10-C10)/B10,IF(AND(B10>0,C10>0),(C10-B10)/B10,IF(AND(B10=0,C10<=0),"",(C10-B10)/B10)))) -> 1 | E10: =+'N ESF ULTRAX'!H35 -> 20994.255 | F10: =IF(AND(C10=0,E10>0),100%,IF(AND(C10<0,E10>=0),(C10-E10)/C10,IF(AND(C10>0,E10>0),(E10-C10)/C10,IF(AND(C10=0,E10<=0),"",(E10-C10)/C10)))) -> 1.1638421 | G10: =+'N ESF ULTRAX'!K35 -> 0 | H10: =IF(AND(E10=0,G10>0),100%,IF(AND(E10<0,G10>=0),(E10-G10)/E10,IF(AND(E10>0,G10>0),(G10-E10)/E10,IF(AND(E10=0,G10<=0),"",(G10-E10)/E10)))) -> -1 | I10: =+'N ESF ULTRAX'!N35 -> 0 | J10: =IF(AND(G10=0,I10>0),100%,IF(AND(G10<0,I10>=0),(G10-I10)/G10,IF(AND(G10>0,I10>0),(I10-G10)/G10,IF(AND(G10=0,I10<=0),"",(I10-G10)/G10)))) | K10: =IF(AND(B10=0,I10>0),100%,IF(AND(B10<0,I10>=0),(B10-I10)/B10,IF(AND(B10>0,I10>0),(I10-B10)/B10,IF(AND(B10=0,I10<=0),"",(I10-B10)/B10))))
A11: Bancos en $ | B11: =+'N ESF ULTRAX'!B48 -> 0 | C11: =+'N ESF ULTRAX'!E48 -> -26155.9 | D11: =IF(AND(B11=0,C11>0),100%,IF(AND(B11<0,C11>=0),(B11-C11)/B11,IF(AND(B11>0,C11>0),(C11-B11)/B11,IF(AND(B11=0,C11<=0),"",(C11-B11)/B11)))) | E11: =+'N ESF ULTRAX'!H48 -> -24428.4 | F11: =IF(AND(C11=0,E11>0),100%,IF(AND(C11<0,E11>=0),(C11-E11)/C11,IF(AND(C11>0,E11>0),(E11-C11)/C11,IF(AND(C11=0,E11<=0),"",(E11-C11)/C11)))) -> -0.066046284 | G11: =+'N ESF ULTRAX'!K48 -> 0 | H11: =IF(AND(E11=0,G11>0),100%,IF(AND(E11<0,G11>=0),(E11-G11)/E11,IF(AND(E11>0,G11>0),(G11-E11)/E11,IF(AND(E11=0,G11<=0),"",(G11-E11)/E11)))) -> 1 | I11: =+'N ESF ULTRAX'!N48 -> 0 | J11: =IF(AND(G11=0,I11>0),100%,IF(AND(G11<0,I11>=0),(G11-I11)/G11,IF(AND(G11>0,I11>0),(I11-G11)/G11,IF(AND(G11=0,I11<=0),"",(I11-G11)/G11)))) | K11: =IF(AND(B11=0,I11>0),100%,IF(AND(B11<0,I11>=0),(B11-I11)/B11,IF(AND(B11>0,I11>0),(I11-B11)/B11,IF(AND(B11=0,I11<=0),"",(I11-B11)/B11))))
A12: Bancos en transito en Bs | B12: =+'N ESF ULTRAX'!B62 -> 0 | C12: =+'N ESF ULTRAX'!E62 -> 995.37258 | D12: =IF(AND(B12=0,C12>0),100%,IF(AND(B12<0,C12>=0),(B12-C12)/B12,IF(AND(B12>0,C12>0),(C12-B12)/B12,IF(AND(B12=0,C12<=0),"",(C12-B12)/B12)))) -> 1 | E12: =+'N ESF ULTRAX'!H62 -> 2768.1093 | F12: =IF(AND(C12=0,E12>0),100%,IF(AND(C12<0,E12>=0),(C12-E12)/C12,IF(AND(C12>0,E12>0),(E12-C12)/C12,IF(AND(C12=0,E12<=0),"",(E12-C12)/C12)))) -> 1.7809781 | G12: =+'N ESF ULTRAX'!K62 -> 0 | H12: =IF(AND(E12=0,G12>0),100%,IF(AND(E12<0,G12>=0),(E12-G12)/E12,IF(AND(E12>0,G12>0),(G12-E12)/E12,IF(AND(E12=0,G12<=0),"",(G12-E12)/E12)))) -> -1 | I12: =+'N ESF ULTRAX'!N62 -> 0 | J12: =IF(AND(G12=0,I12>0),100%,IF(AND(G12<0,I12>=0),(G12-I12)/G12,IF(AND(G12>0,I12>0),(I12-G12)/G12,IF(AND(G12=0,I12<=0),"",(I12-G12)/G12)))) | K12: =IF(AND(B12=0,I12>0),100%,IF(AND(B12<0,I12>=0),(B12-I12)/B12,IF(AND(B12>0,I12>0),(I12-B12)/B12,IF(AND(B12=0,I12<=0),"",(I12-B12)/B12))))
A13: Bancos en transito en $ | B13: =+'N ESF ULTRAX'!B67 -> 0 | C13: =+'N ESF ULTRAX'!E67 -> 0 | D13: =IF(AND(B13=0,C13>0),100%,IF(AND(B13<0,C13>=0),(B13-C13)/B13,IF(AND(B13>0,C13>0),(C13-B13)/B13,IF(AND(B13=0,C13<=0),"",(C13-B13)/B13)))) | E13: =+'N ESF ULTRAX'!H67 -> 0 | F13: =IF(AND(C13=0,E13>0),100%,IF(AND(C13<0,E13>=0),(C13-E13)/C13,IF(AND(C13>0,E13>0),(E13-C13)/C13,IF(AND(C13=0,E13<=0),"",(E13-C13)/C13)))) | G13: =+'N ESF ULTRAX'!K67 -> 0 | H13: =IF(AND(E13=0,G13>0),100%,IF(AND(E13<0,G13>=0),(E13-G13)/E13,IF(AND(E13>0,G13>0),(G13-E13)/E13,IF(AND(E13=0,G13<=0),"",(G13-E13)/E13)))) | I13: =+'N ESF ULTRAX'!N67 -> 0 | J13: =IF(AND(G13=0,I13>0),100%,IF(AND(G13<0,I13>=0),(G13-I13)/G13,IF(AND(G13>0,I13>0),(I13-G13)/G13,IF(AND(G13=0,I13<=0),"",(I13-G13)/G13)))) | K13: =IF(AND(B13=0,I13>0),100%,IF(AND(B13<0,I13>=0),(B13-I13)/B13,IF(AND(B13>0,I13>0),(I13-B13)/B13,IF(AND(B13=0,I13<=0),"",(I13-B13)/B13))))
A14: Cuentas por Cobrar | B14: =+SUM(B15:B19) -> 0 | C14: =+SUM(C15:C19) -> 115040.24 | D14: =IF(AND(B14=0,C14>0),100%,IF(AND(B14<0,C14>=0),(B14-C14)/B14,IF(AND(B14>0,C14>0),(C14-B14)/B14,IF(AND(B14=0,C14<=0),"",(C14-B14)/B14)))) -> 1 | E14: =+SUM(E15:E19) -> 143935.71 | F14: =IF(AND(C14=0,E14>0),100%,IF(AND(C14<0,E14>=0),(C14-E14)/C14,IF(AND(C14>0,E14>0),(E14-C14)/C14,IF(AND(C14=0,E14<=0),"",(E14-C14)/C14)))) -> 0.25117707 | G14: =+SUM(G15:G19) -> 0 | H14: =IF(AND(E14=0,G14>0),100%,IF(AND(E14<0,G14>=0),(E14-G14)/E14,IF(AND(E14>0,G14>0),(G14-E14)/E14,IF(AND(E14=0,G14<=0),"",(G14-E14)/E14)))) -> -1 | I14: =+SUM(I15:I19) -> 0 | J14: =IF(AND(G14=0,I14>0),100%,IF(AND(G14<0,I14>=0),(G14-I14)/G14,IF(AND(G14>0,I14>0),(I14-G14)/G14,IF(AND(G14=0,I14<=0),"",(I14-G14)/G14)))) | K14: =IF(AND(B14=0,I14>0),100%,IF(AND(B14<0,I14>=0),(B14-I14)/B14,IF(AND(B14>0,I14>0),(I14-B14)/B14,IF(AND(B14=0,I14<=0),"",(I14-B14)/B14))))
A15: A clientes | B15: =+'N ESF ULTRAX'!B74 -> 0 | C15: =+'N ESF ULTRAX'!E74 -> 107521.28 | D15: =IF(AND(B15=0,C15>0),100%,IF(AND(B15<0,C15>=0),(B15-C15)/B15,IF(AND(B15>0,C15>0),(C15-B15)/B15,IF(AND(B15=0,C15<=0),"",(C15-B15)/B15)))) -> 1 | E15: =+'N ESF ULTRAX'!H74 -> 132552.96 | F15: =IF(AND(C15=0,E15>0),100%,IF(AND(C15<0,E15>=0),(C15-E15)/C15,IF(AND(C15>0,E15>0),(E15-C15)/C15,IF(AND(C15=0,E15<=0),"",(E15-C15)/C15)))) -> 0.23280675 | G15: =+'N ESF ULTRAX'!K74 -> 0 | H15: =IF(AND(E15=0,G15>0),100%,IF(AND(E15<0,G15>=0),(E15-G15)/E15,IF(AND(E15>0,G15>0),(G15-E15)/E15,IF(AND(E15=0,G15<=0),"",(G15-E15)/E15)))) -> -1 | I15: =+'N ESF ULTRAX'!N74 -> 0 | J15: =IF(AND(G15=0,I15>0),100%,IF(AND(G15<0,I15>=0),(G15-I15)/G15,IF(AND(G15>0,I15>0),(I15-G15)/G15,IF(AND(G15=0,I15<=0),"",(I15-G15)/G15)))) | K15: =IF(AND(B15=0,I15>0),100%,IF(AND(B15<0,I15>=0),(B15-I15)/B15,IF(AND(B15>0,I15>0),(I15-B15)/B15,IF(AND(B15=0,I15<=0),"",(I15-B15)/B15))))
A16: A empresas relacionadas del grupo | B16: =+'N ESF ULTRAX'!B86 -> 0 | C16: =+'N ESF ULTRAX'!E86 -> 3441.8 | D16: =IF(AND(B16=0,C16>0),100%,IF(AND(B16<0,C16>=0),(B16-C16)/B16,IF(AND(B16>0,C16>0),(C16-B16)/B16,IF(AND(B16=0,C16<=0),"",(C16-B16)/B16)))) -> 1 | E16: =+'N ESF ULTRAX'!H86 -> 5227.83 | F16: =IF(AND(C16=0,E16>0),100%,IF(AND(C16<0,E16>=0),(C16-E16)/C16,IF(AND(C16>0,E16>0),(E16-C16)/C16,IF(AND(C16=0,E16<=0),"",(E16-C16)/C16)))) -> 0.51892324 | G16: =+'N ESF ULTRAX'!K86 -> 0 | H16: =IF(AND(E16=0,G16>0),100%,IF(AND(E16<0,G16>=0),(E16-G16)/E16,IF(AND(E16>0,G16>0),(G16-E16)/E16,IF(AND(E16=0,G16<=0),"",(G16-E16)/E16)))) -> -1 | I16: =+'N ESF ULTRAX'!N86 -> 0 | J16: =IF(AND(G16=0,I16>0),100%,IF(AND(G16<0,I16>=0),(G16-I16)/G16,IF(AND(G16>0,I16>0),(I16-G16)/G16,IF(AND(G16=0,I16<=0),"",(I16-G16)/G16)))) | K16: =IF(AND(B16=0,I16>0),100%,IF(AND(B16<0,I16>=0),(B16-I16)/B16,IF(AND(B16>0,I16>0),(I16-B16)/B16,IF(AND(B16=0,I16<=0),"",(I16-B16)/B16))))
A17: A empresas externas del grupo | B17: =+'N ESF ULTRAX'!B92 -> 0 | C17: =+'N ESF ULTRAX'!E92 -> 0 | D17: =IF(AND(B17=0,C17>0),100%,IF(AND(B17<0,C17>=0),(B17-C17)/B17,IF(AND(B17>0,C17>0),(C17-B17)/B17,IF(AND(B17=0,C17<=0),"",(C17-B17)/B17)))) | E17: =+'N ESF ULTRAX'!H92 -> 0 | F17: =IF(AND(C17=0,E17>0),100%,IF(AND(C17<0,E17>=0),(C17-E17)/C17,IF(AND(C17>0,E17>0),(E17-C17)/C17,IF(AND(C17=0,E17<=0),"",(E17-C17)/C17)))) | G17: =+'N ESF ULTRAX'!K92 -> 0 | H17: =IF(AND(E17=0,G17>0),100%,IF(AND(E17<0,G17>=0),(E17-G17)/E17,IF(AND(E17>0,G17>0),(G17-E17)/E17,IF(AND(E17=0,G17<=0),"",(G17-E17)/E17)))) | I17: =+'N ESF ULTRAX'!N92 -> 0 | J17: =IF(AND(G17=0,I17>0),100%,IF(AND(G17<0,I17>=0),(G17-I17)/G17,IF(AND(G17>0,I17>0),(I17-G17)/G17,IF(AND(G17=0,I17<=0),"",(I17-G17)/G17)))) | K17: =IF(AND(B17=0,I17>0),100%,IF(AND(B17<0,I17>=0),(B17-I17)/B17,IF(AND(B17>0,I17>0),(I17-B17)/B17,IF(AND(B17=0,I17<=0),"",(I17-B17)/B17))))
A18: A socios | B18: =+'N ESF ULTRAX'!B98 -> 0 | C18: =+'N ESF ULTRAX'!E98 -> 2873.72 | D18: =IF(AND(B18=0,C18>0),100%,IF(AND(B18<0,C18>=0),(B18-C18)/B18,IF(AND(B18>0,C18>0),(C18-B18)/B18,IF(AND(B18=0,C18<=0),"",(C18-B18)/B18)))) -> 1 | E18: =+'N ESF ULTRAX'!H98 -> 4199.39 | F18: =IF(AND(C18=0,E18>0),100%,IF(AND(C18<0,E18>=0),(C18-E18)/C18,IF(AND(C18>0,E18>0),(E18-C18)/C18,IF(AND(C18=0,E18<=0),"",(E18-C18)/C18)))) -> 0.46130799 | G18: =+'N ESF ULTRAX'!K98 -> 0 | H18: =IF(AND(E18=0,G18>0),100%,IF(AND(E18<0,G18>=0),(E18-G18)/E18,IF(AND(E18>0,G18>0),(G18-E18)/E18,IF(AND(E18=0,G18<=0),"",(G18-E18)/E18)))) -> -1 | I18: =+'N ESF ULTRAX'!N98 -> 0 | J18: =IF(AND(G18=0,I18>0),100%,IF(AND(G18<0,I18>=0),(G18-I18)/G18,IF(AND(G18>0,I18>0),(I18-G18)/G18,IF(AND(G18=0,I18<=0),"",(I18-G18)/G18)))) | K18: =IF(AND(B18=0,I18>0),100%,IF(AND(B18<0,I18>=0),(B18-I18)/B18,IF(AND(B18>0,I18>0),(I18-B18)/B18,IF(AND(B18=0,I18<=0),"",(I18-B18)/B18))))
A19: A empleados | B19: =+'N ESF ULTRAX'!B102 -> 0 | C19: =+'N ESF ULTRAX'!E102 -> 1203.44 | D19: =IF(AND(B19=0,C19>0),100%,IF(AND(B19<0,C19>=0),(B19-C19)/B19,IF(AND(B19>0,C19>0),(C19-B19)/B19,IF(AND(B19=0,C19<=0),"",(C19-B19)/B19)))) -> 1 | E19: =+'N ESF ULTRAX'!H102 -> 1955.53 | F19: =IF(AND(C19=0,E19>0),100%,IF(AND(C19<0,E19>=0),(C19-E19)/C19,IF(AND(C19>0,E19>0),(E19-C19)/C19,IF(AND(C19=0,E19<=0),"",(E19-C19)/C19)))) -> 0.62495014 | G19: =+'N ESF ULTRAX'!K102 -> 0 | H19: =IF(AND(E19=0,G19>0),100%,IF(AND(E19<0,G19>=0),(E19-G19)/E19,IF(AND(E19>0,G19>0),(G19-E19)/E19,IF(AND(E19=0,G19<=0),"",(G19-E19)/E19)))) -> -1 | I19: =+'N ESF ULTRAX'!N102 -> 0 | J19: =IF(AND(G19=0,I19>0),100%,IF(AND(G19<0,I19>=0),(G19-I19)/G19,IF(AND(G19>0,I19>0),(I19-G19)/G19,IF(AND(G19=0,I19<=0),"",(I19-G19)/G19)))) | K19: =IF(AND(B19=0,I19>0),100%,IF(AND(B19<0,I19>=0),(B19-I19)/B19,IF(AND(B19>0,I19>0),(I19-B19)/B19,IF(AND(B19=0,I19<=0),"",(I19-B19)/B19))))
A20: Otras Cuentas por Cobrar | B20: =+SUM(B21:B22) -> 0 | C20: =+SUM(C21:C22) -> -961 | D20: =IF(AND(B20=0,C20>0),100%,IF(AND(B20<0,C20>=0),(B20-C20)/B20,IF(AND(B20>0,C20>0),(C20-B20)/B20,IF(AND(B20=0,C20<=0),"",(C20-B20)/B20)))) | E20: =+SUM(E21:E22) -> 0 | F20: =IF(AND(C20=0,E20>0),100%,IF(AND(C20<0,E20>=0),(C20-E20)/C20,IF(AND(C20>0,E20>0),(E20-C20)/C20,IF(AND(C20=0,E20<=0),"",(E20-C20)/C20)))) -> 1 | G20: =+SUM(G21:G22) -> 0 | H20: =IF(AND(E20=0,G20>0),100%,IF(AND(E20<0,G20>=0),(E20-G20)/E20,IF(AND(E20>0,G20>0),(G20-E20)/E20,IF(AND(E20=0,G20<=0),"",(G20-E20)/E20)))) | I20: =+SUM(I21:I22) -> 0 | J20: =IF(AND(G20=0,I20>0),100%,IF(AND(G20<0,I20>=0),(G20-I20)/G20,IF(AND(G20>0,I20>0),(I20-G20)/G20,IF(AND(G20=0,I20<=0),"",(I20-G20)/G20)))) | K20: =IF(AND(B20=0,I20>0),100%,IF(AND(B20<0,I20>=0),(B20-I20)/B20,IF(AND(B20>0,I20>0),(I20-B20)/B20,IF(AND(B20=0,I20<=0),"",(I20-B20)/B20))))
A21: Otras cuentas por cobrar | B21: =+'N ESF ULTRAX'!B110 -> 0 | C21: =+'N ESF ULTRAX'!E110 -> -961 | D21: =IF(AND(B21=0,C21>0),100%,IF(AND(B21<0,C21>=0),(B21-C21)/B21,IF(AND(B21>0,C21>0),(C21-B21)/B21,IF(AND(B21=0,C21<=0),"",(C21-B21)/B21)))) | E21: =+'N ESF ULTRAX'!H110 -> 0 | F21: =IF(AND(C21=0,E21>0),100%,IF(AND(C21<0,E21>=0),(C21-E21)/C21,IF(AND(C21>0,E21>0),(E21-C21)/C21,IF(AND(C21=0,E21<=0),"",(E21-C21)/C21)))) -> 1 | G21: =+'N ESF ULTRAX'!K110 -> 0 | H21: =IF(AND(E21=0,G21>0),100%,IF(AND(E21<0,G21>=0),(E21-G21)/E21,IF(AND(E21>0,G21>0),(G21-E21)/E21,IF(AND(E21=0,G21<=0),"",(G21-E21)/E21)))) | I21: =+'N ESF ULTRAX'!N110 -> 0 | J21: =IF(AND(G21=0,I21>0),100%,IF(AND(G21<0,I21>=0),(G21-I21)/G21,IF(AND(G21>0,I21>0),(I21-G21)/G21,IF(AND(G21=0,I21<=0),"",(I21-G21)/G21)))) | K21: =IF(AND(B21=0,I21>0),100%,IF(AND(B21<0,I21>=0),(B21-I21)/B21,IF(AND(B21>0,I21>0),(I21-B21)/B21,IF(AND(B21=0,I21<=0),"",(I21-B21)/B21))))
A22: Por sociedades | B22: =+'N ESF ULTRAX'!B114 -> 0 | C22: =+'N ESF ULTRAX'!E114 -> 0 | D22: =IF(AND(B22=0,C22>0),100%,IF(AND(B22<0,C22>=0),(B22-C22)/B22,IF(AND(B22>0,C22>0),(C22-B22)/B22,IF(AND(B22=0,C22<=0),"",(C22-B22)/B22)))) | E22: =+'N ESF ULTRAX'!H114 -> 0 | F22: =IF(AND(C22=0,E22>0),100%,IF(AND(C22<0,E22>=0),(C22-E22)/C22,IF(AND(C22>0,E22>0),(E22-C22)/C22,IF(AND(C22=0,E22<=0),"",(E22-C22)/C22)))) | G22: =+'N ESF ULTRAX'!K114 -> 0 | H22: =IF(AND(E22=0,G22>0),100%,IF(AND(E22<0,G22>=0),(E22-G22)/E22,IF(AND(E22>0,G22>0),(G22-E22)/E22,IF(AND(E22=0,G22<=0),"",(G22-E22)/E22)))) | I22: =+'N ESF ULTRAX'!N114 -> 0 | J22: =IF(AND(G22=0,I22>0),100%,IF(AND(G22<0,I22>=0),(G22-I22)/G22,IF(AND(G22>0,I22>0),(I22-G22)/G22,IF(AND(G22=0,I22<=0),"",(I22-G22)/G22)))) | K22: =IF(AND(B22=0,I22>0),100%,IF(AND(B22<0,I22>=0),(B22-I22)/B22,IF(AND(B22>0,I22>0),(I22-B22)/B22,IF(AND(B22=0,I22<=0),"",(I22-B22)/B22))))
A23: Préstamos por Cobrar | B23: =+SUM(B24:B28) -> 0 | C23: =+SUM(C24:C28) -> 16819.35 | D23: =IF(AND(B23=0,C23>0),100%,IF(AND(B23<0,C23>=0),(B23-C23)/B23,IF(AND(B23>0,C23>0),(C23-B23)/B23,IF(AND(B23=0,C23<=0),"",(C23-B23)/B23)))) -> 1 | E23: =+SUM(E24:E28) -> 22397.61 | F23: =IF(AND(C23=0,E23>0),100%,IF(AND(C23<0,E23>=0),(C23-E23)/C23,IF(AND(C23>0,E23>0),(E23-C23)/C23,IF(AND(C23=0,E23<=0),"",(E23-C23)/C23)))) -> 0.33165729 | G23: =+SUM(G24:G28) -> 0 | H23: =IF(AND(E23=0,G23>0),100%,IF(AND(E23<0,G23>=0),(E23-G23)/E23,IF(AND(E23>0,G23>0),(G23-E23)/E23,IF(AND(E23=0,G23<=0),"",(G23-E23)/E23)))) -> -1 | I23: =+SUM(I24:I28) -> 0 | J23: =IF(AND(G23=0,I23>0),100%,IF(AND(G23<0,I23>=0),(G23-I23)/G23,IF(AND(G23>0,I23>0),(I23-G23)/G23,IF(AND(G23=0,I23<=0),"",(I23-G23)/G23)))) | K23: =IF(AND(B23=0,I23>0),100%,IF(AND(B23<0,I23>=0),(B23-I23)/B23,IF(AND(B23>0,I23>0),(I23-B23)/B23,IF(AND(B23=0,I23<=0),"",(I23-B23)/B23))))
A24: A empresas relacionadas del grupo | B24: =+'N ESF ULTRAX'!B119 -> 0 | C24: =+'N ESF ULTRAX'!E119 -> 0 | D24: =IF(AND(B24=0,C24>0),100%,IF(AND(B24<0,C24>=0),(B24-C24)/B24,IF(AND(B24>0,C24>0),(C24-B24)/B24,IF(AND(B24=0,C24<=0),"",(C24-B24)/B24)))) | E24: =+'N ESF ULTRAX'!H119 -> 0 | F24: =IF(AND(C24=0,E24>0),100%,IF(AND(C24<0,E24>=0),(C24-E24)/C24,IF(AND(C24>0,E24>0),(E24-C24)/C24,IF(AND(C24=0,E24<=0),"",(E24-C24)/C24)))) | G24: =+'N ESF ULTRAX'!K119 -> 0 | H24: =IF(AND(E24=0,G24>0),100%,IF(AND(E24<0,G24>=0),(E24-G24)/E24,IF(AND(E24>0,G24>0),(G24-E24)/E24,IF(AND(E24=0,G24<=0),"",(G24-E24)/E24)))) | I24: =+'N ESF ULTRAX'!N119 -> 0 | J24: =IF(AND(G24=0,I24>0),100%,IF(AND(G24<0,I24>=0),(G24-I24)/G24,IF(AND(G24>0,I24>0),(I24-G24)/G24,IF(AND(G24=0,I24<=0),"",(I24-G24)/G24)))) | K24: =IF(AND(B24=0,I24>0),100%,IF(AND(B24<0,I24>=0),(B24-I24)/B24,IF(AND(B24>0,I24>0),(I24-B24)/B24,IF(AND(B24=0,I24<=0),"",(I24-B24)/B24))))
A25: A empresas externas del grupo | B25: =+'N ESF ULTRAX'!B125 -> 0 | C25: =+'N ESF ULTRAX'!E125 -> 0 | D25: =IF(AND(B25=0,C25>0),100%,IF(AND(B25<0,C25>=0),(B25-C25)/B25,IF(AND(B25>0,C25>0),(C25-B25)/B25,IF(AND(B25=0,C25<=0),"",(C25-B25)/B25)))) | E25: =+'N ESF ULTRAX'!H125 -> 0 | F25: =IF(AND(C25=0,E25>0),100%,IF(AND(C25<0,E25>=0),(C25-E25)/C25,IF(AND(C25>0,E25>0),(E25-C25)/C25,IF(AND(C25=0,E25<=0),"",(E25-C25)/C25)))) | G25: =+'N ESF ULTRAX'!K125 -> 0 | H25: =IF(AND(E25=0,G25>0),100%,IF(AND(E25<0,G25>=0),(E25-G25)/E25,IF(AND(E25>0,G25>0),(G25-E25)/E25,IF(AND(E25=0,G25<=0),"",(G25-E25)/E25)))) | I25: =+'N ESF ULTRAX'!N125 -> 0 | J25: =IF(AND(G25=0,I25>0),100%,IF(AND(G25<0,I25>=0),(G25-I25)/G25,IF(AND(G25>0,I25>0),(I25-G25)/G25,IF(AND(G25=0,I25<=0),"",(I25-G25)/G25)))) | K25: =IF(AND(B25=0,I25>0),100%,IF(AND(B25<0,I25>=0),(B25-I25)/B25,IF(AND(B25>0,I25>0),(I25-B25)/B25,IF(AND(B25=0,I25<=0),"",(I25-B25)/B25))))
A26: A socios | B26: =+'N ESF ULTRAX'!B131 -> 0 | C26: =+'N ESF ULTRAX'!E131 -> 15999.86 | D26: =IF(AND(B26=0,C26>0),100%,IF(AND(B26<0,C26>=0),(B26-C26)/B26,IF(AND(B26>0,C26>0),(C26-B26)/B26,IF(AND(B26=0,C26<=0),"",(C26-B26)/B26)))) -> 1 | E26: =+'N ESF ULTRAX'!H131 -> 20947.86 | F26: =IF(AND(C26=0,E26>0),100%,IF(AND(C26<0,E26>=0),(C26-E26)/C26,IF(AND(C26>0,E26>0),(E26-C26)/C26,IF(AND(C26=0,E26<=0),"",(E26-C26)/C26)))) -> 0.30925271 | G26: =+'N ESF ULTRAX'!K131 -> 0 | H26: =IF(AND(E26=0,G26>0),100%,IF(AND(E26<0,G26>=0),(E26-G26)/E26,IF(AND(E26>0,G26>0),(G26-E26)/E26,IF(AND(E26=0,G26<=0),"",(G26-E26)/E26)))) -> -1 | I26: =+'N ESF ULTRAX'!N131 -> 0 | J26: =IF(AND(G26=0,I26>0),100%,IF(AND(G26<0,I26>=0),(G26-I26)/G26,IF(AND(G26>0,I26>0),(I26-G26)/G26,IF(AND(G26=0,I26<=0),"",(I26-G26)/G26)))) | K26: =IF(AND(B26=0,I26>0),100%,IF(AND(B26<0,I26>=0),(B26-I26)/B26,IF(AND(B26>0,I26>0),(I26-B26)/B26,IF(AND(B26=0,I26<=0),"",(I26-B26)/B26))))
A27: A empleados | B27: =+'N ESF ULTRAX'!B135 -> 0 | C27: =+'N ESF ULTRAX'!E135 -> 819.49 | D27: =IF(AND(B27=0,C27>0),100%,IF(AND(B27<0,C27>=0),(B27-C27)/B27,IF(AND(B27>0,C27>0),(C27-B27)/B27,IF(AND(B27=0,C27<=0),"",(C27-B27)/B27)))) -> 1 | E27: =+'N ESF ULTRAX'!H135 -> 1449.75 | F27: =IF(AND(C27=0,E27>0),100%,IF(AND(C27<0,E27>=0),(C27-E27)/C27,IF(AND(C27>0,E27>0),(E27-C27)/C27,IF(AND(C27=0,E27<=0),"",(E27-C27)/C27)))) -> 0.76908809 | G27: =+'N ESF ULTRAX'!K135 -> 0 | H27: =IF(AND(E27=0,G27>0),100%,IF(AND(E27<0,G27>=0),(E27-G27)/E27,IF(AND(E27>0,G27>0),(G27-E27)/E27,IF(AND(E27=0,G27<=0),"",(G27-E27)/E27)))) -> -1 | I27: =+'N ESF ULTRAX'!N135 -> 0 | J27: =IF(AND(G27=0,I27>0),100%,IF(AND(G27<0,I27>=0),(G27-I27)/G27,IF(AND(G27>0,I27>0),(I27-G27)/G27,IF(AND(G27=0,I27<=0),"",(I27-G27)/G27)))) | K27: =IF(AND(B27=0,I27>0),100%,IF(AND(B27<0,I27>=0),(B27-I27)/B27,IF(AND(B27>0,I27>0),(I27-B27)/B27,IF(AND(B27=0,I27<=0),"",(I27-B27)/B27))))
A28: A terceros | B28: =+'N ESF ULTRAX'!B137 -> 0 | C28: =+'N ESF ULTRAX'!E137 -> 0 | D28: =IF(AND(B28=0,C28>0),100%,IF(AND(B28<0,C28>=0),(B28-C28)/B28,IF(AND(B28>0,C28>0),(C28-B28)/B28,IF(AND(B28=0,C28<=0),"",(C28-B28)/B28)))) | E28: =+'N ESF ULTRAX'!H137 -> 0 | F28: =IF(AND(C28=0,E28>0),100%,IF(AND(C28<0,E28>=0),(C28-E28)/C28,IF(AND(C28>0,E28>0),(E28-C28)/C28,IF(AND(C28=0,E28<=0),"",(E28-C28)/C28)))) | G28: =+'N ESF ULTRAX'!K137 -> 0 | H28: =IF(AND(E28=0,G28>0),100%,IF(AND(E28<0,G28>=0),(E28-G28)/E28,IF(AND(E28>0,G28>0),(G28-E28)/E28,IF(AND(E28=0,G28<=0),"",(G28-E28)/E28)))) | I28: =+'N ESF ULTRAX'!N137 -> 0 | J28: =IF(AND(G28=0,I28>0),100%,IF(AND(G28<0,I28>=0),(G28-I28)/G28,IF(AND(G28>0,I28>0),(I28-G28)/G28,IF(AND(G28=0,I28<=0),"",(I28-G28)/G28)))) | K28: =IF(AND(B28=0,I28>0),100%,IF(AND(B28<0,I28>=0),(B28-I28)/B28,IF(AND(B28>0,I28>0),(I28-B28)/B28,IF(AND(B28=0,I28<=0),"",(I28-B28)/B28))))
A29: Anticipos | B29: =+SUM(B30:B32) -> 0 | C29: =+SUM(C30:C32) -> 0 | D29: =IF(AND(B29=0,C29>0),100%,IF(AND(B29<0,C29>=0),(B29-C29)/B29,IF(AND(B29>0,C29>0),(C29-B29)/B29,IF(AND(B29=0,C29<=0),"",(C29-B29)/B29)))) | E29: =+SUM(E30:E32) -> 30.31 | F29: =IF(AND(C29=0,E29>0),100%,IF(AND(C29<0,E29>=0),(C29-E29)/C29,IF(AND(C29>0,E29>0),(E29-C29)/C29,IF(AND(C29=0,E29<=0),"",(E29-C29)/C29)))) -> 1 | G29: =+SUM(G30:G32) -> 0 | H29: =IF(AND(E29=0,G29>0),100%,IF(AND(E29<0,G29>=0),(E29-G29)/E29,IF(AND(E29>0,G29>0),(G29-E29)/E29,IF(AND(E29=0,G29<=0),"",(G29-E29)/E29)))) -> -1 | I29: =+SUM(I30:I32) -> 0 | J29: =IF(AND(G29=0,I29>0),100%,IF(AND(G29<0,I29>=0),(G29-I29)/G29,IF(AND(G29>0,I29>0),(I29-G29)/G29,IF(AND(G29=0,I29<=0),"",(I29-G29)/G29)))) | K29: =IF(AND(B29=0,I29>0),100%,IF(AND(B29<0,I29>=0),(B29-I29)/B29,IF(AND(B29>0,I29>0),(I29-B29)/B29,IF(AND(B29=0,I29<=0),"",(I29-B29)/B29))))
A30: A proveedores | B30: =+'N ESF ULTRAX'!B140 -> 0 | C30: =+'N ESF ULTRAX'!E140 -> 0 | D30: =IF(AND(B30=0,C30>0),100%,IF(AND(B30<0,C30>=0),(B30-C30)/B30,IF(AND(B30>0,C30>0),(C30-B30)/B30,IF(AND(B30=0,C30<=0),"",(C30-B30)/B30)))) | E30: =+'N ESF ULTRAX'!H140 -> 30.31 | F30: =IF(AND(C30=0,E30>0),100%,IF(AND(C30<0,E30>=0),(C30-E30)/C30,IF(AND(C30>0,E30>0),(E30-C30)/C30,IF(AND(C30=0,E30<=0),"",(E30-C30)/C30)))) -> 1 | G30: =+'N ESF ULTRAX'!K140 -> 0 | H30: =IF(AND(E30=0,G30>0),100%,IF(AND(E30<0,G30>=0),(E30-G30)/E30,IF(AND(E30>0,G30>0),(G30-E30)/E30,IF(AND(E30=0,G30<=0),"",(G30-E30)/E30)))) -> -1 | I30: =+'N ESF ULTRAX'!N140 -> 0 | J30: =IF(AND(G30=0,I30>0),100%,IF(AND(G30<0,I30>=0),(G30-I30)/G30,IF(AND(G30>0,I30>0),(I30-G30)/G30,IF(AND(G30=0,I30<=0),"",(I30-G30)/G30)))) | K30: =IF(AND(B30=0,I30>0),100%,IF(AND(B30<0,I30>=0),(B30-I30)/B30,IF(AND(B30>0,I30>0),(I30-B30)/B30,IF(AND(B30=0,I30<=0),"",(I30-B30)/B30))))
A31: A socios | B31: =+'N ESF ULTRAX'!B143 -> 0 | C31: =+'N ESF ULTRAX'!E143 -> 0 | D31: =IF(AND(B31=0,C31>0),100%,IF(AND(B31<0,C31>=0),(B31-C31)/B31,IF(AND(B31>0,C31>0),(C31-B31)/B31,IF(AND(B31=0,C31<=0),"",(C31-B31)/B31)))) | E31: =+'N ESF ULTRAX'!H143 -> 0 | F31: =IF(AND(C31=0,E31>0),100%,IF(AND(C31<0,E31>=0),(C31-E31)/C31,IF(AND(C31>0,E31>0),(E31-C31)/C31,IF(AND(C31=0,E31<=0),"",(E31-C31)/C31)))) | G31: =+'N ESF ULTRAX'!K143 -> 0 | H31: =IF(AND(E31=0,G31>0),100%,IF(AND(E31<0,G31>=0),(E31-G31)/E31,IF(AND(E31>0,G31>0),(G31-E31)/E31,IF(AND(E31=0,G31<=0),"",(G31-E31)/E31)))) | I31: =+'N ESF ULTRAX'!N143 -> 0 | J31: =IF(AND(G31=0,I31>0),100%,IF(AND(G31<0,I31>=0),(G31-I31)/G31,IF(AND(G31>0,I31>0),(I31-G31)/G31,IF(AND(G31=0,I31<=0),"",(I31-G31)/G31)))) | K31: =IF(AND(B31=0,I31>0),100%,IF(AND(B31<0,I31>=0),(B31-I31)/B31,IF(AND(B31>0,I31>0),(I31-B31)/B31,IF(AND(B31=0,I31<=0),"",(I31-B31)/B31))))
A32: A empleados | B32: =+'N ESF ULTRAX'!B148 -> 0 | C32: =+'N ESF ULTRAX'!E148 -> 0 | D32: =IF(AND(B32=0,C32>0),100%,IF(AND(B32<0,C32>=0),(B32-C32)/B32,IF(AND(B32>0,C32>0),(C32-B32)/B32,IF(AND(B32=0,C32<=0),"",(C32-B32)/B32)))) | E32: =+'N ESF ULTRAX'!H148 -> 0 | F32: =IF(AND(C32=0,E32>0),100%,IF(AND(C32<0,E32>=0),(C32-E32)/C32,IF(AND(C32>0,E32>0),(E32-C32)/C32,IF(AND(C32=0,E32<=0),"",(E32-C32)/C32)))) | G32: =+'N ESF ULTRAX'!K148 -> 0 | H32: =IF(AND(E32=0,G32>0),100%,IF(AND(E32<0,G32>=0),(E32-G32)/E32,IF(AND(E32>0,G32>0),(G32-E32)/E32,IF(AND(E32=0,G32<=0),"",(G32-E32)/E32)))) | I32: =+'N ESF ULTRAX'!N148 -> 0 | J32: =IF(AND(G32=0,I32>0),100%,IF(AND(G32<0,I32>=0),(G32-I32)/G32,IF(AND(G32>0,I32>0),(I32-G32)/G32,IF(AND(G32=0,I32<=0),"",(I32-G32)/G32)))) | K32: =IF(AND(B32=0,I32>0),100%,IF(AND(B32<0,I32>=0),(B32-I32)/B32,IF(AND(B32>0,I32>0),(I32-B32)/B32,IF(AND(B32=0,I32<=0),"",(I32-B32)/B32))))
A33: Inventarios | B33: =+SUM(B34:B37) -> 0 | C33: =+SUM(C34:C37) -> 865451.43 | D33: =IF(AND(B33=0,C33>0),100%,IF(AND(B33<0,C33>=0),(B33-C33)/B33,IF(AND(B33>0,C33>0),(C33-B33)/B33,IF(AND(B33=0,C33<=0),"",(C33-B33)/B33)))) -> 1 | E33: =+SUM(E34:E37) -> 980716.56 | F33: =IF(AND(C33=0,E33>0),100%,IF(AND(C33<0,E33>=0),(C33-E33)/C33,IF(AND(C33>0,E33>0),(E33-C33)/C33,IF(AND(C33=0,E33<=0),"",(E33-C33)/C33)))) -> 0.13318498 | G33: =+SUM(G34:G37) -> 0 | H33: =IF(AND(E33=0,G33>0),100%,IF(AND(E33<0,G33>=0),(E33-G33)/E33,IF(AND(E33>0,G33>0),(G33-E33)/E33,IF(AND(E33=0,G33<=0),"",(G33-E33)/E33)))) -> -1 | I33: =+SUM(I34:I37) -> 0 | J33: =IF(AND(G33=0,I33>0),100%,IF(AND(G33<0,I33>=0),(G33-I33)/G33,IF(AND(G33>0,I33>0),(I33-G33)/G33,IF(AND(G33=0,I33<=0),"",(I33-G33)/G33)))) | K33: =IF(AND(B33=0,I33>0),100%,IF(AND(B33<0,I33>=0),(B33-I33)/B33,IF(AND(B33>0,I33>0),(I33-B33)/B33,IF(AND(B33=0,I33<=0),"",(I33-B33)/B33))))
A34: De mercancía | B34: =+'N ESF ULTRAX'!B151 -> 0 | C34: =+'N ESF ULTRAX'!E151 -> 843080.14 | D34: =IF(AND(B34=0,C34>0),100%,IF(AND(B34<0,C34>=0),(B34-C34)/B34,IF(AND(B34>0,C34>0),(C34-B34)/B34,IF(AND(B34=0,C34<=0),"",(C34-B34)/B34)))) -> 1 | E34: =+'N ESF ULTRAX'!H151 -> 960532.21 | F34: =IF(AND(C34=0,E34>0),100%,IF(AND(C34<0,E34>=0),(C34-E34)/C34,IF(AND(C34>0,E34>0),(E34-C34)/C34,IF(AND(C34=0,E34<=0),"",(E34-C34)/C34)))) -> 0.13931306 | G34: =+'N ESF ULTRAX'!K151 -> 0 | H34: =IF(AND(E34=0,G34>0),100%,IF(AND(E34<0,G34>=0),(E34-G34)/E34,IF(AND(E34>0,G34>0),(G34-E34)/E34,IF(AND(E34=0,G34<=0),"",(G34-E34)/E34)))) -> -1 | I34: =+'N ESF ULTRAX'!N151 -> 0 | J34: =IF(AND(G34=0,I34>0),100%,IF(AND(G34<0,I34>=0),(G34-I34)/G34,IF(AND(G34>0,I34>0),(I34-G34)/G34,IF(AND(G34=0,I34<=0),"",(I34-G34)/G34)))) | K34: =IF(AND(B34=0,I34>0),100%,IF(AND(B34<0,I34>=0),(B34-I34)/B34,IF(AND(B34>0,I34>0),(I34-B34)/B34,IF(AND(B34=0,I34<=0),"",(I34-B34)/B34))))
A35: De suministros | B35: =+'N ESF ULTRAX'!B153 -> 0 | C35: =+'N ESF ULTRAX'!E153 -> 8142.86 | D35: =IF(AND(B35=0,C35>0),100%,IF(AND(B35<0,C35>=0),(B35-C35)/B35,IF(AND(B35>0,C35>0),(C35-B35)/B35,IF(AND(B35=0,C35<=0),"",(C35-B35)/B35)))) -> 1 | E35: =+'N ESF ULTRAX'!H153 -> 6855.06 | F35: =IF(AND(C35=0,E35>0),100%,IF(AND(C35<0,E35>=0),(C35-E35)/C35,IF(AND(C35>0,E35>0),(E35-C35)/C35,IF(AND(C35=0,E35<=0),"",(E35-C35)/C35)))) -> -0.15815082 | G35: =+'N ESF ULTRAX'!K153 -> 0 | H35: =IF(AND(E35=0,G35>0),100%,IF(AND(E35<0,G35>=0),(E35-G35)/E35,IF(AND(E35>0,G35>0),(G35-E35)/E35,IF(AND(E35=0,G35<=0),"",(G35-E35)/E35)))) -> -1 | I35: =+'N ESF ULTRAX'!N153 -> 0 | J35: =IF(AND(G35=0,I35>0),100%,IF(AND(G35<0,I35>=0),(G35-I35)/G35,IF(AND(G35>0,I35>0),(I35-G35)/G35,IF(AND(G35=0,I35<=0),"",(I35-G35)/G35)))) | K35: =IF(AND(B35=0,I35>0),100%,IF(AND(B35<0,I35>=0),(B35-I35)/B35,IF(AND(B35>0,I35>0),(I35-B35)/B35,IF(AND(B35=0,I35<=0),"",(I35-B35)/B35))))
A36: En tránsito | B36: =+'N ESF ULTRAX'!B155 -> 0 | C36: =+'N ESF ULTRAX'!E155 -> 1865.38 | D36: =IF(AND(B36=0,C36>0),100%,IF(AND(B36<0,C36>=0),(B36-C36)/B36,IF(AND(B36>0,C36>0),(C36-B36)/B36,IF(AND(B36=0,C36<=0),"",(C36-B36)/B36)))) -> 1 | E36: =+'N ESF ULTRAX'!H155 -> 782.75 | F36: =IF(AND(C36=0,E36>0),100%,IF(AND(C36<0,E36>=0),(C36-E36)/C36,IF(AND(C36>0,E36>0),(E36-C36)/C36,IF(AND(C36=0,E36<=0),"",(E36-C36)/C36)))) -> -0.58038041 | G36: =+'N ESF ULTRAX'!K155 -> 0 | H36: =IF(AND(E36=0,G36>0),100%,IF(AND(E36<0,G36>=0),(E36-G36)/E36,IF(AND(E36>0,G36>0),(G36-E36)/E36,IF(AND(E36=0,G36<=0),"",(G36-E36)/E36)))) -> -1 | I36: =+'N ESF ULTRAX'!N155 -> 0 | J36: =IF(AND(G36=0,I36>0),100%,IF(AND(G36<0,I36>=0),(G36-I36)/G36,IF(AND(G36>0,I36>0),(I36-G36)/G36,IF(AND(G36=0,I36<=0),"",(I36-G36)/G36)))) | K36: =IF(AND(B36=0,I36>0),100%,IF(AND(B36<0,I36>=0),(B36-I36)/B36,IF(AND(B36>0,I36>0),(I36-B36)/B36,IF(AND(B36=0,I36<=0),"",(I36-B36)/B36))))
A37: A consignación | B37: =+'N ESF ULTRAX'!B158 -> 0 | C37: =+'N ESF ULTRAX'!E158 -> 12363.05 | D37: =IF(AND(B37=0,C37>0),100%,IF(AND(B37<0,C37>=0),(B37-C37)/B37,IF(AND(B37>0,C37>0),(C37-B37)/B37,IF(AND(B37=0,C37<=0),"",(C37-B37)/B37)))) -> 1 | E37: =+'N ESF ULTRAX'!H158 -> 12546.54 | F37: =IF(AND(C37=0,E37>0),100%,IF(AND(C37<0,E37>=0),(C37-E37)/C37,IF(AND(C37>0,E37>0),(E37-C37)/C37,IF(AND(C37=0,E37<=0),"",(E37-C37)/C37)))) -> 0.014841807 | G37: =+'N ESF ULTRAX'!K158 -> 0 | H37: =IF(AND(E37=0,G37>0),100%,IF(AND(E37<0,G37>=0),(E37-G37)/E37,IF(AND(E37>0,G37>0),(G37-E37)/E37,IF(AND(E37=0,G37<=0),"",(G37-E37)/E37)))) -> -1 | I37: =+'N ESF ULTRAX'!N158 -> 0 | J37: =IF(AND(G37=0,I37>0),100%,IF(AND(G37<0,I37>=0),(G37-I37)/G37,IF(AND(G37>0,I37>0),(I37-G37)/G37,IF(AND(G37=0,I37<=0),"",(I37-G37)/G37)))) | K37: =IF(AND(B37=0,I37>0),100%,IF(AND(B37<0,I37>=0),(B37-I37)/B37,IF(AND(B37>0,I37>0),(I37-B37)/B37,IF(AND(B37=0,I37<=0),"",(I37-B37)/B37))))
A38: Prepagados | B38: =+SUM(B39:B40) -> 0 | C38: =+SUM(C39:C40) -> 14972.967 | D38: =IF(AND(B38=0,C38>0),100%,IF(AND(B38<0,C38>=0),(B38-C38)/B38,IF(AND(B38>0,C38>0),(C38-B38)/B38,IF(AND(B38=0,C38<=0),"",(C38-B38)/B38)))) -> 1 | E38: =+SUM(E39:E40) -> 13068.429 | F38: =IF(AND(C38=0,E38>0),100%,IF(AND(C38<0,E38>=0),(C38-E38)/C38,IF(AND(C38>0,E38>0),(E38-C38)/C38,IF(AND(C38=0,E38<=0),"",(E38-C38)/C38)))) -> -0.12719839 | G38: =+SUM(G39:G40) -> 0 | H38: =IF(AND(E38=0,G38>0),100%,IF(AND(E38<0,G38>=0),(E38-G38)/E38,IF(AND(E38>0,G38>0),(G38-E38)/E38,IF(AND(E38=0,G38<=0),"",(G38-E38)/E38)))) -> -1 | I38: =+SUM(I39:I40) -> 0 | J38: =IF(AND(G38=0,I38>0),100%,IF(AND(G38<0,I38>=0),(G38-I38)/G38,IF(AND(G38>0,I38>0),(I38-G38)/G38,IF(AND(G38=0,I38<=0),"",(I38-G38)/G38)))) | K38: =IF(AND(B38=0,I38>0),100%,IF(AND(B38<0,I38>=0),(B38-I38)/B38,IF(AND(B38>0,I38>0),(I38-B38)/B38,IF(AND(B38=0,I38<=0),"",(I38-B38)/B38))))
A39: Impuestos | B39: =+'N ESF ULTRAX'!B162 -> 0 | C39: =+'N ESF ULTRAX'!E162 -> 4312.9667 | D39: =IF(AND(B39=0,C39>0),100%,IF(AND(B39<0,C39>=0),(B39-C39)/B39,IF(AND(B39>0,C39>0),(C39-B39)/B39,IF(AND(B39=0,C39<=0),"",(C39-B39)/B39)))) -> 1 | E39: =+'N ESF ULTRAX'!H162 -> 2408.4294 | F39: =IF(AND(C39=0,E39>0),100%,IF(AND(C39<0,E39>=0),(C39-E39)/C39,IF(AND(C39>0,E39>0),(E39-C39)/C39,IF(AND(C39=0,E39<=0),"",(E39-C39)/C39)))) -> -0.44158404 | G39: =+'N ESF ULTRAX'!K162 -> 0 | H39: =IF(AND(E39=0,G39>0),100%,IF(AND(E39<0,G39>=0),(E39-G39)/E39,IF(AND(E39>0,G39>0),(G39-E39)/E39,IF(AND(E39=0,G39<=0),"",(G39-E39)/E39)))) -> -1 | I39: =+'N ESF ULTRAX'!N162 -> 0 | J39: =IF(AND(G39=0,I39>0),100%,IF(AND(G39<0,I39>=0),(G39-I39)/G39,IF(AND(G39>0,I39>0),(I39-G39)/G39,IF(AND(G39=0,I39<=0),"",(I39-G39)/G39)))) | K39: =IF(AND(B39=0,I39>0),100%,IF(AND(B39<0,I39>=0),(B39-I39)/B39,IF(AND(B39>0,I39>0),(I39-B39)/B39,IF(AND(B39=0,I39<=0),"",(I39-B39)/B39))))
A40: Gastos pagados por anticipado | B40: =+'N ESF ULTRAX'!B168 -> 0 | C40: =+'N ESF ULTRAX'!E168 -> 10660 | D40: =IF(AND(B40=0,C40>0),100%,IF(AND(B40<0,C40>=0),(B40-C40)/B40,IF(AND(B40>0,C40>0),(C40-B40)/B40,IF(AND(B40=0,C40<=0),"",(C40-B40)/B40)))) -> 1 | E40: =+'N ESF ULTRAX'!H168 -> 10660 | F40: =IF(AND(C40=0,E40>0),100%,IF(AND(C40<0,E40>=0),(C40-E40)/C40,IF(AND(C40>0,E40>0),(E40-C40)/C40,IF(AND(C40=0,E40<=0),"",(E40-C40)/C40)))) -> 0 | G40: =+'N ESF ULTRAX'!K168 -> 0 | H40: =IF(AND(E40=0,G40>0),100%,IF(AND(E40<0,G40>=0),(E40-G40)/E40,IF(AND(E40>0,G40>0),(G40-E40)/E40,IF(AND(E40=0,G40<=0),"",(G40-E40)/E40)))) -> -1 | I40: =+'N ESF ULTRAX'!N168 -> 0 | J40: =IF(AND(G40=0,I40>0),100%,IF(AND(G40<0,I40>=0),(G40-I40)/G40,IF(AND(G40>0,I40>0),(I40-G40)/G40,IF(AND(G40=0,I40<=0),"",(I40-G40)/G40)))) | K40: =IF(AND(B40=0,I40>0),100%,IF(AND(B40<0,I40>=0),(B40-I40)/B40,IF(AND(B40>0,I40>0),(I40-B40)/B40,IF(AND(B40=0,I40<=0),"",(I40-B40)/B40))))
A41: ACTIVOS NO CORRIENTES | B41: =+B42+B48 -> 0 | C41: =+C42+C48 -> 82701.4 | D41: =IF(AND(B41=0,C41>0),100%,IF(AND(B41<0,C41>=0),(B41-C41)/B41,IF(AND(B41>0,C41>0),(C41-B41)/B41,IF(AND(B41=0,C41<=0),"",(C41-B41)/B41)))) -> 1 | E41: =+E42+E48 -> 86759.9 | F41: =IF(AND(C41=0,E41>0),100%,IF(AND(C41<0,E41>=0),(C41-E41)/C41,IF(AND(C41>0,E41>0),(E41-C41)/C41,IF(AND(C41=0,E41<=0),"",(E41-C41)/C41)))) -> 0.049074139 | G41: =+G42+G48 -> 0 | H41: =IF(AND(E41=0,G41>0),100%,IF(AND(E41<0,G41>=0),(E41-G41)/E41,IF(AND(E41>0,G41>0),(G41-E41)/E41,IF(AND(E41=0,G41<=0),"",(G41-E41)/E41)))) -> -1 | I41: =+I42+I48 -> 0 | J41: =IF(AND(G41=0,I41>0),100%,IF(AND(G41<0,I41>=0),(G41-I41)/G41,IF(AND(G41>0,I41>0),(I41-G41)/G41,IF(AND(G41=0,I41<=0),"",(I41-G41)/G41)))) | K41: =IF(AND(B41=0,I41>0),100%,IF(AND(B41<0,I41>=0),(B41-I41)/B41,IF(AND(B41>0,I41>0),(I41-B41)/B41,IF(AND(B41=0,I41<=0),"",(I41-B41)/B41))))
...

Sheet  EERR ULTRAX
A2: ESTADO DE RESULTADOS
A3: PARTIDAS | B3: =IF(ISBLANK(A2),"",YEAR(TODAY())-1) -> 2025 | C3: % Vtas | D3: % Gastos | E3: ENE | F3: % Vtas | G3: % Gastos | H3: FEB | I3: % Vtas | J3: % Gastos | K3: Vari Rel. | L3: ACUM EJEC | M3: % Vtas | N3: % Gastos | O3: MAR | P3: % Vtas | Q3: % Gastos | R3: Vari Rel. | S3: ACUM EJEC | T3: % Vtas | U3: % Gastos | V3: ACUM PPTO | W3: % Vtas | X3: Var PPTO | Y3: ABR | Z3: % Vtas | AA3: % Gastos | AB3: Vari Rel. | AC3: ACUM EJEC | AD3: % Vtas | AE3: % Gastos | AF3: MAY | AG3: % Vtas | AH3: % Gastos | AI3: Vari Rel. | AJ3: ACUM EJEC | AK3: % Vtas | AL3: % Gastos | AM3: JUN | AN3: % Vtas | AO3: % Gastos | AP3: Vari Rel. | AQ3: ACUM EJEC | AR3: % Vtas | AS3: % Gastos | AT3: ACUM PPTO | AU3: % Vtas | AV3: Var PPTO | AW3: PROM 6 EJEC | AX3: % Vtas | AY3: % Gastos | AZ3: PROM 6 PPTO | BA3: % Vtas | BB3: Var PPTO | BC3: JUL | BD3: % Vtas | BE3: % Gastos | BF3: Vari Rel. | BG3: ACUM EJEC | BH3: % Vtas | BI3: % Gastos | BJ3: AGO | BK3: % Vtas | BL3: % Gastos | BM3: Vari Rel. | BN3: ACUM EJEC | BO3: % Vtas | BP3: % Gastos | BQ3: SEPT | BR3: % Vtas | BS3: % Gastos | BT3: Vari Rel. | BU3: ACUM EJEC | BV3: % Vtas | BW3: % Gastos | BX3: ACUM PPTO | BY3: % Vtas | BZ3: Var PPTO | CA3: OCT | CB3: % Vtas | CC3: % Gastos | CD3: Vari Rel. | CE3: ACUM EJEC | CF3: % Vtas | CG3: % Gastos | CH3: NOV | CI3: % Vtas | CJ3: % Gastos | CK3: Vari Rel. | CL3: ACUM EJEC | CM3: % Vtas | CN3: % Gastos | CO3: DIC | CP3: % Vtas | CQ3: % Gastos | CR3: Vari Rel. | CS3: 2025 | CT3: % Vtas | CU3: % Gastos | CV3: ACUM PPTO | CW3: % Vtas | CX3: Var PPTO
A4: Total Ingresos | B4: =+B5+B10+B15+B18 -> 0 | C4: =IF(AND(B4=0,B4>=0), "",B4/B4) | E4: =+E5+E10+E15+E18 -> 69718.3 | F4: =IF(AND(E4=0,E4>=0), "",E4/E4) -> 1 | H4: =+H5+H10+H15+H18 -> 90981.729 | I4: =IF(AND(H4=0,H4>=0), "",H4/H4) -> 1 | K4: =IF(AND(E4=0,H4>0),100%,IF(AND(E4<0,H4=0),(E4-H4)/E4,IF(AND(E4>0,H4>0),(H4-E4)/E4,IF(AND(E4=0,H4=0),"",(H4-E4)/E4)))) -> 0.30499065 | L4: =+L5+L10+L15+L18 -> 160700.03 | M4: =IF(AND(L4=0,L4>=0), "",L4/L4) -> 1 | O4: =+O5+O10+O15+O18 -> 107659.26 | P4: =IF(AND(O4=0,O4>=0), "",O4/O4) -> 1 | R4: =IF(AND(H4=0,O4>0),100%,IF(AND(H4<0,O4=0),(H4-O4)/H4,IF(AND(H4>0,O4>0),(O4-H4)/H4,IF(AND(H4=0,O4=0),"",(O4-H4)/H4)))) -> 0.18330632 | S4: =+S5+S10+S15+S18 -> 268359.28 | T4: =IF(AND(S4=0,S4>=0), "",S4/S4) -> 1 | V4: =+V5+V10+V15+V18 -> 0 | W4: =IF(AND(V4=0,V4>=0), "",V4/V4) | X4: =IF(AND(V4=0,S4>0),100%,IF(AND(V4<0,S4=0),(V4-S4)/V4,IF(AND(V4>0,S4>0),(S4-V4)/V4,IF(AND(V4=0,S4=0),"",(S4-V4)/V4)))) -> 1 | Y4: =+Y5+Y10+Y15+Y18 -> 117425.78 | Z4: =IF(AND(Y4=0,Y4>=0), "",Y4/Y4) -> 1 | AB4: =IF(AND(O4=0,Y4>0),100%,IF(AND(O4<0,Y4=0),(O4-Y4)/O4,IF(AND(O4>0,Y4>0),(Y4-O4)/O4,IF(AND(O4=0,Y4=0),"",(Y4-O4)/O4)))) -> 0.090716988 | AC4: =+AC5+AC10+AC15+AC18 -> 385785.06 | AD4: =IF(AND(AC4=0,AC4>=0), "",AC4/AC4) -> 1 | AF4: =+AF5+AF10+AF15+AF18 -> 132408.43 | AG4: =IF(AND(AF4=0,AF4>=0), "",AF4/AF4) -> 1 | AI4: =IF(AND(Y4=0,AF4>0),100%,IF(AND(Y4<0,AF4=0),(Y4-AF4)/Y4,IF(AND(Y4>0,AF4>0),(AF4-Y4)/Y4,IF(AND(Y4=0,AF4=0),"",(AF4-Y4)/Y4)))) -> 0.12759251 | AJ4: =+AJ5+AJ10+AJ15+AJ18 -> 518193.49 | AK4: =IF(AND(AJ4=0,AJ4>=0), "",AJ4/AJ4) -> 1 | AM4: =+AM5+AM10+AM15+AM18 -> 118129.94 | AN4: =IF(AND(AM4=0,AM4>=0), "",AM4/AM4) -> 1 | AP4: =IF(AND(AF4=0,AM4>0),100%,IF(AND(AF4<0,AM4=0),(AF4-AM4)/AF4,IF(AND(AF4>0,AM4>0),(AM4-AF4)/AF4,IF(AND(AF4=0,AM4=0),"",(AM4-AF4)/AF4)))) -> -0.10783671 | AQ4: =+AQ5+AQ10+AQ15+AQ18 -> 636323.43 | AR4: =IF(AND(AQ4=0,AQ4>=0), "",AQ4/AQ4) -> 1 | AT4: =+AT5+AT10+AT15+AT18 -> 0 | AU4: =IF(AND(AT4=0,AT4>=0), "",AT4/AT4) | AV4: =IF(AND(AT4=0,AQ4>0),100%,IF(AND(AT4<0,AQ4=0),(AT4-AQ4)/AT4,IF(AND(AT4>0,AQ4>0),(AQ4-AT4)/AT4,IF(AND(AT4=0,AQ4=0),"",(AQ4-AT4)/AT4)))) -> 1 | AW4: =+AW5+AW10+AW15+AW18 -> 106053.91 | AX4: =IF(AND(AW4=0,AW4>=0), "",AW4/AW4) -> 1 | AZ4: =+AZ5+AZ10+AZ15+AZ18 -> 0 | BA4: =IF(AND(AZ4=0,AZ4>=0), "",AZ4/AZ4) | BB4: =IF(AND(AZ4=0,AW4>0),100%,IF(AND(AZ4<0,AW4=0),(AZ4-AW4)/AZ4,IF(AND(AZ4>0,AW4>0),(AW4-AZ4)/AZ4,IF(AND(AZ4=0,AW4=0),"",(AW4-AZ4)/AZ4)))) -> 1 | BC4: =+BC5+BC10+BC15+BC18 -> 0 | BD4: =IF(AND(BC4=0,BC4>=0), "",BC4/BC4) | BF4: =IF(AND(AM4=0,BC4>0),100%,IF(AND(AM4<0,BC4=0),(AM4-BC4)/AM4,IF(AND(AM4>0,BC4>0),(BC4-AM4)/AM4,IF(AND(AM4=0,BC4=0),"",(BC4-AM4)/AM4)))) -> -1 | BG4: =+BG5+BG10+BG15+BG18 -> 636323.43 | BH4: =IF(AND(BG4=0,BG4>=0), "",BG4/BG4) -> 1 | BJ4: =+BJ5+BJ10+BJ15+BJ18 -> 0 | BK4: =IF(AND(BJ4=0,BJ4>=0), "",BJ4/BJ4) | BM4: =IF(AND(BC4=0,BJ4>0),100%,IF(AND(BC4<0,BJ4=0),(BC4-BJ4)/BC4,IF(AND(BC4>0,BJ4>0),(BJ4-BC4)/BC4,IF(AND(BC4=0,BJ4=0),"",(BJ4-BC4)/BC4)))) | BN4: =+BN5+BN10+BN15+BN18 -> 636323.43 | BO4: =IF(AND(BN4=0,BN4>=0), "",BN4/BN4) -> 1 | BQ4: =+BQ5+BQ10+BQ15+BQ18 -> 0 | BR4: =IF(AND(BQ4=0,BQ4>=0), "",BQ4/BQ4) | BT4: =IF(AND(BJ4=0,BQ4>0),100%,IF(AND(BJ4<0,BQ4=0),(BJ4-BQ4)/BJ4,IF(AND(BJ4>0,BQ4>0),(BQ4-BJ4)/BJ4,IF(AND(BJ4=0,BQ4=0),"",(BQ4-BJ4)/BJ4)))) | BU4: =+BU5+BU10+BU15+BU18 -> 636323.43 | BV4: =IF(AND(BU4=0,BU4>=0), "",BU4/BU4) -> 1 | BX4: =+BX5+BX10+BX15+BX18 -> 0 | BY4: =IF(AND(BX4=0,BX4>=0), "",BX4/BX4) | BZ4: =IF(AND(BX4=0,BU4>0),100%,IF(AND(BX4<0,BU4=0),(BX4-BU4)/BX4,IF(AND(BX4>0,BU4>0),(BU4-BX4)/BX4,IF(AND(BX4=0,BU4=0),"",(BU4-BX4)/BX4)))) -> 1 | CA4: =+CA5+CA10+CA15+CA18 -> 0 | CB4: =IF(AND(CA4=0,CA4>=0), "",CA4/CA4) | CD4: =IF(AND(BQ4=0,CA4>0),100%,IF(AND(BQ4<0,CA4=0),(BQ4-CA4)/BQ4,IF(AND(BQ4>0,CA4>0),(CA4-BQ4)/BQ4,IF(AND(BQ4=0,CA4=0),"",(CA4-BQ4)/BQ4)))) | CE4: =+CE5+CE10+CE15+CE18 -> 636323.43 | CF4: =IF(AND(CE4=0,CE4>=0), "",CE4/CE4) -> 1 | CH4: =+CH5+CH10+CH15+CH18 -> 0 | CI4: =IF(AND(CH4=0,CH4>=0), "",CH4/CH4) | CK4: =IF(AND(CA4=0,CH4>0),100%,IF(AND(CA4<0,CH4=0),(CA4-CH4)/CA4,IF(AND(CA4>0,CH4>0),(CH4-CA4)/CA4,IF(AND(CA4=0,CH4=0),"",(CH4-CA4)/CA4)))) | CL4: =+CL5+CL10+CL15+CL18 -> 636323.43 | CM4: =IF(AND(CL4=0,CL4>=0), "",CL4/CL4) -> 1 | CO4: =+CO5+CO10+CO15+CO18 -> 0 | CP4: =IF(AND(CO4=0,CO4>=0), "",CO4/CO4) | CR4: =IF(AND(CH4=0,CO4>0),100%,IF(AND(CH4<0,CO4=0),(CH4-CO4)/CH4,IF(AND(CH4>0,CO4>0),(CO4-CH4)/CH4,IF(AND(CH4=0,CO4=0),"",(CO4-CH4)/CH4)))) | CS4: =+CS5+CS10+CS15+CS18 -> 636323.43 | CT4: =IF(AND(CS4=0,CS4>=0), "",CS4/CS4) -> 1 | CV4: =+CV5+CV10+CV15+CV18 -> 0 | CW4: =IF(AND(CV4=0,CV4>=0), "",CV4/CV4) | CX4: =IF(AND(CV4=0,CS4>0),100%,IF(AND(CV4<0,CS4=0),(CV4-CS4)/CV4,IF(AND(CV4>0,CS4>0),(CS4-CV4)/CV4,IF(AND(CV4=0,CS4=0),"",(CS4-CV4)/CV4)))) -> 1
A5: Subtotal Ingresos por Venta de Mercancia | B5: =+B6+B7+B8 -> 0 | C5: =IF(AND(B4=0,B5>=0), "",B5/B4) | E5: =+E6+E7+E8 -> 67748.176 | F5: =IF(AND(E4=0,E5>=0), "",E5/E4) -> 0.97174165 | H5: =+H6+H7+H8 -> 89152.784 | I5: =IF(AND(H4=0,H5>=0), "",H5/H4) -> 0.97989766 | K5: =IF(AND(E5=0,H5>0),100%,IF(AND(E5<0,H5=0),(E5-H5)/E5,IF(AND(E5>0,H5>0),(H5-E5)/E5,IF(AND(E5=0,H5=0),"",(H5-E5)/E5)))) -> 0.31594368 | L5: =+L6+L7+L8 -> 156900.96 | M5: =IF(AND(L4=0,L5>=0), "",L5/L4) -> 0.97635925 | O5: =+O6+O7+O8 -> 104539.79 | P5: =IF(AND(O4=0,O5>=0), "",O5/O4) -> 0.97102466 | R5: =IF(AND(H5=0,O5>0),100%,IF(AND(H5<0,O5=0),(H5-O5)/H5,IF(AND(H5>0,O5>0),(O5-H5)/H5,IF(AND(H5=0,O5=0),"",(O5-H5)/H5)))) -> 0.17259145 | S5: =+S6+S7+S8 -> 261440.75 | T5: =IF(AND(S4=0,S5>=0), "",S5/S4) -> 0.97421914 | V5: =+V6+V7+V8 -> 0 | W5: =IF(AND(V4=0,V5>=0), "",V5/V4) | X5: =IF(AND(V5=0,S5>0),100%,IF(AND(V5<0,S5=0),(V5-S5)/V5,IF(AND(V5>0,S5>0),(S5-V5)/V5,IF(AND(V5=0,S5=0),"",(S5-V5)/V5)))) -> 1 | Y5: =+Y6+Y7+Y8 -> 115671.81 | Z5: =IF(AND(Y4=0,Y5>=0), "",Y5/Y4) -> 0.98506319 | AB5: =IF(AND(O5=0,Y5>0),100%,IF(AND(O5<0,Y5=0),(O5-Y5)/O5,IF(AND(O5>0,Y5>0),(Y5-O5)/O5,IF(AND(O5=0,Y5=0),"",(Y5-O5)/O5)))) -> 0.10648597 | AC5: =+AC6+AC7+AC8 -> 377112.56 | AD5: =IF(AND(AC4=0,AC5>=0), "",AC5/AC4) -> 0.97751987 | AF5: =+AF6+AF7+AF8 -> 130183.42 | AG5: =IF(AND(AF4=0,AF5>=0), "",AF5/AF4) -> 0.98319589 | AI5: =IF(AND(Y5=0,AF5>0),100%,IF(AND(Y5<0,AF5=0),(Y5-AF5)/Y5,IF(AND(Y5>0,AF5>0),(AF5-Y5)/Y5,IF(AND(Y5=0,AF5=0),"",(AF5-Y5)/Y5)))) -> 0.12545503 | AJ5: =+AJ6+AJ7+AJ8 -> 507295.99 | AK5: =IF(AND(AJ4=0,AJ5>=0), "",AJ5/AJ4) -> 0.9789702 | AM5: =+AM6+AM7+AM8 -> 116415.01 | AN5: =IF(AND(AM4=0,AM5>=0), "",AM5/AM4) -> 0.98548272 | AP5: =IF(AND(AF5=0,AM5>0),100%,IF(AND(AF5<0,AM5=0),(AF5-AM5)/AF5,IF(AND(AF5>0,AM5>0),(AM5-AF5)/AF5,IF(AND(AF5=0,AM5=0),"",(AM5-AF5)/AF5)))) -> -0.10576162 | AQ5: =+AQ6+AQ7+AQ8 -> 623711 | AR5: =IF(AND(AQ4=0,AQ5>=0), "",AQ5/AQ4) -> 0.98017921 | AT5: =+AT6+AT7+AT8 -> 0 | AU5: =IF(AND(AT4=0,AT5>=0), "",AT5/AT4) | AV5: =IF(AND(AT5=0,AQ5>0),100%,IF(AND(AT5<0,AQ5=0),(AT5-AQ5)/AT5,IF(AND(AT5>0,AQ5>0),(AQ5-AT5)/AT5,IF(AND(AT5=0,AQ5=0),"",(AQ5-AT5)/AT5)))) -> 1 | AW5: =+AW6+AW7+AW8 -> 103951.83 | AX5: =IF(AND(AW4=0,AW5>=0), "",AW5/AW4) -> 0.98017921 | AZ5: =+AZ6+AZ7+AZ8 -> 0 | BA5: =IF(AND(AZ4=0,AZ5>=0), "",AZ5/AZ4) | BB5: =IF(AND(AZ5=0,AW5>0),100%,IF(AND(AZ5<0,AW5=0),(AZ5-AW5)/AZ5,IF(AND(AZ5>0,AW5>0),(AW5-AZ5)/AZ5,IF(AND(AZ5=0,AW5=0),"",(AW5-AZ5)/AZ5)))) -> 1 | BC5: =+BC6+BC7+BC8 -> 0 | BD5: =IF(AND(BC4=0,BC5>=0), "",BC5/BC4) | BF5: =IF(AND(AM5=0,BC5>0),100%,IF(AND(AM5<0,BC5=0),(AM5-BC5)/AM5,IF(AND(AM5>0,BC5>0),(BC5-AM5)/AM5,IF(AND(AM5=0,BC5=0),"",(BC5-AM5)/AM5)))) -> -1 | BG5: =+BG6+BG7+BG8 -> 623711 | BH5: =IF(AND(BG4=0,BG5>=0), "",BG5/BG4) -> 0.98017921 | BJ5: =+BJ6+BJ7+BJ8 -> 0 | BK5: =IF(AND(BJ4=0,BJ5>=0), "",BJ5/BJ4) | BM5: =IF(AND(BC5=0,BJ5>0),100%,IF(AND(BC5<0,BJ5=0),(BC5-BJ5)/BC5,IF(AND(BC5>0,BJ5>0),(BJ5-BC5)/BC5,IF(AND(BC5=0,BJ5=0),"",(BJ5-BC5)/BC5)))) | BN5: =+BN6+BN7+BN8 -> 623711 | BO5: =IF(AND(BN4=0,BN5>=0), "",BN5/BN4) -> 0.98017921 | BQ5: =+BQ6+BQ7+BQ8 -> 0 | BR5: =IF(AND(BQ4=0,BQ5>=0), "",BQ5/BQ4) | BT5: =IF(AND(BJ5=0,BQ5>0),100%,IF(AND(BJ5<0,BQ5=0),(BJ5-BQ5)/BJ5,IF(AND(BJ5>0,BQ5>0),(BQ5-BJ5)/BJ5,IF(AND(BJ5=0,BQ5=0),"",(BQ5-BJ5)/BJ5)))) | BU5: =+BU6+BU7+BU8 -> 623711 | BV5: =IF(AND(BU4=0,BU5>=0), "",BU5/BU4) -> 0.98017921 | BX5: =+BX6+BX7+BX8 -> 0 | BY5: =IF(AND(BX4=0,BX5>=0), "",BX5/BX4) | BZ5: =IF(AND(BX5=0,BU5>0),100%,IF(AND(BX5<0,BU5=0),(BX5-BU5)/BX5,IF(AND(BX5>0,BU5>0),(BU5-BX5)/BX5,IF(AND(BX5=0,BU5=0),"",(BU5-BX5)/BX5)))) -> 1 | CA5: =+CA6+CA7+CA8 -> 0 | CB5: =IF(AND(CA4=0,CA5>=0), "",CA5/CA4) | CD5: =IF(AND(BQ5=0,CA5>0),100%,IF(AND(BQ5<0,CA5=0),(BQ5-CA5)/BQ5,IF(AND(BQ5>0,CA5>0),(CA5-BQ5)/BQ5,IF(AND(BQ5=0,CA5=0),"",(CA5-BQ5)/BQ5)))) | CE5: =+CE6+CE7+CE8 -> 623711 | CF5: =IF(AND(CE4=0,CE5>=0), "",CE5/CE4) -> 0.98017921 | CH5: =+CH6+CH7+CH8 -> 0 | CI5: =IF(AND(CH4=0,CH5>=0), "",CH5/CH4) | CK5: =IF(AND(CA5=0,CH5>0),100%,IF(AND(CA5<0,CH5=0),(CA5-CH5)/CA5,IF(AND(CA5>0,CH5>0),(CH5-CA5)/CA5,IF(AND(CA5=0,CH5=0),"",(CH5-CA5)/CA5)))) | CL5: =+CL6+CL7+CL8 -> 623711 | CM5: =IF(AND(CL4=0,CL5>=0), "",CL5/CL4) -> 0.98017921 | CO5: =+CO6+CO7+CO8 -> 0 | CP5: =IF(AND(CO4=0,CO5>=0), "",CO5/CO4) | CR5: =IF(AND(CH5=0,CO5>0),100%,IF(AND(CH5<0,CO5=0),(CH5-CO5)/CH5,IF(AND(CH5>0,CO5>0),(CO5-CH5)/CH5,IF(AND(CH5=0,CO5=0),"",(CO5-CH5)/CH5)))) | CS5: =+CS6+CS7+CS8 -> 623711 | CT5: =IF(AND(CS4=0,CS5>=0), "",CS5/CS4) -> 0.98017921 | CV5: =+CV6+CV7+CV8 -> 0 | CW5: =IF(AND(CV4=0,CV5>=0), "",CV5/CV4) | CX5: =IF(AND(CV5=0,CS5>0),100%,IF(AND(CV5<0,CS5=0),(CV5-CS5)/CV5,IF(AND(CV5>0,CS5>0),(CS5-CV5)/CV5,IF(AND(CV5=0,CS5=0),"",(CS5-CV5)/CV5)))) -> 1
A6: Ingresos por venta de mercancía | B6: =+'N EERR ULTRAX'!B6 -> 0 | C6: =IF(AND(B4=0,B6>=0), "",B6/B4) | E6: =+'N EERR ULTRAX'!C6 -> 67748.176 | F6: =IF(AND(E4=0,E6>=0), "",E6/E4) -> 0.97174165 | H6: =+'N EERR ULTRAX'!D6 -> 89152.784 | I6: =IF(AND(H4=0,H6>=0), "",H6/H4) -> 0.97989766 | K6: =IF(AND(E6=0,H6>0),100%,IF(AND(E6<0,H6=0),(E6-H6)/E6,IF(AND(E6>0,H6>0),(H6-E6)/E6,IF(AND(E6=0,H6=0),"",(H6-E6)/E6)))) -> 0.31594368 | L6: =+E6+H6 -> 156900.96 | M6: =IF(AND(L4=0,L6>=0), "",L6/L4) -> 0.97635925 | O6: =+'N EERR ULTRAX'!E6 -> 104539.79 | P6: =IF(AND(O4=0,O6>=0), "",O6/O4) -> 0.97102466 | R6: =IF(AND(H6=0,O6>0),100%,IF(AND(H6<0,O6=0),(H6-O6)/H6,IF(AND(H6>0,O6>0),(O6-H6)/H6,IF(AND(H6=0,O6=0),"",(O6-H6)/H6)))) -> 0.17259145 | S6: =+L6+O6 -> 261440.75 | T6: =IF(AND(S4=0,S6>=0), "",S6/S4) -> 0.97421914 | W6: =IF(AND(V4=0,V6>=0), "",V6/V4) | X6: =IF(AND(V6=0,S6>0),100%,IF(AND(V6<0,S6=0),(V6-S6)/V6,IF(AND(V6>0,S6>0),(S6-V6)/V6,IF(AND(V6=0,S6=0),"",(S6-V6)/V6)))) -> 1 | Y6: =+'N EERR ULTRAX'!F6 -> 115671.81 | Z6: =IF(AND(Y4=0,Y6>=0), "",Y6/Y4) -> 0.98506319 | AB6: =IF(AND(O6=0,Y6>0),100%,IF(AND(O6<0,Y6=0),(O6-Y6)/O6,IF(AND(O6>0,Y6>0),(Y6-O6)/O6,IF(AND(O6=0,Y6=0),"",(Y6-O6)/O6)))) -> 0.10648597 | AC6: =+S6+Y6 -> 377112.56 | AD6: =IF(AND(AC4=0,AC6>=0), "",AC6/AC4) -> 0.97751987 | AF6: =+'N EERR ULTRAX'!G6 -> 130801.53 | AG6: =IF(AND(AF4=0,AF6>=0), "",AF6/AF4) -> 0.9878641 | AI6: =IF(AND(Y6=0,AF6>0),100%,IF(AND(Y6<0,AF6=0),(Y6-AF6)/Y6,IF(AND(Y6>0,AF6>0),(AF6-Y6)/Y6,IF(AND(Y6=0,AF6=0),"",(AF6-Y6)/Y6)))) -> 0.13079869 | AJ6: =+AC6+AF6 -> 507914.1 | AK6: =IF(AND(AJ4=0,AJ6>=0), "",AJ6/AJ4) -> 0.98016302 | AM6: =+'N EERR ULTRAX'!H6 -> 117157.41 | AN6: =IF(AND(AM4=0,AM6>=0), "",AM6/AM4) -> 0.99176729 | AP6: =IF(AND(AF6=0,AM6>0),100%,IF(AND(AF6<0,AM6=0),(AF6-AM6)/AF6,IF(AND(AF6>0,AM6>0),(AM6-AF6)/AF6,IF(AND(AF6=0,AM6=0),"",(AM6-AF6)/AF6)))) -> -0.10431165 | AQ6: =+AJ6+AM6 -> 625071.51 | AR6: =IF(AND(AQ4=0,AQ6>=0), "",AQ6/AQ4) -> 0.98231729 | AT6: =+V6*2 -> 0 | AU6: =IF(AND(AT4=0,AT6>=0), "",AT6/AT4) | AV6: =IF(AND(AT6=0,AQ6>0),100%,IF(AND(AT6<0,AQ6=0),(AT6-AQ6)/AT6,IF(AND(AT6>0,AQ6>0),(AQ6-AT6)/AT6,IF(AND(AT6=0,AQ6=0),"",(AQ6-AT6)/AT6)))) -> 1 | AW6: =+AQ6/6 -> 104178.58 | AX6: =IF(AND(AW4=0,AW6>=0), "",AW6/AW4) -> 0.98231729 | AZ6: =+AT6/6 -> 0 | BA6: =IF(AND(AZ4=0,AZ6>=0), "",AZ6/AZ4) | BB6: =IF(AND(AZ6=0,AW6>0),100%,IF(AND(AZ6<0,AW6=0),(AZ6-AW6)/AZ6,IF(AND(AZ6>0,AW6>0),(AW6-AZ6)/AZ6,IF(AND(AZ6=0,AW6=0),"",(AW6-AZ6)/AZ6)))) -> 1 | BC6: =+'N EERR ULTRAX'!I6 -> 0 | BD6: =IF(AND(BC4=0,BC6>=0), "",BC6/BC4) | BF6: =IF(AND(AM6=0,BC6>0),100%,IF(AND(AM6<0,BC6=0),(AM6-BC6)/AM6,IF(AND(AM6>0,BC6>0),(BC6-AM6)/AM6,IF(AND(AM6=0,BC6=0),"",(BC6-AM6)/AM6)))) -> -1 | BG6: =+AQ6+BC6 -> 625071.51 | BH6: =IF(AND(BG4=0,BG6>=0), "",BG6/BG4) -> 0.98231729 | BJ6: =+'N EERR ULTRAX'!J6 -> 0 | BK6: =IF(AND(BJ4=0,BJ6>=0), "",BJ6/BJ4) | BM6: =IF(AND(BC6=0,BJ6>0),100%,IF(AND(BC6<0,BJ6=0),(BC6-BJ6)/BC6,IF(AND(BC6>0,BJ6>0),(BJ6-BC6)/BC6,IF(AND(BC6=0,BJ6=0),"",(BJ6-BC6)/BC6)))) | BN6: =+BG6+BJ6 -> 625071.51 | BO6: =IF(AND(BN4=0,BN6>=0), "",BN6/BN4) -> 0.98231729 | BQ6: =+'N EERR ULTRAX'!K6 -> 0 | BR6: =IF(AND(BQ4=0,BQ6>=0), "",BQ6/BQ4) | BT6: =IF(AND(BJ6=0,BQ6>0),100%,IF(AND(BJ6<0,BQ6=0),(BJ6-BQ6)/BJ6,IF(AND(BJ6>0,BQ6>0),(BQ6-BJ6)/BJ6,IF(AND(BJ6=0,BQ6=0),"",(BQ6-BJ6)/BJ6)))) | BU6: =+BN6+BQ6 -> 625071.51 | BV6: =IF(AND(BU4=0,BU6>=0), "",BU6/BU4) -> 0.98231729 | BX6: =+AZ6*9 -> 0 | BY6: =IF(AND(BX4=0,BX6>=0), "",BX6/BX4) | BZ6: =IF(AND(BX6=0,BU6>0),100%,IF(AND(BX6<0,BU6=0),(BX6-BU6)/BX6,IF(AND(BX6>0,BU6>0),(BU6-BX6)/BX6,IF(AND(BX6=0,BU6=0),"",(BU6-BX6)/BX6)))) -> 1 | CA6: =+'N EERR ULTRAX'!L6 -> 0 | CB6: =IF(AND(CA4=0,CA6>=0), "",CA6/CA4) | CD6: =IF(AND(BQ6=0,CA6>0),100%,IF(AND(BQ6<0,CA6=0),(BQ6-CA6)/BQ6,IF(AND(BQ6>0,CA6>0),(CA6-BQ6)/BQ6,IF(AND(BQ6=0,CA6=0),"",(CA6-BQ6)/BQ6)))) | CE6: =+BU6+CA6 -> 625071.51 | CF6: =IF(AND(CE4=0,CE6>=0), "",CE6/CE4) -> 0.98231729 | CH6: =+'N EERR ULTRAX'!M6 -> 0 | CI6: =IF(AND(CH4=0,CH6>=0), "",CH6/CH4) | CK6: =IF(AND(CA6=0,CH6>0),100%,IF(AND(CA6<0,CH6=0),(CA6-CH6)/CA6,IF(AND(CA6>0,CH6>0),(CH6-CA6)/CA6,IF(AND(CA6=0,CH6=0),"",(CH6-CA6)/CA6)))) | CL6: =+CE6+CH6 -> 625071.51 | CM6: =IF(AND(CL4=0,CL6>=0), "",CL6/CL4) -> 0.98231729 | CO6: =+'N EERR ULTRAX'!N6 -> 0 | CP6: =IF(AND(CO4=0,CO6>=0), "",CO6/CO4) | CR6: =IF(AND(CH6=0,CO6>0),100%,IF(AND(CH6<0,CO6=0),(CH6-CO6)/CH6,IF(AND(CH6>0,CO6>0),(CO6-CH6)/CH6,IF(AND(CH6=0,CO6=0),"",(CO6-CH6)/CH6)))) | CS6: =+CL6+CO6 -> 625071.51 | CT6: =IF(AND(CS4=0,CS6>=0), "",CS6/CS4) -> 0.98231729 | CV6: =+AZ6*12 -> 0 | CW6: =IF(AND(CV4=0,CV6>=0), "",CV6/CV4) | CX6: =IF(AND(CV6=0,CS6>0),100%,IF(AND(CV6<0,CS6=0),(CV6-CS6)/CV6,IF(AND(CV6>0,CS6>0),(CS6-CV6)/CV6,IF(AND(CV6=0,CS6=0),"",(CS6-CV6)/CV6)))) -> 1
A7: Devoluciones sobre ventas | B7: =+'N EERR ULTRAX'!B7 -> 0 | C7: =IF(AND(B4=0,B7>=0), "",B7/B4) | E7: =+'N EERR ULTRAX'!C7 -> 0 | F7: =IF(AND(E4=0,E7>=0), "",E7/E4) -> 0 | H7: =+'N EERR ULTRAX'!D7 -> 0 | I7: =IF(AND(H4=0,H7>=0), "",H7/H4) -> 0 | K7: =IF(AND(E7=0,H7>0),100%,IF(AND(E7<0,H7=0),(E7-H7)/E7,IF(AND(E7>0,H7>0),(H7-E7)/E7,IF(AND(E7=0,H7=0),"",(H7-E7)/E7)))) | L7: =+E7+H7 -> 0 | M7: =IF(AND(L4=0,L7>=0), "",L7/L4) -> 0 | O7: =+'N EERR ULTRAX'!E7 -> 0 | P7: =IF(AND(O4=0,O7>=0), "",O7/O4) -> 0 | R7: =IF(AND(H7=0,O7>0),100%,IF(AND(H7<0,O7=0),(H7-O7)/H7,IF(AND(H7>0,O7>0),(O7-H7)/H7,IF(AND(H7=0,O7=0),"",(O7-H7)/H7)))) | S7: =+L7+O7 -> 0 | T7: =IF(AND(S4=0,S7>=0), "",S7/S4) -> 0 | W7: =IF(AND(V4=0,V7>=0), "",V7/V4) | X7: =IF(AND(V7=0,S7>0),100%,IF(AND(V7<0,S7=0),(V7-S7)/V7,IF(AND(V7>0,S7>0),(S7-V7)/V7,IF(AND(V7=0,S7=0),"",(S7-V7)/V7)))) | Y7: =+'N EERR ULTRAX'!F7 -> 0 | Z7: =IF(AND(Y4=0,Y7>=0), "",Y7/Y4) -> 0 | AB7: =IF(AND(O7=0,Y7>0),100%,IF(AND(O7<0,Y7=0),(O7-Y7)/O7,IF(AND(O7>0,Y7>0),(Y7-O7)/O7,IF(AND(O7=0,Y7=0),"",(Y7-O7)/O7)))) | AC7: =+S7+Y7 -> 0 | AD7: =IF(AND(AC4=0,AC7>=0), "",AC7/AC4) -> 0 | AF7: =+'N EERR ULTRAX'!G7 -> 0 | AG7: =IF(AND(AF4=0,AF7>=0), "",AF7/AF4) -> 0 | AI7: =IF(AND(Y7=0,AF7>0),100%,IF(AND(Y7<0,AF7=0),(Y7-AF7)/Y7,IF(AND(Y7>0,AF7>0),(AF7-Y7)/Y7,IF(AND(Y7=0,AF7=0),"",(AF7-Y7)/Y7)))) | AJ7: =+AC7+AF7 -> 0 | AK7: =IF(AND(AJ4=0,AJ7>=0), "",AJ7/AJ4) -> 0 | AM7: =+'N EERR ULTRAX'!H7 -> 0 | AN7: =IF(AND(AM4=0,AM7>=0), "",AM7/AM4) -> 0 | AP7: =IF(AND(AF7=0,AM7>0),100%,IF(AND(AF7<0,AM7=0),(AF7-AM7)/AF7,IF(AND(AF7>0,AM7>0),(AM7-AF7)/AF7,IF(AND(AF7=0,AM7=0),"",(AM7-AF7)/AF7)))) | AQ7: =+AJ7+AM7 -> 0 | AR7: =IF(AND(AQ4=0,AQ7>=0), "",AQ7/AQ4) -> 0 | AT7: =+V7*2 -> 0 | AU7: =IF(AND(AT4=0,AT7>=0), "",AT7/AT4) | AV7: =IF(AND(AT7=0,AQ7>0),100%,IF(AND(AT7<0,AQ7=0),(AT7-AQ7)/AT7,IF(AND(AT7>0,AQ7>0),(AQ7-AT7)/AT7,IF(AND(AT7=0,AQ7=0),"",(AQ7-AT7)/AT7)))) | AW7: =+AQ7/6 -> 0 | AX7: =IF(AND(AW4=0,AW7>=0), "",AW7/AW4) -> 0 | AZ7: =+AT7/6 -> 0 | BA7: =IF(AND(AZ4=0,AZ7>=0), "",AZ7/AZ4) | BB7: =IF(AND(AZ7=0,AW7>0),100%,IF(AND(AZ7<0,AW7=0),(AZ7-AW7)/AZ7,IF(AND(AZ7>0,AW7>0),(AW7-AZ7)/AZ7,IF(AND(AZ7=0,AW7=0),"",(AW7-AZ7)/AZ7)))) | BC7: =+'N EERR ULTRAX'!I7 -> 0 | BD7: =IF(AND(BC4=0,BC7>=0), "",BC7/BC4) | BF7: =IF(AND(AM7=0,BC7>0),100%,IF(AND(AM7<0,BC7=0),(AM7-BC7)/AM7,IF(AND(AM7>0,BC7>0),(BC7-AM7)/AM7,IF(AND(AM7=0,BC7=0),"",(BC7-AM7)/AM7)))) | BG7: =+AQ7+BC7 -> 0 | BH7: =IF(AND(BG4=0,BG7>=0), "",BG7/BG4) -> 0 | BJ7: =+'N EERR ULTRAX'!J7 -> 0 | BK7: =IF(AND(BJ4=0,BJ7>=0), "",BJ7/BJ4) | BM7: =IF(AND(BC7=0,BJ7>0),100%,IF(AND(BC7<0,BJ7=0),(BC7-BJ7)/BC7,IF(AND(BC7>0,BJ7>0),(BJ7-BC7)/BC7,IF(AND(BC7=0,BJ7=0),"",(BJ7-BC7)/BC7)))) | BN7: =+BG7+BJ7 -> 0 | BO7: =IF(AND(BN4=0,BN7>=0), "",BN7/BN4) -> 0 | BQ7: =+'N EERR ULTRAX'!K7 -> 0 | BR7: =IF(AND(BQ4=0,BQ7>=0), "",BQ7/BQ4) | BT7: =IF(AND(BJ7=0,BQ7>0),100%,IF(AND(BJ7<0,BQ7=0),(BJ7-BQ7)/BJ7,IF(AND(BJ7>0,BQ7>0),(BQ7-BJ7)/BJ7,IF(AND(BJ7=0,BQ7=0),"",(BQ7-BJ7)/BJ7)))) | BU7: =+BN7+BQ7 -> 0 | BV7: =IF(AND(BU4=0,BU7>=0), "",BU7/BU4) -> 0 | BX7: =+AZ7*9 -> 0 | BY7: =IF(AND(BX4=0,BX7>=0), "",BX7/BX4) | BZ7: =IF(AND(BX7=0,BU7>0),100%,IF(AND(BX7<0,BU7=0),(BX7-BU7)/BX7,IF(AND(BX7>0,BU7>0),(BU7-BX7)/BX7,IF(AND(BX7=0,BU7=0),"",(BU7-BX7)/BX7)))) | CA7: =+'N EERR ULTRAX'!L7 -> 0 | CB7: =IF(AND(CA4=0,CA7>=0), "",CA7/CA4) | CD7: =IF(AND(BQ7=0,CA7>0),100%,IF(AND(BQ7<0,CA7=0),(BQ7-CA7)/BQ7,IF(AND(BQ7>0,CA7>0),(CA7-BQ7)/BQ7,IF(AND(BQ7=0,CA7=0),"",(CA7-BQ7)/BQ7)))) | CE7: =+BU7+CA7 -> 0 | CF7: =IF(AND(CE4=0,CE7>=0), "",CE7/CE4) -> 0 | CH7: =+'N EERR ULTRAX'!M7 -> 0 | CI7: =IF(AND(CH4=0,CH7>=0), "",CH7/CH4) | CK7: =IF(AND(CA7=0,CH7>0),100%,IF(AND(CA7<0,CH7=0),(CA7-CH7)/CA7,IF(AND(CA7>0,CH7>0),(CH7-CA7)/CA7,IF(AND(CA7=0,CH7=0),"",(CH7-CA7)/CA7)))) | CL7: =+CE7+CH7 -> 0 | CM7: =IF(AND(CL4=0,CL7>=0), "",CL7/CL4) -> 0 | CO7: =+'N EERR ULTRAX'!N7 -> 0 | CP7: =IF(AND(CO4=0,CO7>=0), "",CO7/CO4) | CR7: =IF(AND(CH7=0,CO7>0),100%,IF(AND(CH7<0,CO7=0),(CH7-CO7)/CH7,IF(AND(CH7>0,CO7>0),(CO7-CH7)/CH7,IF(AND(CH7=0,CO7=0),"",(CO7-CH7)/CH7)))) | CS7: =+CL7+CO7 -> 0 | CT7: =IF(AND(CS4=0,CS7>=0), "",CS7/CS4) -> 0 | CV7: =+AZ7*12 -> 0 | CW7: =IF(AND(CV4=0,CV7>=0), "",CV7/CV4) | CX7: =IF(AND(CV7=0,CS7>0),100%,IF(AND(CV7<0,CS7=0),(CV7-CS7)/CV7,IF(AND(CV7>0,CS7>0),(CS7-CV7)/CV7,IF(AND(CV7=0,CS7=0),"",(CS7-CV7)/CV7))))
A8: Descuentos sobre ventas | B8: =+'N EERR ULTRAX'!B8+'N EERR ULTRAX'!B9 -> 0 | C8: =IF(AND(B5=0,B8>=0), "",B8/B5) | E8: =+'N EERR ULTRAX'!C8+'N EERR ULTRAX'!C9 -> 0 | F8: =IF(AND(E5=0,E8>=0), "",E8/E5) -> 0 | H8: =+'N EERR ULTRAX'!D8+'N EERR ULTRAX'!D9 -> 0 | I8: =IF(AND(H5=0,H8>=0), "",H8/H5) -> 0 | K8: =IF(AND(E8=0,H8>0),100%,IF(AND(E8<0,H8=0),(E8-H8)/E8,IF(AND(E8>0,H8>0),(H8-E8)/E8,IF(AND(E8=0,H8=0),"",(H8-E8)/E8)))) | L8: =+E8+H8 -> 0 | M8: =IF(AND(L5=0,L8>=0), "",L8/L5) -> 0 | O8: =+'N EERR ULTRAX'!E8+'N EERR ULTRAX'!E9 -> 0 | P8: =IF(AND(O5=0,O8>=0), "",O8/O5) -> 0 | R8: =IF(AND(H8=0,O8>0),100%,IF(AND(H8<0,O8=0),(H8-O8)/H8,IF(AND(H8>0,O8>0),(O8-H8)/H8,IF(AND(H8=0,O8=0),"",(O8-H8)/H8)))) | S8: =+L8+O8 -> 0 | T8: =IF(AND(S5=0,S8>=0), "",S8/S5) -> 0 | W8: =IF(AND(V5=0,V8>=0), "",V8/V5) | X8: =IF(AND(V8=0,S8>0),100%,IF(AND(V8<0,S8=0),(V8-S8)/V8,IF(AND(V8>0,S8>0),(S8-V8)/V8,IF(AND(V8=0,S8=0),"",(S8-V8)/V8)))) | Y8: =+'N EERR ULTRAX'!F8+'N EERR ULTRAX'!F9 -> 0 | Z8: =IF(AND(Y5=0,Y8>=0), "",Y8/Y5) -> 0 | AB8: =IF(AND(O8=0,Y8>0),100%,IF(AND(O8<0,Y8=0),(O8-Y8)/O8,IF(AND(O8>0,Y8>0),(Y8-O8)/O8,IF(AND(O8=0,Y8=0),"",(Y8-O8)/O8)))) | AC8: =+S8+Y8 -> 0 | AD8: =IF(AND(AC5=0,AC8>=0), "",AC8/AC5) -> 0 | AF8: =+'N EERR ULTRAX'!G8+'N EERR ULTRAX'!G9 -> -618.11011 | AG8: =IF(AND(AF5=0,AF8>=0), "",AF8/AF5) -> -0.004747994 | AI8: =IF(AND(Y8=0,AF8>0),100%,IF(AND(Y8<0,AF8=0),(Y8-AF8)/Y8,IF(AND(Y8>0,AF8>0),(AF8-Y8)/Y8,IF(AND(Y8=0,AF8=0),"",(AF8-Y8)/Y8)))) -> #DIV/0! | AJ8: =+AC8+AF8 -> -618.11011 | AK8: =IF(AND(AJ5=0,AJ8>=0), "",AJ8/AJ5) -> -0.0012184408 | AM8: =+'N EERR ULTRAX'!H8+'N EERR ULTRAX'!H9 -> -742.39559 | AN8: =IF(AND(AM5=0,AM8>=0), "",AM8/AM5) -> -0.0063771464 | AP8: =IF(AND(AF8=0,AM8>0),100%,IF(AND(AF8<0,AM8=0),(AF8-AM8)/AF8,IF(AND(AF8>0,AM8>0),(AM8-AF8)/AF8,IF(AND(AF8=0,AM8=0),"",(AM8-AF8)/AF8)))) -> 0.20107336 | AQ8: =+AJ8+AM8 -> -1360.5057 | AR8: =IF(AND(AQ5=0,AQ8>=0), "",AQ8/AQ5) -> -0.0021813078 | AT8: =+V8*2 -> 0 | AU8: =IF(AND(AT5=0,AT8>=0), "",AT8/AT5) | AV8: =IF(AND(AT8=0,AQ8>0),100%,IF(AND(AT8<0,AQ8=0),(AT8-AQ8)/AT8,IF(AND(AT8>0,AQ8>0),(AQ8-AT8)/AT8,IF(AND(AT8=0,AQ8=0),"",(AQ8-AT8)/AT8)))) -> #DIV/0! | AW8: =+AQ8/6 -> -226.75095 | AX8: =IF(AND(AW5=0,AW8>=0), "",AW8/AW5) -> -0.0021813078 | AZ8: =+AT8/6 -> 0 | BA8: =IF(AND(AZ5=0,AZ8>=0), "",AZ8/AZ5) | BB8: =IF(AND(AZ8=0,AW8>0),100%,IF(AND(AZ8<0,AW8=0),(AZ8-AW8)/AZ8,IF(AND(AZ8>0,AW8>0),(AW8-AZ8)/AZ8,IF(AND(AZ8=0,AW8=0),"",(AW8-AZ8)/AZ8)))) -> #DIV/0! | BC8: =+'N EERR ULTRAX'!I8+'N EERR ULTRAX'!I9 -> 0 | BD8: =IF(AND(BC5=0,BC8>=0), "",BC8/BC5) | BF8: =IF(AND(AM8=0,BC8>0),100%,IF(AND(AM8<0,BC8=0),(AM8-BC8)/AM8,IF(AND(AM8>0,BC8>0),(BC8-AM8)/AM8,IF(AND(AM8=0,BC8=0),"",(BC8-AM8)/AM8)))) -> 1 | BG8: =+AQ8+BC8 -> -1360.5057 | BH8: =IF(AND(BG5=0,BG8>=0), "",BG8/BG5) -> -0.0021813078 | BJ8: =+'N EERR ULTRAX'!J8+'N EERR ULTRAX'!J9 -> 0 | BK8: =IF(AND(BJ5=0,BJ8>=0), "",BJ8/BJ5) | BM8: =IF(AND(BC8=0,BJ8>0),100%,IF(AND(BC8<0,BJ8=0),(BC8-BJ8)/BC8,IF(AND(BC8>0,BJ8>0),(BJ8-BC8)/BC8,IF(AND(BC8=0,BJ8=0),"",(BJ8-BC8)/BC8)))) | BN8: =+BG8+BJ8 -> -1360.5057 | BO8: =IF(AND(BN5=0,BN8>=0), "",BN8/BN5) -> -0.0021813078 | BQ8: =+'N EERR ULTRAX'!K8+'N EERR ULTRAX'!K9 -> 0 | BR8: =IF(AND(BQ5=0,BQ8>=0), "",BQ8/BQ5) | BT8: =IF(AND(BJ8=0,BQ8>0),100%,IF(AND(BJ8<0,BQ8=0),(BJ8-BQ8)/BJ8,IF(AND(BJ8>0,BQ8>0),(BQ8-BJ8)/BJ8,IF(AND(BJ8=0,BQ8=0),"",(BQ8-BJ8)/BJ8)))) | BU8: =+BN8+BQ8 -> -1360.5057 | BV8: =IF(AND(BU5=0,BU8>=0), "",BU8/BU5) -> -0.0021813078 | BX8: =+AZ8*9 -> 0 | BY8: =IF(AND(BX5=0,BX8>=0), "",BX8/BX5) | BZ8: =IF(AND(BX8=0,BU8>0),100%,IF(AND(BX8<0,BU8=0),(BX8-BU8)/BX8,IF(AND(BX8>0,BU8>0),(BU8-BX8)/BX8,IF(AND(BX8=0,BU8=0),"",(BU8-BX8)/BX8)))) -> #DIV/0! | CA8: =+'N EERR ULTRAX'!L8+'N EERR ULTRAX'!L9 -> 0 | CB8: =IF(AND(CA5=0,CA8>=0), "",CA8/CA5) | CD8: =IF(AND(BQ8=0,CA8>0),100%,IF(AND(BQ8<0,CA8=0),(BQ8-CA8)/BQ8,IF(AND(BQ8>0,CA8>0),(CA8-BQ8)/BQ8,IF(AND(BQ8=0,CA8=0),"",(CA8-BQ8)/BQ8)))) | CE8: =+BU8+CA8 -> -1360.5057 | CF8: =IF(AND(CE5=0,CE8>=0), "",CE8/CE5) -> -0.0021813078 | CH8: =+'N EERR ULTRAX'!M8+'N EERR ULTRAX'!M9 -> 0 | CI8: =IF(AND(CH5=0,CH8>=0), "",CH8/CH5) | CK8: =IF(AND(CA8=0,CH8>0),100%,IF(AND(CA8<0,CH8=0),(CA8-CH8)/CA8,IF(AND(CA8>0,CH8>0),(CH8-CA8)/CA8,IF(AND(CA8=0,CH8=0),"",(CH8-CA8)/CA8)))) | CL8: =+CE8+CH8 -> -1360.5057 | CM8: =IF(AND(CL5=0,CL8>=0), "",CL8/CL5) -> -0.0021813078 | CO8: =+'N EERR ULTRAX'!N8+'N EERR ULTRAX'!N9 -> 0 | CP8: =IF(AND(CO5=0,CO8>=0), "",CO8/CO5) | CR8: =IF(AND(CH8=0,CO8>0),100%,IF(AND(CH8<0,CO8=0),(CH8-CO8)/CH8,IF(AND(CH8>0,CO8>0),(CO8-CH8)/CH8,IF(AND(CH8=0,CO8=0),"",(CO8-CH8)/CH8)))) | CS8: =+CL8+CO8 -> -1360.5057 | CT8: =IF(AND(CS5=0,CS8>=0), "",CS8/CS5) -> -0.0021813078 | CV8: =+AZ8*12 -> 0 | CW8: =IF(AND(CV5=0,CV8>=0), "",CV8/CV5) | CX8: =IF(AND(CV8=0,CS8>0),100%,IF(AND(CV8<0,CS8=0),(CV8-CS8)/CV8,IF(AND(CV8>0,CS8>0),(CS8-CV8)/CV8,IF(AND(CV8=0,CS8=0),"",(CS8-CV8)/CV8)))) -> #DIV/0!
